Workbook

Sheet Sheet6
A1: Weeks | B1: CD5-m260 | D1: CD5-m261 | F1: CD5-m263 | H1: CD5-m264 | J1: CD5-m265 | L1: CD5-m266 | N1: CD5-m267 | P1: CD5-m269 | R1: CD5-m270 | T1: CD5-m271 | V1: CD5-m272 | X1: CD5-m273 | Z1: CD5-m281 | AB1: CD5-m282 | AD1: CD5-m283 | AF1: CD5-m284 | AH1: CD5-m285 | AJ1: CD10-m881 | AL1: CD10-m882 | AN1: CD10-m883 | AP1: CD10-m884 | AR1: CD10- m885 | AT1: CD10-m876 | AV1: CD10-m877 | AX1: CD10- m878 | AZ1: CD10-m879 | BB1: CD10-m880 | BD1: CD20-m014 | BF1: CD20-m016 | BH1: CD20-m018 | BJ1: CD20-m020 | BL1: CD20-m021 | BN1: CD20-m022 | BP1: CD20-m023 | BR1: CD20-m025 | BT1: CD20-m026 | BV1: CD20-m027 | BX1: CD20-m028 | BZ1: CD20-m034 | CB1: CD20-m035 | CD1: CD20-m036 | CF1: CD20-m038 | CH1: CD21-m010 | CJ1: CD21-m011 | CL1: CD21-m014 | CN1: CD21-m015 | CP1: CD21-m016 | CR1: CD21-m017 | CT1: CD21-m018 | CV1: CD21-m019 | CX1: CD21-m020 | CZ1: CD46-m331 | DB1: CD46-m332 | DD1: CD46-m333 | DF1: CD46-m334 | DH1: CD46-m336 | DJ1: CD46-m337 | DL1: CD46-m338 | DN1: CD46-m339 | DP1: CD46-m340 | DR1: CD20-m004 | DT1: CD20-m005 | DV1: CD20-m006 | DX1: CD20-m007 | DZ1: CD20-m008 | EB1: CD20-m009 | ED1: CD20-m010 | EF1: CD20-m011 | EH1: CD20-m012 | EJ1: CD20-m013 | EL1: CD20-m029 | EN1: CD20-m030 | EP1: CD20-m031 | ER1: CD20-m032 | ET1: CD20-m033 | EV1: CD-m722 | EX1: CD-m723 | EZ1: CD41-m724 | FB1: CD41-m725 | FD1: CD41-m726 | FF1: CD41-m727 | FH1: CD41-m729 | FJ1: CD41-m730 | FL1: CD41-m731 | FN1: CD41-m774 | FP1: CD10-m851 | FR1: CD10-m852 | FT1: CD10-m853 | FV1: CD10-m854 | FX1: CD10-m855 | FZ1: CD10-m896 | GB1: CD10-m898 | GD1: CD10-m899 | GF1: CD10-m900 | GH1: CD21-m998 | GJ1: CD21-m999 | GL1: CD21-m002 | GN1: CD21-m003 | GP1: CD21-m004 | GR1: CD21-m006 | GT1: CD21-m007 | GV1: CD21-m008 | GX1: CD21-m009 | GZ1: CD30-m193 | HB1: CD30-m195 | HD1: CD30-m196 | HF1: CD30-m197 | HH1: CD30-m203 | HJ1: CD30-m204 | HL1: CD30-m205 | HN1: CD30-m206 | HP1: CD30-m207 | HR1: CD30-m229 | HT1: CD30-m230 | HV1: CD30-m231 | HX1: CD30-m232 | HZ1: CD27-m740 | IB1: CD27-m806 | ID1: CD27-m807 | IF1: CD27-m808 | IH1: CD27-m809 | IJ1: CD27-m810 | IL1: CD27-m756 | IN1: CD27-m757 | IP1: CD27-m783 | IR1: CD27-m784 | IT1: CD27-m785 | IV1: CD27-m786 | IX1: CD27-m787 | IZ1: CD27-m788 | JB1: CD27-m789
A2: 0 | B2: 100 | C2: 100 | D2: 125 | E2: 125 | F2: 150 | G2: 150 | H2: 175 | I2: 175 | J2: 188 | K2: 188 | L2: 200 | M2: 200 | N2: 225 | O2: 225 | P2: 250 | Q2: 250 | R2: 275 | S2: 275 | T2: 288 | U2: 288 | V2: 300 | W2: 300 | X2: 325 | Y2: 325 | Z2: 338 | AA2: 338 | AB2: 350 | AC2: 350 | AD2: 3.63e+002* | AE2: 3.63e+002* | AF2: 375 | AG2: 375 | AH2: 383 | AI2: 383 | AJ2: 400 | AK2: 400 | AL2: 425 | AM2: 425 | AN2: 450 | AO2: 450 | AP2: 475 | AQ2: 475 | AR2: 500 | AS2: 500 | AT2: 5.13e+002* | AU2: 5.13e+002* | AV2: 525 | AW2: 525 | AX2: 550 | AY2: 550 | AZ2: 575 | BA2: 575 | BB2: 600 | BC2: 600 | BD2: 625 | BE2: 625 | BF2: 650 | BG2: 650 | BH2: 675 | BI2: 675 | BJ2: 688 | BK2: 688 | BL2: 700 | BM2: 700 | BN2: 713 | BO2: 713 | BP2: 725 | BQ2: 725 | BR2: 7.38e+002* | BS2: 7.38e+002* | BT2: 750 | BU2: 750 | BV2: 763 | BW2: 763 | BX2: 775 | BY2: 775 | BZ2: 800 | CA2: 800 | CB2: 8.25e+002* | CC2: 8.25e+002* | CD2: 8.5e+002* | CE2: 8.5e+002* | CF2: 875 | CG2: 875 | CH2: 150 | CI2: 150 | CJ2: 200 | CK2: 200 | CL2: 300 | CM2: 300 | CN2: 400 | CO2: 400 | CP2: 500 | CQ2: 500 | CR2: 600 | CS2: 600 | CT2: 700 | CU2: 700 | CV2: 800 | CW2: 800 | CX2: 900 | CY2: 900 | CZ2: 150 | DA2: 150 | DB2: 250 | DC2: 250 | DD2: 350 | DE2: 350 | DF2: 450 | DG2: 450 | DH2: 550 | DI2: 550 | DJ2: 650 | DK2: 650 | DL2: 750* | DM2: 750* | DN2: 850 | DO2: 850 | DP2: 850 | DQ2: 850 | DR2: 150 | DS2: 150 | DT2: 200 | DU2: 200 | DV2: 250 | DW2: 250 | DX2: 300 | DY2: 300 | DZ2: 350 | EA2: 350 | EB2: 400 | EC2: 400 | ED2: 450 | EE2: 450 | EF2: 500 | EG2: 500 | EH2: 550 | EI2: 550 | EJ2: 600 | EK2: 600 | EL2: 650 | EM2: 650 | EN2: 700 | EO2: 700 | EP2: 750 | EQ2: 750 | ER2: 800 | ES2: 800 | ET2: 900 | EU2: 900 | EV2: 150 | EW2: 150 | EX2: 200 | EY2: 200 | EZ2: 250 | FA2: 250 | FB2: 300 | FC2: 300 | FD2: 350 | FE2: 350 | FF2: 400 | FG2: 400 | FH2: 450 | FI2: 450 | FJ2: 500 | FK2: 500 | FL2: 550 | FM2: 550 | FN2: 600 | FO2: 600 | FP2: 150 | FQ2: 150 | FR2: 200 | FS2: 200 | FT2: 250 | FU2: 250 | FV2: 300 | FW2: 300 | FX2: 400 | FY2: 400 | FZ2: 500 | GA2: 500 | GB2: 600 | GC2: 600 | GD2: 700 | GE2: 700 | GF2: 800 | GG2: 800 | GH2: 150 | GI2: 150 | GJ2: 200 | GK2: 200 | GL2: 300 | GM2: 300 | GN2: 400 | GO2: 400 | GP2: 500 | GQ2: 500 | GR2: 600 | GS2: 600 | GT2: 700 | GU2: 700 | GV2: 800 | GW2: 800 | GX2: 900 | GY2: 900 | GZ2: 150 | HA2: 150 | HB2: 200 | HC2: 200 | HD2: 300 | HE2: 300 | HF2: 400 | HG2: 400 | HH2: 500 | HI2: 500 | HJ2: 600 | HK2: 600 | HL2: 700 | HM2: 700 | HN2: 800 | HO2: 800 | HP2: 900 | HQ2: 900 | HR2: 200 | HS2: 200 | HT2: 300 | HU2: 300 | HV2: 400 | HW2: 400 | HX2: 500 | HY2: 500 | HZ2: 300 | IA2: 300 | IB2: 200 | IC2: 200 | ID2: 300 | IE2: 300 | IF2: 400 | IG2: 400 | IH2: 500 | II2: 500 | IJ2: 600 | IK2: 600 | IL2: 800 | IM2: 800 | IN2: 900 | IO2: 900 | IP2: 300 | IQ2: 300 | IR2: 400 | IS2: 400 | IT2: 500 | IU2: 500 | IV2: 600 | IW2: 600 | IX2: 700 | IY2: 700 | IZ2: 800 | JA2: 800 | JB2: 900 | JC2: 900
A3: 1 | B3: 3427.595 | D3: 69840.86 | F3: 248850.2 | H3: 47154.75 | J3: 96924.43 | L3: 9785.094 | N3: 2750.64 | O3: 1894.282 | P3: 101479.1 | Q3: 53751.47 | R3: 28746.14 | S3: 36254.73 | T3: 111834.9 | U3: 91788.58 | V3: 100508.1 | W3: 79888.88 | X3: 225019.4 | Z3: 372125.5 | AB3: 146178.3 | AD3: 2.814206e+004* | AE3: 3.596149e+004* | AF3: 559363.4 | AG3: 756122.2 | AH3: 54868.17 | AI3: 35825.87 | AJ3: 297243 | AK3: 224135.6 | AL3: 203275.8 | AM3: 12052.86 | AN3: 1631.012 | AO3: 2691.839 | AP3: 2290903 | AQ3: 2783205 | AR3: 7328.624 | AS3: 3197.484 | AT3: 2.435722e+004* | AU3: 5.441707e+004* | AV3: 46080.62 | AW3: 51737.37 | AX3: 177505.4 | AY3: 371015.3 | AZ3: 617873.3 | BA3: 853149.8 | BB3: 58460.17 | BC3: 81964.56 | BD3: 1648.2079 | BE3: 1049.8799 | BF3: 19715.384 | BG3: 21011.837 | BH3: 1120.5838 | BI3: 2163.6972 | BJ3: 132928.18 | BK3: 75220.169 | BL3: 5246.0794 | BM3: 24689.907 | BN3: 3777.3564 | BO3: 7815.2509 | BP3: 87265.625 | BQ3: 82816.658 | BR3: 7.38e+002* | BS3: 7.38e+002* | BT3: 230144.97 | BU3: 75509.064 | BV3: 13325.337 | BW3: 1950.2518 | BX3: 25164.734 | BY3: 34329.453 | BZ3: 5240.0098 | CA3: 8293.5934 | CB3: 1.142382145e+004* | CC3: 4.607697487e+003* | CD3: 2.433984041e+003* | CE3: 1.237808228e+003* | CF3: 875 | CG3: 875 | CH3: 261588.47 | CI3: 248814.87 | CJ3: 385861.02 | CK3: 359675.93 | CL3: 12667.118 | CM3: 2476.1484 | CN3: 72464.386 | CO3: 82735.069 | CP3: 108457.47 | CQ3: 63352.047 | CR3: 250040.28 | CS3: 97204.468 | CT3: 387922.91 | CU3: 410775.02 | CV3: 6503.2964 | CW3: 4022.7132 | CX3: 275206.73 | CY3: 250261.15 | CZ3: 1504.8711 | DA3: 1888.3488 | DB3: 9481.0514 | DC3: 8759.4614 | DD3: 17962.955 | DE3: 15778.524 | DF3: 1416.6386 | DG3: 1931.7822 | DH3: 1385.2108 | DI3: 1000 | DJ3: 1683.1639 | DK3: 1338.1785 | DL3: 19231.21834* | DM3: 26263.4449* | DN3: 8067.0872 | DO3: 7501.1888 | DP3: 8099.3557 | DQ3: 8730.4296 | DR3: 1000 | DS3: 1412.1687 | DT3: 1359.1089 | DU3: 1000 | DV3: 106442.57 | DW3: 120001.48 | DX3: 36401.035 | DY3: 11308.42 | DZ3: 263013.34 | EA3: 202853.1 | EB3: 400 | EC3: 400 | ED3: 1484.9164 | EE3: 1487.4687 | EF3: 122303.52 | EG3: 137337.75 | EH3: 24828.981 | EI3: 26171.503 | EJ3: 25472.912 | EK3: 19928.593 | EL3: 3112.3178 | EM3: 1000 | EN3: 700 | EO3: 700 | EP3: 5741.7312 | EQ3: 1000 | ER3: 25043.865 | ES3: 25850.315 | ET3: 101001.85 | EU3: 71471.458 | EV3: 7667.1124 | EW3: 5118.3763 | EX3: 200 | EY3: 200 | EZ3: 8413.0182 | FA3: 5425.571 | FB3: 4855.2599 | FC3: 2000 | FD3: 7464.3698 | FE3: 4607.9602 | FF3: 2301.5709 | FG3: 3277.1688 | FH3: 7649.9867 | FI3: 6601.2092 | FJ3: 500 | FK3: 500 | FL3: 2000 | FM3: 2390.3124 | FN3: 600 | FO3: 600 | FP3: 76973.8 | FQ3: 54434.8 | FR3: 404603.6 | FS3: 293440.8 | FT3: 1000 | FU3: 6873.81 | FV3: 1509.654 | FW3: 1000 | FX3: 42752.36 | FY3: 25104.14 | FZ3: 12731.76 | GA3: 3725.392 | GB3: 3804.367 | GC3: 1000 | GD3: 19221.64 | GE3: 8855.06 | GF3: 53206.13 | GG3: 98665.53 | GH3: 221055 | GI3: 197732.5 | GJ3: 285070.25 | GK3: 180844 | GL3: 180337 | GM3: 241932.5 | GN3: 8774.25 | GO3: 10543.25 | GP3: 189604 | GQ3: 169002.75 | GR3: 5202.5 | GS3: 7364 | GT3: 90673.75 | GU3: 64333.25 | GV3: 12792.5 | GW3: 9324.5 | GX3: 80506.25 | GY3: 53927.75 | GZ3: 150 | HA3: 150 | HB3: 200 | HC3: 200 | HD3: 52099.739 | HE3: 63037.361 | HF3: 300 | HG3: 300 | HH3: 135330 | HI3: 135938.49 | HJ3: 400 | HK3: 400 | HL3: 223172.41 | HM3: 219728.09 | HN3: 78023.46 | HO3: 98323.257 | HP3: 148328.55 | HQ3: 135093.95 | HR3: 392180.51 | HS3: 449587.92 | HT3: 237670.3 | HU3: 191498.86 | HV3: 307113.53 | HW3: 323158.78 | HX3: 215920.14 | HY3: 230591.8 | HZ3: 300 | IA3: 300 | IB3: 12799.677 | IC3: 22558.243 | ID3: 12779.493 | IE3: 11075.739 | IF3: 13547.158 | IG3: 22370.617 | IH3: 500 | II3: 500 | IJ3: 600 | IK3: 600 | IL3: 800 | IM3: 800 | IN3: 900 | IO3: 900 | IP3: 300 | IQ3: 300 | IR3: 1012.8438 | IS3: 1000 | IT3: 500 | IU3: 500 | IV3: 5228.4927 | IW3: 4356.3671 | IX3: 700 | IY3: 700 | IZ3: 1000 | JA3: 1439.9335 | JB3: 900 | JC3: 900
A4: 2 | B4: 54766 | C4: 58483.76 | D4: 167730.7 | E4: 202032.2 | F4: 182883.7 | G4: 227723 | H4: 103789.9 | I4: 147608.9 | J4: 357531.9 | K4: 364034.2 | L4: 199679.2 | M4: 474861.3 | N4: 115140.3 | O4: 196744.7 | P4: 434650.1 | Q4: 579362.9 | R4: 82442.55 | S4: 89464.82 | T4: 245710.2 | U4: 525100.5 | V4: 410459 | W4: 768735.1 | X4: 538880.1 | Y4: 603571.8 | Z4: 387136.4 | AA4: 469583.4 | AB4: 1413134 | AC4: 936128.4 | AD4: 1.33246e+006* | AE4: 1.971867e+006* | AF4: 389906.9 | AG4: 333077.2 | AH4: 445374.4 | AI4: 443890.2 | AJ4: 450866.9 | AK4: 380270.1 | AL4: 753353.8 | AM4: 703738 | AN4: 574275.9 | AO4: 626590.9 | AP4: 1992870 | AQ4: 1734511 | AR4: 1399044 | AS4: 1573943 | AT4: 6.971054e+004* | AU4: 6.010169e+004* | AV4: 719142.5 | AW4: 938547.2 | AX4: 481775.4 | AY4: 405219.7 | AZ4: 744078.1 | BA4: 702291.7 | BB4: 945182.4 | BC4: 602763.9 | BD4: 370550.02 | BE4: 312037.84 | BF4: 738136.54 | BG4: 575595.58 | BH4: 1072669.6 | BI4: 589380.92 | BJ4: 1137166.9 | BK4: 1303142 | BL4: 979689.03 | BM4: 613415.34 | BN4: 3823600.3 | BO4: 1885801.4 | BP4: 1314754.8 | BQ4: 629888.98 | BR4: 1e+003* | BS4: 2.251561737e+005* | BT4: 85504.333 | BU4: 517262.33 | BV4: 38133.583 | BW4: 1183718 | BX4: 104589.56 | BY4: 924174.19 | BZ4: 313942.32 | CA4: 397298.71 | CB4: 7.481554565e+005* | CC4: 6.772858887e+005* | CD4: 1.124658585e+005* | CE4: 6.889674377e+004* | CF4: 875 | CG4: 875 | CH4: 20973.003 | CI4: 18141.268 | CJ4: 137617.75 | CK4: 77739.113 | CL4: 107412.29 | CM4: 75431.488 | CN4: 14496.294 | CO4: 5900.5914 | CP4: 120452.35 | CQ4: 31181.637 | CR4: 16433.767 | CS4: 6769.9432 | CT4: 23312.632 | CU4: 13016.19 | CV4: 472280.4 | CW4: 287470.46 | CX4: 647553.77 | CY4: 451040.41 | CZ4: 373981.26 | DA4: 338900.51 | DB4: 368617.52 | DC4: 308812.77 | DD4: 420398.44 | DE4: 405656.92 | DF4: 167781.94 | DG4: 162292.65 | DH4: 198767.91 | DI4: 156669.83 | DJ4: 1938159.1 | DK4: 1508030.9 | DL4: 1366762.817* | DM4: 1320554.443* | DN4: 323702.79 | DO4: 314027.56 | DP4: 1116915.5 | DQ4: 1051001 | DR4: 731825.81 | DS4: 429929.99 | DT4: 229954.47 | DU4: 467513.43 | DV4: 494556.85 | DW4: 408751.59 | DX4: 599752.5 | DY4: 839378.3 | DZ4: 345488.13 | EA4: 304043.7 | EB4: 579665.83 | EC4: 443877.32 | ED4: 56727.802 | EE4: 366213.04 | EF4: 456219.82 | EG4: 981401.55 | EH4: 187610.93 | EI4: 156562.85 | EJ4: 289833.53 | EK4: 80086.113 | EL4: 61651.234 | EM4: 592588.75 | EN4: 43053.49 | EO4: 232066.76 | EP4: 8739.5763 | EQ4: 71790.375 | ER4: 221119.52 | ES4: 278875.37 | ET4: 1332190.8 | EU4: 483727.02 | EV4: 948447.51 | EW4: 738240.84 | EX4: 29610.737 | EY4: 33166.321 | EZ4: 77446.64 | FA4: 74008.736 | FB4: 148967.19 | FC4: 157124.11 | FD4: 21747.124 | FE4: 19693.516 | FF4: 103155.9 | FG4: 117071.05 | FH4: 13226.558 | FI4: 14546.884 | FJ4: 5189.6625 | FK4: 4160.5391 | FL4: 32644.394 | FM4: 37757.397 | FN4: 99461.632 | FO4: 100091.32 | FP4: 504429.9 | FQ4: 390306.4 | FR4: 1495462 | FS4: 1495857 | FT4: 162568 | FU4: 97754.67 | FV4: 513224.3 | FW4: 393542.3 | FX4: 493647.8 | FY4: 350089.8 | FZ4: 1109.462 | GA4: 1000 | GB4: 85409.29 | GC4: 85789.06 | GD4: 1067549 | GE4: 1292940 | GF4: 1369468 | GG4: 1393732 | GH4: 369094.67 | GI4: 315156.43 | GJ4: 341345 | GK4: 212067.75 | GL4: 58565.5 | GM4: 46116.5 | GN4: 422416.5 | GO4: 275682.5 | GP4: 205237.25 | GQ4: 172485.25 | GR4: 79817.5 | GS4: 85936.75 | GT4: 299889.56 | GU4: 264692.17 | GV4: 84992 | GW4: 11961.75 | GX4: 43398.029 | GY4: 29855.486 | GZ4: 36108.318 | HA4: 19201.366 | HB4: 43385.044 | HC4: 46825.5 | HD4: 402439.82 | HE4: 331356.29 | HF4: 6879.0846 | HG4: 7755.7478 | HH4: 424640.01 | HI4: 386378.05 | HJ4: 387127.23 | HK4: 294935.18 | HL4: 228637.88 | HM4: 151342.03 | HN4: 386177.64 | HO4: 300186.4 | HP4: 90756.386 | HQ4: 103162.67 | HR4: 701868.29 | HS4: 648418.64 | HT4: 299859.86 | HU4: 453543.88 | HV4: 338482.64 | HW4: 486259.67 | HX4: 679275.94 | HY4: 373912.99 | IB4: 76500.969 | IC4: 87809.235 | ID4: 72074.196 | IE4: 74947.563 | IF4: 21474.403 | IG4: 14405.559 | IH4: 11474.228 | II4: 7524.9438 | IJ4: 6454.9494 | IK4: 1047.471 | IL4: 41769.497 | IM4: 41028.87 | IN4: 4926.3482 | IO4: 1326.8404 | IP4: 73789.139 | IQ4: 49211.163 | IR4: 82655.304 | IS4: 90363.174 | IT4: 78581.665 | IU4: 49657.715 | IV4: 34054.878 | IW4: 52189.342 | IX4: 7921.618 | IY4: 14382.214 | IZ4: 71959.801 | JA4: 54198.383 | JB4: 39500.637 | JC4: 17760.599
A5: 3 | B5: 48150.25 | C5: 45915.25 | D5: 620842.1 | E5: 324218.7 | F5: 1231278 | G5: 424368.3 | H5: 209880.9 | I5: 156009.4 | J5: 1002010 | K5: 943357.4 | L5: 791185.8 | M5: 1017687 | N5: 98744.64 | O5: 839722.8 | P5: 625626.6 | Q5: 480973.2 | R5: 80511.17 | S5: 125548.6 | T5: 294744.7 | U5: 66367.28 | V5: 92875.9 | W5: 43290.84 | X5: 134096.2 | Y5: 111825.1 | Z5: 1264375 | AA5: 1110108 | AB5: 2795059 | AC5: 1472671 | AD5: 1.47405e+006* | AE5: 8.065103e+005* | AF5: 767116.6 | AG5: 895140.7 | AH5: 626895.3 | AJ5: 103521.5 | AK5: 98325.59 | AL5: 513612.4 | AM5: 611041.5 | AN5: 137076.6 | AO5: 154396.4 | AP5: 858132.7 | AQ5: 747297.2 | AR5: 966714.4 | AS5: 835936.7 | AT5: 8.485795e+004* | AU5: 9.543111e+004* | AV5: 265551.1 | AW5: 345897.4 | AX5: 330716.4 | AY5: 308737.3 | AZ5: 469364.4 | BA5: 490019 | BB5: 204905.1 | BC5: 133806.8 | BD5: 1204538.8 | BE5: 739797.73 | BF5: 1733738.3 | BG5: 531259.34 | BH5: 309900.24 | BI5: 426654.21 | BJ5: 1568522.9 | BK5: 1153568.7 | BL5: 252139.66 | BM5: 522378.17 | BN5: 136113.91 | BO5: 52961.006 | BP5: 2212772 | BQ5: 1440573.7 | BR5: 9.385163116e+004* | BS5: 2.441060066e+004* | BT5: 704895.39 | BU5: 845159.42 | BV5: 170059.86 | BW5: 172293.81 | BX5: 276381.23 | BY5: 318930.94 | BZ5: 368930.36 | CA5: 485308.2 | CB5: 7.920079102e+006* | CC5: 6.027200684e+006* | CD5: 2.611281738e+005* | CE5: 1.883332214e+005* | CF5: 343178.59 | CG5: 613953 | CH5: 274522.13 | CI5: 255016.36 | CJ5: 43120.201 | CK5: 45412.823 | CL5: 355679.08 | CM5: 262537.81 | CN5: 390416.84 | CO5: 305458.1 | CP5: 251433.04 | CQ5: 219339.23 | CR5: 40963.936 | CS5: 25309.132 | CT5: 847155.94 | CU5: 711135.5 | CV5: 214757.98 | CW5: 231836.73 | CX5: 544401.55 | CY5: 395378.33 | CZ5: 552131.23 | DA5: 547552.43 | DB5: 387300.78 | DC5: 318821.66 | DD5: 376346.41 | DE5: 275580.75 | DF5: 265091.25 | DG5: 277124.82 | DH5: 479256.32 | DI5: 510713.78 | DJ5: 943220.28 | DK5: 765076.84 | DL5: 2247489.258* | DM5: 2706646.484* | DN5: 616120.12 | DO5: 539353.45 | DP5: 986113.1 | DQ5: 983633.3 | DR5: 350372.38 | DS5: 544603.27 | DT5: 457444.55 | DU5: 222580.15 | DV5: 1669006 | DW5: 978245.42 | DX5: 1090101.8 | DY5: 4914843.3 | DZ5: 545981.08 | EA5: 269199.07 | EB5: 1730618 | EC5: 967378.05 | ED5: 574137.21 | EE5: 631118.35 | EF5: 560442.02 | EG5: 217197.65 | EH5: 739867.86 | EI5: 682333.19 | EJ5: 2015854.2 | EK5: 1439958.4 | EL5: 3089989.3 | EM5: 1119659.7 | EN5: 846978.21 | EO5: 204100.22 | EP5: 238467.32 | EQ5: 338364.87 | ER5: 2841195.3 | ES5: 1257097.4 | ET5: 853386.66 | EU5: 301033.08 | EV5: 149180.73 | EW5: 149685.09 | EX5: 60919.079 | EY5: 63701.069 | EZ5: 70712.845 | FA5: 71343.193 | FB5: 44191.006 | FC5: 48753.429 | FD5: 90690.376 | FE5: 91827.354 | FF5: 122499.31 | FG5: 109570.42 | FH5: 23316.74 | FI5: 20143.612 | FJ5: 10709.892 | FK5: 14303.412 | FL5: 43886.547 | FM5: 42585.613 | FN5: 28463.049 | FO5: 25667.795 | FP5: 453520.8 | FQ5: 530669.8 | FR5: 74284.05 | FS5: 13558.87 | FT5: 155848.7 | FU5: 76861.06 | FV5: 41263.95 | FW5: 277860.5 | FX5: 120721 | FY5: 116693.1 | FZ5: 227588.9 | GA5: 206364.8 | GB5: 396341.9 | GC5: 625134.4 | GD5: 265951.1 | GE5: 359345.8 | GF5: 1087724 | GG5: 695936.1 | GH5: 123955.5 | GI5: 135366 | GJ5: 305184.5 | GK5: 233230.5 | GL5: 10797.25 | GM5: 15251.25 | GN5: 65815.5 | GO5: 34276 | GP5: 36370.5 | GQ5: 17249.25 | GR5: 199121.25 | GS5: 110936.25 | GT5: 564672 | GU5: 509730.62 | GV5: 72346 | GW5: 77442.5 | GX5: 48181.931 | GY5: 52316.578 | GZ5: 306226.84 | HA5: 305113.65 | HB5: 165894.9 | HC5: 156226.29 | HD5: 124902.63 | HE5: 133894.62 | HF5: 8867.0282 | HG5: 11720.551 | HH5: 85852.127 | HI5: 93675.446 | HJ5: 123277.51 | HK5: 146114.12 | HL5: 83961.281 | HM5: 84127.205 | HN5: 88412.582 | HO5: 108617.41 | HP5: 106255.7 | HQ5: 112354.02 | HR5: 146569.41 | HS5: 147665.65 | HT5: 232316.16 | HU5: 211481.55 | HV5: 144546.1 | HW5: 148453.61 | HX5: 35566.944 | HY5: 37966.743 | HZ5: 76937.943 | IA5: 48476.566 | IB5: 151055.19 | IC5: 148529.59 | ID5: 143362.27 | IE5: 67262.856 | IF5: 66200.676 | IG5: 56829.468 | IH5: 22105.465 | II5: 24528.421 | IJ5: 37524.83 | IK5: 40040.195 | IL5: 329737.73 | IM5: 282361.48 | IN5: 285958.28 | IO5: 294965.79 | IP5: 104982.97 | IQ5: 103134.94 | IR5: 268496.12 | IS5: 314939.21 | IT5: 169269.81 | IU5: 257196.41 | IV5: 81675.11 | IW5: 105467.02 | IX5: 46584.053 | IY5: 56642.433 | IZ5: 139929.41 | JA5: 166913.28 | JB5: 82362.648 | JC5: 82323.166
A6: 4 | B6: 23679.88 | C6: 16674.76 | D6: 116832.3 | E6: 133953.2 | F6: 93269.36 | H6: 194576.1 | I6: 329833.1 | J6: 370390.3 | K6: 463724.9 | L6: 493019.5 | M6: 514106.6 | N6: 64016.26 | O6: 58588.19 | P6: 58008.6 | Q6: 54259.5 | R6: 51466.07 | S6: 37159.11 | T6: 242290.9 | U6: 332192.9 | V6: 110662.9 | W6: 54086.51 | X6: 122162.4 | Y6: 114489.7 | Z6: 592683.8 | AA6: 470548 | AB6: 492871.1 | AC6: 552674.6 | AD6: 2.823046e+006* | AE6: 2.773845e+006* | AF6: 124051.1 | AG6: 187651.9 | AH6: 278646.7 | AJ6: 46460.25 | AK6: 50484 | AL6: 146882.2 | AM6: 150529.2 | AN6: 105198.5 | AO6: 82429.75 | AP6: 140199.5 | AQ6: 120701 | AR6: 119601.8 | AS6: 122069.8 | AT6: 5.019044e+006* | AU6: 3.957005e+006* | AV6: 204020.5 | AW6: 177270 | AX6: 54640 | AY6: 47135.5 | AZ6: 214839.8 | BA6: 244214.2 | BB6: 282275.2 | BC6: 385914 | BD6: 37046.299 | BE6: 18500.38 | BF6: 74864.334 | BG6: 56910.728 | BH6: 27403.543 | BI6: 3527.7975 | BJ6: 110657.15 | BK6: 127353.37 | BL6: 249093.06 | BM6: 496486.54 | BN6: 463152.19 | BO6: 306429.47 | BP6: 210419.77 | BQ6: 196323.29 | BR6: 2.410835571e+005* | BS6: 2.099333344e+005* | BT6: 177058.94 | BU6: 126008.08 | BV6: 251389.27 | BW6: 261546.33 | BX6: 20300.737 | BY6: 34673.733 | BZ6: 131771.53 | CA6: 108264.4 | CB6: 3.050324951e+006* | CC6: 1.497937744e+006* | CD6: 1.933562469e+005* | CE6: 2.31818985e+005* | CF6: 727620.12 | CG6: 770915.1 | CH6: 395839.17 | CI6: 278240.51 | CJ6: 49803.604 | CK6: 65676.208 | CL6: 47736.629 | CM6: 55644.791 | CN6: 453939.45 | CO6: 287582.61 | CP6: 72595.772 | CQ6: 54178.638 | CR6: 178362.99 | CS6: 175313.89 | CT6: 129369.23 | CU6: 132216.14 | CV6: 14433.831 | CW6: 18123.119 | CX6: 218701.1 | CY6: 147166.81 | CZ6: 98853.767 | DA6: 99578.064 | DB6: 117044.26 | DC6: 102085.26 | DD6: 109190.63 | DE6: 134035.25 | DF6: 195704.42 | DG6: 208921.63 | DH6: 226677.48 | DI6: 215709.82 | DJ6: 315002.62 | DK6: 355923.61 | DL6: 405814.8499* | DM6: 384405.9143* | DN6: 187973.42 | DO6: 221471.89 | DP6: 149605.73 | DQ6: 130807.24 | DR6: 81966.072 | DS6: 89477.135 | DT6: 808631.04 | DU6: 609046.26 | DV6: 289380.55 | DW6: 290191.31 | DX6: 253419.48 | DY6: 209247.02 | DZ6: 258327.33 | EA6: 264598.6 | EB6: 500905.36 | EC6: 479874.45 | ED6: 232664.15 | EE6: 178422.13 | EF6: 446328.46 | EG6: 339041.63 | EH6: 250520.92 | EI6: 250397.16 | EJ6: 814211.73 | EK6: 649524.11 | EL6: 385064.45 | EM6: 238431.78 | EN6: 35093.14 | EO6: 25831.614 | EP6: 208121.38 | EQ6: 193145.65 | ER6: 189858.63 | ES6: 109901.19 | ET6: 100598.91 | EU6: 15643.716 | EV6: 36960.442 | EW6: 31138.414 | EX6: 10407.813 | EY6: 10798.672 | EZ6: 15485.414 | FA6: 14714.582 | FB6: 22642.351 | FC6: 24356.806 | FD6: 48425.674 | FE6: 53768.52 | FF6: 22554.07 | FG6: 23656.168 | FH6: 6793.4885 | FI6: 8719.7084 | FJ6: 3577.0035 | FK6: 2930.7106 | FL6: 11136.743 | FM6: 11834.881 | FN6: 24014.633 | FO6: 18624.508 | FP6: 834554.2 | FQ6: 902801.2 | FR6: 481520.5 | FS6: 440011.5 | FT6: 101191.5 | FU6: 17882.25 | FV6: 364287 | FW6: 964683.1 | FX6: 331322.2 | FY6: 372417.8 | FZ6: 281443.2 | GA6: 373680.4 | GB6: 106739.8 | GC6: 146271 | GD6: 722832.1 | GE6: 627694.6 | GF6: 383033.9 | GG6: 405968.9 | GH6: 70197.479 | GI6: 59629.242 | GJ6: 83015.06 | GK6: 77175.682 | GL6: 33476.326 | GM6: 33533.176 | GN6: 42384.113 | GO6: 45191.845 | GP6: 45266.956 | GQ6: 51665.916 | GR6: 71153.625 | GS6: 74105.431 | GT6: 59222.82 | GU6: 56373.936 | GV6: 45163.841 | GW6: 36545.059 | GX6: 56822.784 | GY6: 42622.711 | GZ6: 202354.64 | HA6: 223440.15 | HB6: 165048.63 | HC6: 183490.97 | HD6: 198451.31 | HE6: 188158.02 | HF6: 38447.697 | HG6: 43096.836 | HH6: 87514.084 | HI6: 109834.19 | HJ6: 480568.33 | HK6: 337873.26 | HL6: 198596.48 | HM6: 173012.8 | HN6: 83099.159 | HO6: 74581.947 | HP6: 195047.15 | HQ6: 199803.73 | HR6: 288401.89 | HS6: 285943.76 | HT6: 401222.23 | HU6: 434581.63 | HV6: 122474.38 | HW6: 110373.36 | HX6: 100532.88 | HY6: 119794.24 | HZ6: 857331.79 | IA6: 293166.17 | IB6: 122465.87 | IC6: 100590.33 | ID6: 95574.6 | IE6: 41976.322 | IF6: 209636.35 | IG6: 176349.44 | IH6: 81315.392 | II6: 74427.895 | IJ6: 249943.31 | IK6: 188284.79 | IL6: 259619.63 | IM6: 281387.76 | IN6: 1257272.1 | IO6: 1179616.8 | IP6: 136994.89 | IQ6: 127046.72 | IR6: 668193.66 | IS6: 222617.71 | IT6: 531049.26 | IU6: 194059.49 | IV6: 185579.33 | IW6: 58368.801 | IX6: 292286.29 | IY6: 80767.418 | IZ6: 99990.017 | JA6: 122764.13 | JB6: 330305.17 | JC6: 260198.3
A7: 5 | B7: 9652.154 | C7: 10014.09 | D7: 59048.82 | E7: 29491.55 | F7: 9998.865 | G7: 18823.49 | H7: 28188.49 | I7: 30313.54 | J7: 60448.49 | L7: 120621.8 | M7: 84243.05 | N7: 269724.9 | O7: 96723.82 | P7: 60525.26 | Q7: 73152.83 | R7: 68137.48 | S7: 75824.67 | T7: 181064.7 | U7: 174326.8 | V7: 188947.5 | W7: 225469.1 | X7: 13882.88 | Y7: 12411.26 | Z7: 22435.58 | AA7: 60123.74 | AB7: 1201155 | AC7: 1105592 | AD7: 5.741935e+004* | AE7: 1.339658e+005* | AF7: 281665 | AG7: 8888.155 | AH7: 25179.52 | AI7: 33194.28 | AJ7: 9829.775 | AK7: 11821.04 | AL7: 259003.8 | AM7: 264814.3 | AN7: 10212.04 | AO7: 3607.808 | AP7: 77330.95 | AQ7: 99307.33 | AR7: 197111 | AS7: 186130 | AT7: 4.300618e+005* | AU7: 4.449197e+005* | AV7: 245931 | AW7: 285896.1 | AX7: 12605.37 | AY7: 3926.041 | AZ7: 110520.5 | BA7: 122017 | BB7: 556055.1 | BC7: 599796.3 | BD7: 19458.059 | BE7: 16515.821 | BF7: 33465.721 | BG7: 23450.634 | BH7: 51681.45 | BI7: 77366.013 | BJ7: 369623.6 | BK7: 294710.42 | BL7: 112075.39 | BM7: 117672.39 | BN7: 1904723.3 | BO7: 1635262.2 | BP7: 184070.88 | BQ7: 100391.96 | BT7: 63824.394 | BU7: 108008.64 | BV7: 94769.455 | BW7: 50760.887 | BX7: 85484.413 | BY7: 51750.237 | BZ7: 103936.94 | CA7: 86841.377 | CD7: 1.39648407e+005* | CE7: 4.558027649e+004* | CF7: 323351.2 | CG7: 368729.74 | CH7: 271770.26 | CI7: 378331.73 | CJ7: 119415.44 | CK7: 80317.924 | CL7: 16627.508 | CM7: 17013.689 | CN7: 4405.654 | CO7: 3941.2301 | CP7: 77390.656 | CQ7: 83409.164 | CR7: 55265.839 | CS7: 47685.863 | CT7: 106224.04 | CU7: 81698.471 | CV7: 800 | CW7: 800 | CX7: 20989.204 | CY7: 22562.469 | CZ7: 42707.054 | DA7: 45890.232 | DB7: 21776.14 | DC7: 20388.66 | DD7: 18585.76 | DE7: 21016.569 | DF7: 15906.202 | DG7: 17782.2 | DH7: 25599.304 | DI7: 28679.728 | DJ7: 71599.686 | DK7: 70790.81 | DL7: 148532.3792* | DM7: 147334.7931* | DN7: 103165.54 | DO7: 94403.122 | DP7: 48019.646 | DQ7: 57061.218 | DR7: 43068.287 | DS7: 43637.81 | DT7: 389358.49 | DU7: 440008.91 | DV7: 241947.95 | DW7: 148008.59 | DX7: 64707.008 | DY7: 73943.237 | DZ7: 116832.15 | EA7: 112818.42 | EB7: 133718 | EC7: 139325.03 | ED7: 122700.62 | EE7: 133718.35 | EF7: 236347.66 | EG7: 148512.3 | EH7: 163904.36 | EI7: 147312.5 | EJ7: 506807.19 | EK7: 547616.94 | EL7: 204178.01 | EM7: 150907.26 | EN7: 118905.19 | EO7: 109096.47 | EP7: 286276.28 | EQ7: 236691.62 | ER7: 327696.69 | ES7: 370125.95 | ET7: 67845.245 | EU7: 107183.28 | EV7: 77736.183 | EW7: 70709.663 | EX7: 11049.001 | EY7: 12231.382 | EZ7: 24709.562 | FA7: 20493.425 | FB7: 28147.139 | FC7: 25034.765 | FD7: 38308.048 | FE7: 42028.103 | FF7: 63504.04 | FG7: 65686.89 | FH7: 11796.585 | FI7: 12588.934 | FJ7: 7577.2524 | FK7: 8446.7154 | FL7: 25032.36 | FM7: 35146.446 | FN7: 43254.787 | FO7: 51047.882 | FP7: 362459 | FQ7: 391602 | FR7: 311733.1 | FS7: 260341.3 | FT7: 55711.73 | FU7: 62852.04 | FV7: 102040.2 | FW7: 19621.67 | FX7: 74767.23 | FY7: 282910.1 | FZ7: 26346.54 | GA7: 17759.42 | GB7: 367901.3 | GC7: 351273 | GD7: 101960.9 | GE7: 38696.44 | GF7: 140029.3 | GG7: 133003.3 | GH7: 85164.055 | GI7: 84298.218 | GJ7: 78188.026 | GK7: 46491.169 | GL7: 127781.67 | GM7: 111089.74 | GN7: 71780.029 | GO7: 45580.227 | GP7: 112089.15 | GQ7: 99738.098 | GR7: 210410.02 | GS7: 207960.3 | GT7: 162975.42 | GU7: 152521.18 | GV7: 74603.79 | GW7: 50849.808 | GX7: 22112.024 | GY7: 10050.433 | GZ7: 207808.18 | HA7: 233133.67 | HB7: 244825.74 | HC7: 274905.18 | HE7: 222579.93 | HF7: 55544.289 | HG7: 64307.816 | HH7: 202277.5 | HI7: 193357.44 | HJ7: 37428.131 | HK7: 70133.781 | HL7: 296964.72 | HM7: 362322.3 | HN7: 172880.02 | HO7: 187124.36 | HP7: 268889.25 | HQ7: 313322.27 | HR7: 541384.16 | HS7: 595120.42 | HV7: 162820.59 | HW7: 160303.19 | HX7: 161243.15 | HY7: 168920.23 | HZ7: 341806.94 | IA7: 322836.04 | IB7: 175681.17 | IC7: 160334.71 | ID7: 79432.148 | IE7: 127261.18 | IF7: 201592.37 | IG7: 226611.95 | IH7: 141655.8 | II7: 133393.87 | IJ7: 181544.51 | IK7: 192280.2 | IL7: 290489.2 | IM7: 282865.63 | IN7: 386549.88 | IO7: 306665.5 | IP7: 169844.31 | IQ7: 198425.31 | IR7: 114080.52 | IS7: 123084.59 | IT7: 197303.26 | IU7: 183152.52 | IV7: 108543.79 | IW7: 123773.9 | IX7: 67234.119 | IY7: 72193.686 | IZ7: 115624.01 | JA7: 118876.95 | JB7: 226022.6 | JC7: 241097.44
A8: 6 | B8: 100 | C8: 100 | D8: 8421.177 | E8: 7114.775 | F8: 150 | G8: 1439.098 | H8: 3441.07 | I8: 1857.14 | J8: 16608.32 | K8: 3583.121 | L8: 10289.7 | N8: 1803.462 | O8: 4306.246 | P8: 5523.722 | Q8: 3053.028 | S8: 17929.54 | T8: 32621.49 | U8: 37500.8 | V8: 18378.99 | W8: 3876.251 | X8: 4562.226 | Y8: 4524.771 | Z8: 209161.2 | AA8: 186712.3 | AB8: 10226.7 | AC8: 8012.44 | AD8: 2.331222e+005* | AE8: 2.693312e+005* | AG8: 1087.03 | AH8: 12432.13 | AI8: 41618.06 | AJ8: 6482.078 | AK8: 1000 | AL8: 6888.131 | AM8: 4735.155 | AN8: 1000 | AO8: 1106.996 | AP8: 12381.93 | AQ8: 4199.805 | AR8: 7420.821 | AS8: 3338.041 | AV8: 25735.68 | AW8: 27143.04 | AX8: 550 | AY8: 550 | AZ8: 5547.662 | BA8: 2936.203 | BB8: 13928.59 | BC8: 12255.14 | BD8: 2308.6712 | BE8: 23483.98 | BF8: 650 | BG8: 650 | BH8: 1174.297 | BI8: 1000 | BJ8: 30242.437 | BK8: 17400.072 | BL8: 16779.449 | BM8: 19988.726 | BN8: 45738.815 | BO8: 45182.823 | BP8: 5980.3486 | BQ8: 10788.258 | BT8: 4396.9994 | BU8: 1000 | BV8: 21464.201 | BW8: 13198.649 | BX8: 2894.7876 | BY8: 1101.5186 | BZ8: 6037.9682 | CA8: 2125.845 | CD8: 3.769528198e+004* | CE8: 3.57279892e+004* | CF8: 875 | CG8: 875 | CH8: 5926.6095 | CI8: 7587.5201 | CJ8: 19364.969 | CK8: 21502.028 | CL8: 1627.7903 | CM8: 6108.5968 | CN8: 4339.2358 | CO8: 5761.8113 | CP8: 2664.2785 | CQ8: 5538.6219 | CR8: 17594.36 | CS8: 12110.708 | CT8: 700 | CU8: 700 | CV8: 9545.9127 | CW8: 5870.4834 | CX8: 7456.3479 | CY8: 9166.1787 | CZ8: 4808.7258 | DA8: 8286.9711 | DB8: 4821.0902 | DC8: 3906.2328 | DD8: 4343.2379 | DE8: 1985.5402 | DF8: 2699.9857 | DG8: 2455.5781 | DH8: 4004.1075 | DI8: 2405.7641 | DJ8: 14023.069 | DK8: 11635.307 | DL8: 95055.87006* | DM8: 102745.575* | DN8: 32242.561 | DO8: 26051.979 | DP8: 4054.7729 | DQ8: 1001.4088 | DR8: 1000 | DS8: 2191.2405 | DT8: 41091.434 | DU8: 59481.575 | DV8: 73833.313 | DW8: 49008.438 | DX8: 10879.959 | DY8: 10447.989 | DZ8: 37230.503 | EA8: 55812.061 | EB8: 57263.405 | EC8: 74401.665 | ED8: 6547.2159 | EE8: 8166.6851 | EF8: 27738.678 | EG8: 25128.237 | EH8: 34526.47 | EI8: 30919.291 | EJ8: 27390.993 | EK8: 49198.349 | EL8: 95095.406 | EM8: 109535.61 | EN8: 45883.69 | EO8: 39569.103 | EP8: 437558.93 | EQ8: 382570.25 | ER8: 185174.71 | ES8: 190540.89 | ET8: 54815.361 | EU8: 62847.897 | EV8: 61361.591 | EW8: 59522.057 | EX8: 10308.003 | EY8: 11865.157 | EZ8: 24394.686 | FA8: 22961.943 | FB8: 59883.518 | FC8: 58127.293 | FD8: 69006.699 | FE8: 62741.009 | FF8: 135775.04 | FG8: 132957.37 | FH8: 15821.92 | FI8: 13199.044 | FJ8: 20492.025 | FK8: 17747.231 | FL8: 31171.976 | FM8: 42972.37 | FN8: 58562.92 | FO8: 52757.332 | FP8: 1152532 | FQ8: 1027226 | FR8: 1856239 | FS8: 2113520 | FT8: 1318451 | FU8: 1382890 | FV8: 2282796 | FW8: 2877624 | FX8: 906918.6 | FY8: 1209465 | FZ8: 2406335 | GA8: 2318032 | GB8: 1378507 | GC8: 1419379 | GD8: 1497244 | GE8: 1525984 | GF8: 257820.4 | GG8: 220672.9 | GH8: 36562.973 | GI8: 39188.068 | GJ8: 51050.705 | GK8: 122259.22 | GL8: 74591.599 | GM8: 116243.68 | GN8: 56923.26 | GO8: 45661.602 | GP8: 36725.655 | GQ8: 36076.672 | GR8: 62158.661 | GS8: 65245.903 | GT8: 72599.449 | GU8: 67461.7 | GV8: 22795.914 | GW8: 21689.11 | GX8: 9572.5393 | GY8: 11717.377 | GZ8: 61208.611 | HA8: 49218.193 | HB8: 112067.81 | HC8: 82505.493 | HD8: 28091 | HE8: 20684.357 | HF8: 12069.318 | HG8: 10580.486 | HH8: 42528.831 | HI8: 47612.862 | HJ8: 60271.74 | HK8: 56748.528 | HL8: 63518.215 | HM8: 78490.196 | HN8: 48746.227 | HO8: 50105.644 | HP8: 48814.293 | HQ8: 62500.874 | HR8: 79245.399 | HS8: 78347.786 | HT8: 115740.88 | HU8: 92875.908 | HV8: 30762.577 | HW8: 32779.339 | HX8: 46579.212 | HY8: 51125.843 | HZ8: 26897.839 | IA8: 19443.575 | IB8: 72553.162 | IC8: 127706.2 | ID8: 112124.4 | IE8: 121099.4 | IF8: 121995.51 | IG8: 111298.71 | IH8: 111117.26 | II8: 81294.037 | IJ8: 272199.52 | IK8: 271742.68 | IL8: 430923.98 | IM8: 429064.36 | IN8: 159808.78 | IO8: 190537.83 | IP8: 85761.322 | IQ8: 93400.726 | IR8: 120279.55 | IS8: 133723.24 | IT8: 154102.14 | IU8: 129232.67 | IV8: 50003.914 | IW8: 52976.334 | IX8: 35740.589 | IY8: 31397.297 | IZ8: 44612.476 | JA8: 45563.82 | JB8: 20429.647 | JC8: 46448.83
A9: 7 | C9: 100 | D9: 150 | F9: 150 | G9: 150 | H9: 175 | I9: 175 | J9: 19260.95 | K9: 16116.3 | L9: 29264 | M9: 7198.456 | N9: 225 | O9: 225 | P9: 1238.444 | Q9: 1584.721 | R9: 7241.785 | S9: 8484.36 | U9: 37520.47 | V9: 1753.66 | X9: 5001.742 | Y9: 325 | Z9: 164940.2 | AA9: 84602.29 | AB9: 16207.39 | AC9: 29208.21 | AF9: 375 | AG9: 375 | AH9: 33470.24 | AI9: 16754.09 | AJ9: 9366.521 | AK9: 13043.17 | AL9: 2678.863 | AM9: 9912.648 | AN9: 2448.823 | AO9: 5423.941 | AP9: 4396.257 | AQ9: 4543.801 | AR9: 3169.97 | AS9: 1000 | AV9: 46098.57 | AW9: 58775.3 | AX9: 1976.931 | AY9: 1000 | AZ9: 1490.265 | BA9: 1000 | BB9: 6326.991 | BC9: 4648.904 | BD9: 625 | BE9: 625 | BF9: 650 | BG9: 650 | BH9: 675 | BI9: 675 | BJ9: 63646.412 | BK9: 39710.541 | BL9: 700 | BM9: 700 | BN9: 23046.345 | BO9: 20014.399 | BP9: 3229.0032 | BQ9: 1593.2374 | BT9: 6079.9246 | BU9: 3821.9903 | BV9: 1000 | BW9: 1061.3061 | BX9: 775 | BY9: 775 | BZ9: 1537.9982 | CA9: 1282.694 | CF9: 6287.3421 | CG9: 1000 | CH9: 4536.3045 | CI9: 3752.9297 | CJ9: 15868.738 | CK9: 24288.16 | CL9: 300 | CM9: 300 | CN9: 2277.0534 | CO9: 4813.7641 | CP9: 6417.8019 | CQ9: 1882.9571 | CR9: 600 | CS9: 600 | CT9: 33053.288 | CU9: 35358.334 | CV9: 2212.2998 | CW9: 5727.3154 | CX9: 900 | CY9: 900 | CZ9: 2010.4568 | DA9: 1282.0625 | DB9: 14473.532 | DC9: 14681.541 | DD9: 1208.6786 | DE9: 1614.5357 | DF9: 2123.9653 | DG9: 1763.6483 | DH9: 4980.0215 | DI9: 4920.3801 | DJ9: 5338.9344 | DK9: 2205.6155 | DN9: 105699.96 | DO9: 97659.737 | DP9: 1048.46 | DQ9: 1170.1859 | DR9: 74158.974 | DS9: 53977.688 | DT9: 327686.98 | DU9: 373066.41 | DV9: 576892.09 | DW9: 569284.48 | DX9: 128321.76 | DY9: 135047.93 | DZ9: 248795.68 | EA9: 243333.08 | EB9: 129411.47 | EC9: 106905.41 | ED9: 221908.16 | EE9: 225738.05 | EF9: 149026.08 | EG9: 43309.448 | EH9: 90722.252 | EI9: 57430.626 | EJ9: 5352.3016 | EK9: 1000 | EL9: 388473.08 | EM9: 473116.27 | EN9: 9895.6642 | EO9: 17516.222 | EP9: 354424.74 | EQ9: 363830.93 | ER9: 181850.92 | ES9: 180128.78 | ET9: 118718.76 | EU9: 69500.275 | EV9: 48022.236 | EW9: 54645.206 | EX9: 7574.3318 | EY9: 6341.7506 | EZ9: 6084.4274 | FA9: 9107.5373 | FB9: 10443.911 | FC9: 12258.884 | FD9: 21032.003 | FE9: 23479.126 | FF9: 43778.263 | FG9: 47665.863 | FH9: 9212.7056 | FI9: 10247.955 | FJ9: 13247.994 | FK9: 14911.779 | FL9: 12264.835 | FM9: 8066.3929 | FN9: 19186.747 | FO9: 15582.744 | FP9: 333351.5 | FQ9: 349528.6 | FR9: 522250.7 | FS9: 117689.6 | FT9: 222412.1 | FU9: 318137.2 | FV9: 837728 | FW9: 597391.9 | FX9: 1241652 | FY9: 1481489 | FZ9: 340240.5 | GA9: 311909.2 | GB9: 166313.3 | GC9: 212014.2 | GD9: 119899.2 | GE9: 23010.41 | GF9: 15407.86 | GG9: 30997.19 | GH9: 66704.842 | GI9: 54507.061 | GJ9: 106715.4 | GK9: 122989.17 | GL9: 174065.66 | GM9: 160921.77 | GN9: 241958.5 | GO9: 237307.19 | GP9: 62745.602 | GQ9: 59300.713 | GR9: 65051.292 | GS9: 60199.31 | GT9: 197464.28 | GU9: 172014.1 | GV9: 60740.669 | GW9: 62064.907 | GX9: 29155.378 | GY9: 29038.801 | GZ9: 153990.74 | HA9: 197466.05 | HB9: 167728.42 | HC9: 163531.07 | HD9: 27864.569 | HE9: 31185.505 | HF9: 355451.39 | HG9: 378224.91 | HH9: 10035.686 | HI9: 10589.602 | HJ9: 45771.942 | HK9: 55676.392 | HL9: 20051.401 | HM9: 23667.305 | HN9: 21093.845 | HO9: 18553.764 | HP9: 314545.53 | HQ9: 319366.42 | HR9: 519499.63 | HS9: 610852.23 | HT9: 209023.99 | HU9: 230417.47 | HV9: 290722.96 | HW9: 272150.7 | HX9: 329926.36 | HY9: 324066.96 | HZ9: 83732.151 | IA9: 104837.7 | IB9: 83702.591 | IC9: 88895.065 | ID9: 236485.26 | IE9: 198723.13 | IF9: 74333.687 | IG9: 88777.107 | IH9: 104575.23 | II9: 69831.36 | IJ9: 177789.6 | IK9: 175618.12 | IL9: 326841.13 | IM9: 296297.21 | IN9: 141403.96 | IO9: 126972.09 | IP9: 80598.015 | IQ9: 70662.743 | IR9: 117045.13 | IS9: 101014.66 | IT9: 134918.84 | IU9: 40954.117 | IV9: 69768.669 | IW9: 76532.639 | IX9: 40916.473 | IY9: 42519.913 | IZ9: 229884.29 | JA9: 206908.31 | JB9: 161072.81 | JC9: 119187.51
A10: 8 | C10: 100 | D10: 1402.587 | E10: 1543.419 | G10: 2400.679 | H10: 29490.19 | I10: 42556.27 | J10: 7240.208 | K10: 2681.838 | L10: 1905.022 | M10: 3079.95 | N10: 225 | O10: 225 | P10: 250 | R10: 1226.452 | S10: 5138.461 | T10: 19015.71 | U10: 15527.13 | V10: 1469.808 | W10: 1063.569 | X10: 8218.693 | Y10: 3188.707 | Z10: 247112.8 | AA10: 197157.9 | AB10: 1137.991 | AC10: 2702.855 | AF10: 5638.083 | AG10: 7002.655 | AH10: 14926.12 | AI10: 44932.72 | AJ10: 400 | AK10: 400 | AL10: 1588.818 | AM10: 2279.624 | AN10: 450 | AO10: 450 | AP10: 475 | AQ10: 475 | AR10: 5253.237 | AS10: 4144.569 | AV10: 525 | AW10: 525 | AX10: 9929.228 | AY10: 6492.203 | AZ10: 575 | BA10: 575 | BB10: 3882.467 | BC10: 2847.752 | BD10: 625 | BE10: 625 | BF10: 650 | BG10: 650 | BH10: 675 | BI10: 675 | BJ10: 47358.54 | BK10: 64686.806 | BL10: 190696.11 | BM10: 151151.4 | BN10: 121084.79 | BO10: 83984.97 | BP10: 52664.04 | BQ10: 44739.494 | BT10: 50547.924 | BU10: 34038.254 | BV10: 76295.853 | BW10: 62367.069 | BX10: 7417.4128 | BY10: 9994.6842 | BZ10: 800 | CA10: 800 | CF10: 3542.1383 | CG10: 5809.936 | CH10: 150 | CI10: 150 | CJ10: 200 | CK10: 200 | CL10: 300 | CM10: 300 | CN10: 400 | CO10: 400 | CP10: 1000 | CQ10: 1005.8596 | CR10: 600 | CS10: 600 | CT10: 1137.0364 | CU10: 5219.4448 | CV10: 800 | CW10: 800 | CX10: 900 | CY10: 900 | CZ10: 1065.2537 | DA10: 1684.3114 | DB10: 392409.09 | DC10: 368731.63 | DD10: 350 | DE10: 350 | DF10: 450 | DG10: 450 | DH10: 47354.107 | DI10: 46983.654 | DJ10: 17514.843 | DK10: 21304.882 | DN10: 101486.76 | DO10: 117202.74 | DP10: 29543.125 | DQ10: 36101.734 | DR10: 119200.97 | DS10: 180684.3 | DT10: 246211.14 | DU10: 189702.15 | DV10: 173307.62 | DW10: 191576.2 | DX10: 175593.99 | DY10: 174389.82 | DZ10: 217565.2 | EA10: 195255.86 | EB10: 259263.52 | EC10: 207233.63 | ED10: 190058.3 | EE10: 167180.8 | EF10: 55320.354 | EG10: 78166.275 | EH10: 297028.08 | EI10: 282552.19 | EJ10: 208994.55 | EK10: 182457.86 | EN10: 14612.526 | EO10: 1000 | EP10: 341763.31 | EQ10: 347443.24 | ER10: 188628.27 | ES10: 169806.12 | ET10: 184526.93 | EU10: 164013.35 | EV10: 118126.54 | EW10: 122945.75 | EX10: 202388.84 | EY10: 197769.85 | EZ10: 1015369.9 | FA10: 907638.98 | FB10: 260714.11 | FC10: 253259.66 | FD10: 308733.76 | FE10: 328443.91 | FF10: 944594.6 | FG10: 979362.49 | FH10: 667423.65 | FI10: 702760.19 | FJ10: 147336.7 | FK10: 150010.59 | FL10: 423525.7 | FM10: 444993.1 | FN10: 393089.78 | FO10: 359155.46 | FP10: 97886.15 | FQ10: 108380.5 | FR10: 1707781 | FS10: 2523630 | FT10: 253365.2 | FU10: 296896.3 | FV10: 69770.2 | FW10: 158263.8 | FX10: 284462.1 | FY10: 472839.2 | FZ10: 64376.07 | GA10: 66912.69 | GB10: 474055.8 | GC10: 426893 | GD10: 195887.3 | GE10: 197472.4 | GF10: 4985.997 | GG10: 2575.348 | GH10: 138821.88 | GI10: 96429.787 | GJ10: 68372.452 | GK10: 48808.746 | GL10: 134693.41 | GM10: 131497.79 | GN10: 90096.321 | GO10: 76727.936 | GP10: 19806.713 | GQ10: 48211.754 | GR10: 53092.003 | GS10: 59643.955 | GT10: 413541.96 | GU10: 436984.74 | GV10: 164339.58 | GW10: 63379.913 | GX10: 39579.758 | GY10: 58067.715 | GZ10: 71968.956 | HA10: 67877.609 | HB10: 102567.73 | HC10: 87463.463 | HD10: 140754.9 | HE10: 169858.37 | HF10: 255349.69 | HG10: 232027.37 | HH10: 278704.16 | HI10: 285318.18 | HJ10: 52843.208 | HK10: 46583.969 | HL10: 23974.054 | HM10: 23752.01 | HN10: 171958.76 | HO10: 205135.33 | HP10: 144475.23 | HQ10: 146451.36 | HR10: 142943.08 | HS10: 163860.55 | HT10: 129187.19 | HU10: 134150.27 | HV10: 145944.14 | HW10: 145579.35 | HX10: 202887.63 | HY10: 212742.86 | HZ10: 244952.35 | IA10: 265966.98 | IB10: 73108.955 | IC10: 67057.808 | ID10: 104274.6 | IE10: 96965.317 | IF10: 110082.32 | IG10: 108218.23 | IH10: 124782.91 | II10: 121441.77 | IJ10: 285646.7 | IK10: 202132.92 | IN10: 161966.31 | IO10: 122721.6 | IP10: 57067.062 | IQ10: 56072.376 | IR10: 107522.28 | IS10: 109102.4 | IT10: 332563.72 | IU10: 259356.9 | IV10: 225146.23 | IW10: 190170.87 | IX10: 129811.77 | IY10: 85717.636 | IZ10: 204349.81 | JA10: 136697.72 | JB10: 164954.88 | JC10: 110178.69
A11: 9 | B11: 1787.839 | D11: 3619.834 | E11: 1228.187 | G11: 150 | H11: 229114.8 | I11: 313293 | J11: 32476.7 | K11: 32589.12 | L11: 1137.711 | N11: 225 | O11: 225 | P11: 15881.49 | Q11: 5227.599 | R11: 4874.872 | S11: 6260.458 | T11: 12821.76 | U11: 16540.35 | V11: 36367.85 | W11: 26019.28 | X11: 325 | Y11: 325 | Z11: 60090.33 | AA11: 76763.38 | AC11: 350 | AF11: 375 | AG11: 375 | AH11: 1157.471 | AI11: 3443.771 | AJ11: 3281.049 | AK11: 1000 | AL11: 1000 | AM11: 1960.148 | AN11: 450 | AO11: 450 | AP11: 10938.08 | AQ11: 1000 | AR11: 500 | AS11: 500 | AV11: 1173.655 | AW11: 1000 | AZ11: 575 | BA11: 575 | BB11: 600 | BC11: 600 | BD11: 625 | BE11: 625 | BF11: 650 | BG11: 650 | BH11: 675 | BI11: 675 | BJ11: 366030 | BK11: 350238.19 | BL11: 440885.13 | BM11: 587824.71 | BN11: 2115301.3 | BO11: 2435939.7 | BP11: 274227.84 | BQ11: 440991.58 | BT11: 274239.26 | BU11: 115563.48 | BV11: 631475.1 | BW11: 347391.24 | BX11: 1000 | BY11: 3185.7009 | BZ11: 800 | CA11: 800 | CF11: 875 | CG11: 875 | CH11: 3096099.9 | CI11: 2866963.4 | CJ11: 1840.5228 | CK11: 1170.8864 | CL11: 1000 | CM11: 5172.1601 | CN11: 1233.2982 | CO11: 1211.9024 | CP11: 2215.1771 | CQ11: 3599.9358 | CR11: 17182.878 | CS11: 7699.9111 | CT11: 4986.095 | CU11: 5996.0032 | CV11: 800 | CW11: 800 | CX11: 3844.084 | CY11: 1000 | CZ11: 15121.368 | DA11: 16607.063 | DB11: 1615181.9 | DC11: 1387381.1 | DD11: 350 | DE11: 350 | DF11: 7376.2393 | DG11: 6656.7731 | DH11: 2870901.9 | DI11: 2895745.1 | DJ11: 537236.63 | DK11: 486738.13 | DN11: 86244.713 | DO11: 73700.844 | DP11: 826866.88 | DQ11: 768486.69 | DR11: 397678.74 | DS11: 406580.78 | DT11: 258800.9 | DU11: 253876.25 | DV11: 903969.85 | DW11: 899146.97 | DX11: 537017.21 | DY11: 571462.95 | DZ11: 97648.308 | EA11: 196591.4 | EB11: 323797.82 | EC11: 300794.25 | ED11: 50993.179 | EE11: 54614.59 | EF11: 124530.72 | EG11: 122742.83 | EH11: 340542.88 | EI11: 320489.04 | EJ11: 595280.33 | EK11: 472529.88 | EN11: 408079.68 | EO11: 643898.62 | EP11: 274182.04 | EQ11: 307314.03 | ER11: 27644.398 | ES11: 254411.67 | ET11: 62439.19 | EU11: 182043.93 | EV11: 486642.82 | EW11: 507629.39 | EX11: 108199.09 | EY11: 112846.57 | EZ11: 492409.67 | FA11: 467289.12 | FB11: 160589.42 | FC11: 157196.91 | FD11: 511207.95 | FE11: 587043.64 | FF11: 623732.54 | FG11: 615633.67 | FH11: 149933.53 | FI11: 146281.77 | FJ11: 119391.04 | FK11: 116686.42 | FL11: 438107.36 | FM11: 415601.17 | FN11: 246943.39 | FO11: 209800.66 | FP11: 25852.57 | FQ11: 11323.36 | FR11: 525951.6 | FS11: 223741.4 | FT11: 130777.5 | FU11: 147358.6 | FV11: 14995.12 | FW11: 18638.36 | FX11: 747634.1 | FY11: 922857.3 | FZ11: 141838.9 | GA11: 233487.2 | GB11: 1193860 | GC11: 1630967 | GD11: 141864.5 | GE11: 118259.4 | GF11: 398691.6 | GG11: 977814.9 | GH11: 43609.219 | GI11: 57219.044 | GJ11: 83173.729 | GK11: 61341.198 | GL11: 96919.281 | GM11: 15381.191 | GN11: 27798.086 | GO11: 43950.863 | GP11: 59615.265 | GQ11: 74120.239 | GR11: 115738.48 | GS11: 125438.46 | GT11: 95368.69 | GU11: 123176.29 | GV11: 127701.16 | GW11: 137984.42 | GX11: 40693.653 | GY11: 19954.706 | GZ11: 85575.523 | HA11: 101975.26 | HB11: 217106.32 | HC11: 202209.18 | HD11: 217817.28 | HE11: 187311.49 | HF11: 322085.6 | HG11: 237282.75 | HH11: 239484.92 | HI11: 182491.56 | HJ11: 118623.54 | HK11: 79955.933 | HL11: 50865.204 | HM11: 50976.337 | HN11: 83908.272 | HO11: 79273.643 | HP11: 136933.94 | HQ11: 147353.84 | HR11: 129558.69 | HS11: 123624.98 | HT11: 70457.588 | HU11: 60694.153 | HV11: 204823.76 | HW11: 187599.99 | HX11: 147500.15 | HY11: 138587.88 | HZ11: 214039.1 | IA11: 216201.64 | IB11: 39511.508 | IC11: 29983.046 | ID11: 105442.25 | IE11: 114641.24 | IF11: 229980.54 | IG11: 213901.52 | IH11: 114668.11 | II11: 207540.59 | IJ11: 134423.27 | IK11: 151901.57 | IL11: 130163.07 | IM11: 138456.93 | IO11: 71205.597 | IP11: 130245.43 | IQ11: 108660.42 | IR11: 216729.17 | IS11: 254189.78 | IT11: 154034.16 | IU11: 150689.16 | IV11: 189615.1 | IW11: 209308.62 | IX11: 100916.3 | IY11: 95146.952 | IZ11: 132475.58 | JA11: 133145.07 | JB11: 162100.73 | JC11: 145718.38
A12: 10 | D12: 1093.334 | F12: 3454.991 | P12: 250 | Q12: 3900.118 | T12: 62368.24 | U12: 68560.34 | V12: 177403.2 | W12: 119912.3 | X12: 37540.27 | Y12: 14681.28 | Z12: 300245.2 | AJ12: 400 | AK12: 400 | AL12: 425 | AM12: 425 | AN12: 450 | AO12: 450 | AP12: 475 | AQ12: 475 | AR12: 500 | AS12: 500 | AV12: 1000 | AW12: 2131.745 | AZ12: 575 | BA12: 575 | BB12: 600 | BC12: 600 | BD12: 625 | BE12: 625 | BF12: 650 | BG12: 650 | BH12: 1000 | BI12: 1135.406 | BJ12: 154562.53 | BK12: 313993.56 | BL12: 882048.89 | BM12: 883221.68 | BN12: 1030847.9 | BO12: 866943.18 | BP12: 1091995.6 | BQ12: 1095360.6 | BT12: 12884.498 | BU12: 7753.9363 | BV12: 168095.92 | BW12: 43605.087 | BX12: 87088.47 | BY12: 134418.66 | BZ12: 800 | CA12: 800 | CF12: 10629.594 | CG12: 16033.804 | CH12: 2111815.7 | CI12: 1349335.3 | CJ12: 1000 | CK12: 3090.0385 | CL12: 300 | CM12: 300 | CN12: 400 | CO12: 400 | CP12: 1000 | CQ12: 1518.2757 | CR12: 277092.53 | CS12: 292808.53 | CT12: 2291.7204 | CU12: 1000 | CV12: 3273.2618 | CW12: 1000 | CX12: 2357.2457 | CY12: 1000 | CZ12: 117248.7 | DA12: 123048.57 | DD12: 350 | DE12: 350 | DF12: 53900.028 | DG12: 53611.858 | DH12: 294117.61 | DI12: 317149.2 | DJ12: 754560.06 | DK12: 693760.99 | DN12: 79537.437 | DO12: 74413.391 | DP12: 548492.61 | DQ12: 557754.21 | DR12: 772021.91 | DS12: 524714.72 | DT12: 72292.046 | DU12: 3594.8136 | DV12: 898410.71 | DW12: 1368616.3 | DX12: 391465.85 | DY12: 307378.81 | DZ12: 797166.2 | EA12: 877439.09 | EB12: 926929.14 | EC12: 647764.59 | ED12: 37353.779 | EE12: 32572.33 | EF12: 41726.36 | EG12: 95981.522 | EH12: 123626.29 | EI12: 287392.46 | EJ12: 554577.58 | EK12: 568588.56 | EN12: 323582.58 | EO12: 205355.64 | EP12: 280119.51 | EQ12: 259153.93 | ER12: 1427884 | ES12: 1284997.6 | ET12: 260436.92 | EU12: 163065.72 | EV12: 188932.82 | EW12: 207710.25 | EX12: 65040.115 | EY12: 72477.196 | EZ12: 183178.39 | FA12: 196562.47 | FB12: 117771.64 | FC12: 118612.47 | FD12: 307681.73 | FE12: 310399.08 | FF12: 335350.04 | FG12: 354827.3 | FH12: 74917.9 | FI12: 62669.632 | FJ12: 46967.621 | FK12: 50117.569 | FL12: 180983.15 | FM12: 168684.42 | FN12: 161477.14 | FO12: 161173.92 | FP12: 165269.9 | FQ12: 329813.2 | FR12: 925409.9 | FS12: 835885.6 | FT12: 331223.5 | FU12: 310378.4 | FV12: 232860.8 | FW12: 188575.8 | FX12: 612350.8 | FY12: 370419.4 | FZ12: 270472.3 | GA12: 505717.8 | GB12: 2150936 | GC12: 273332.7 | GD12: 435904.2 | GE12: 140452.1 | GF12: 292154.2 | GG12: 266204.3 | GH12: 201661.36 | GI12: 192402.83 | GJ12: 267056.3 | GK12: 244264.76 | GL12: 72672.699 | GM12: 95189.941 | GN12: 63613.285 | GO12: 77713.989 | GP12: 151869.71 | GQ12: 125513.45 | GR12: 164899.96 | GS12: 113317.94 | GT12: 293706.91 | GU12: 288792.02 | GV12: 416044.07 | GW12: 331282.35 | GX12: 123787.35 | GY12: 39494.453 | GZ12: 225003.69 | HA12: 241600.37 | HB12: 165769.41 | HC12: 157242.8 | HD12: 108650.43 | HE12: 128067.6 | HF12: 148477.14 | HG12: 137314.94 | HH12: 83977.432 | HI12: 81541.313 | HJ12: 85587.746 | HK12: 108099.4 | HL12: 24292.957 | HM12: 34019.341 | HN12: 99603.523 | HO12: 100450.94 | HP12: 68971.519 | HQ12: 82010.864 | HS12: 148430.97 | HU12: 61798.481 | HW12: 81894.577 | HY12: 143629.01 | HZ12: 310549.56 | IA12: 348254.21 | IB12: 48860.184 | IC12: 50790.939 | ID12: 113983.69 | IE12: 127825.57 | IF12: 179623.92 | IG12: 190097.63 | IH12: 191571.29 | II12: 168488.69 | IJ12: 404793.46 | IK12: 417158.42 | IL12: 82866.409 | IM12: 83346.443 | IN12: 80134.361 | IO12: 86698.601 | IP12: 182465.85 | IQ12: 195336.15 | IR12: 227961.88 | IS12: 257903.9 | IT12: 169955.31 | IU12: 186162.17 | IV12: 529539.31 | IW12: 549590.09 | IX12: 147987.75 | IY12: 154125.26 | IZ12: 317606.23 | JA12: 344417.51 | JB12: 151088.09 | JC12: 167057.17
A13: 11 | B13: 100 | C13: 100 | D13: 5836.632 | E13: 1000 | F13: 12600.44 | G13: 24784.28 | J13: 1842296 | K13: 1957775 | L13: 1983.719 | M13: 3660.596 | N13: 5322.637 | O13: 5531.137 | P13: 2170.254 | R13: 5772.689 | S13: 24669.69 | T13: 779301.2 | U13: 1150835 | V13: 1464034 | W13: 1177284 | X13: 325 | Y13: 325 | Z13: 264465.9 | AA13: 380590.2 | AB13: 1331.731 | AC13: 1799.49 | AF13: 2253.544 | AG13: 2146.016 | AH13: 26155.14 | AI13: 23421.76 | AJ13: 400 | AK13: 400 | AL13: 8387.472 | AM13: 7843.945 | AN13: 450 | AO13: 450 | AP13: 4084.315 | AQ13: 9726.545 | AR13: 1311.079 | AS13: 1000 | AV13: 525 | AW13: 525 | AZ13: 575 | BA13: 575 | BB13: 600 | BC13: 600 | BD13: 625 | BE13: 625 | BF13: 650 | BG13: 650 | BH13: 2669.914 | BI13: 1000 | BJ13: 517585.63 | BK13: 500137.94 | BL13: 98481.3 | BM13: 21414.318 | BN13: 595974.06 | BO13: 467576.02 | BP13: 298615.51 | BQ13: 244431.41 | BT13: 3834.3167 | BU13: 1634.8343 | BX13: 81307.198 | BY13: 57053.062 | BZ13: 513301.45 | CA13: 442574.52 | CF13: 875 | CG13: 875 | CH13: 1142259.2 | CI13: 1130533.3 | CJ13: 11828.296 | CK13: 13414.272 | CL13: 2450.5205 | CM13: 1000 | CN13: 400 | CO13: 400 | CR13: 2971417 | CS13: 2605152.1 | CT13: 3541.8646 | CU13: 2795.9862 | CV13: 6727.8643 | CW13: 1076.8489 | CX13: 900 | CY13: 900 | CZ13: 568957.95 | DA13: 540678.77 | DD13: 350 | DE13: 350 | DF13: 177350.02 | DG13: 199690.12 | DH13: 166616.91 | DI13: 193384.51 | DJ13: 530302.8 | DK13: 562218.81 | DN13: 115275.46 | DO13: 121822.88 | DP13: 412243.07 | DQ13: 490824.68 | DR13: 38189.911 | DS13: 36537.693 | DT13: 221186.9 | DU13: 181512.76 | DV13: 612014.83 | DW13: 590062.44 | DZ13: 1860412 | EA13: 1761851.7 | EB13: 332315.58 | EC13: 315436.58 | ED13: 77631.607 | EE13: 14670.07 | EF13: 84153.252 | EG13: 106019.39 | EH13: 310329.65 | EI13: 256241.24 | EJ13: 299506.23 | EK13: 371679.08 | EN13: 429533.87 | EO13: 467475.04 | EP13: 153818.51 | EQ13: 142419.08 | ER13: 726112.73 | ES13: 734977.17 | ET13: 57032.455 | EU13: 21585.623 | EV13: 146405.96 | EW13: 142071.72 | EX13: 35220.135 | EY13: 45236.931 | EZ13: 150611.31 | FA13: 158080.8 | FB13: 71076.141 | FC13: 58731.098 | FD13: 261497.47 | FE13: 281428.5 | FF13: 190240.33 | FG13: 170398.01 | FH13: 51858.227 | FI13: 66518.341 | FJ13: 29094.881 | FK13: 29256.144 | FL13: 59678.474 | FM13: 64132.156 | FN13: 79690.453 | FO13: 79433.815 | FP13: 165617.9 | FQ13: 197643.3 | FR13: 509659.9 | FS13: 246270.5 | FT13: 305478.7 | FU13: 245568.7 | FV13: 315666.7 | FW13: 855933.4 | FX13: 831565 | FY13: 849860.4 | FZ13: 231240.5 | GA13: 141712.9 | GD13: 156981 | GE13: 190463.4 | GF13: 183538.1 | GG13: 229462.2 | GH13: 92163.971 | GI13: 54894.684 | GJ13: 128084.63 | GK13: 227301.45 | GL13: 41268.745 | GM13: 29992.615 | GN13: 87913.597 | GO13: 92614.792 | GP13: 82914.001 | GQ13: 72922.737 | GR13: 154445.85 | GS13: 173335.17 | GT13: 164689.5 | GU13: 106441.89 | GV13: 190057.48 | GW13: 179132.29 | GX13: 111875.75 | GY13: 93804.359 | GZ13: 58178.139 | HA13: 56615.257 | HB13: 94656.677 | HC13: 89673.439 | HD13: 10653.212 | HE13: 7710.7792 | HF13: 192763.95 | HG13: 160028.03 | HH13: 60288.078 | HI13: 72497.765 | HJ13: 62856.846 | HK13: 75484.512 | HL13: 10876.126 | HM13: 9278.594 | HN13: 57131.157 | HO13: 50219.231 | HP13: 115934.34 | HQ13: 134369.42 | HR13: 112873.66 | HS13: 117896.96 | HT13: 45517.681 | HU13: 44237.587 | HV13: 599578.19 | HW13: 582945.25 | HX13: 57422.024 | HY13: 53317.047 | HZ13: 352788.33 | IA13: 329226.59 | IB13: 62139.359 | IC13: 58875.984 | ID13: 161083.83 | IE13: 150555.82 | IF13: 199254.88 | IG13: 194860.21 | IH13: 232827.87 | II13: 198543.06 | IJ13: 580287.48 | IK13: 636138.12 | IL13: 125867.49 | IM13: 126730.8 | IN13: 184381.94 | IO13: 167748.35 | IP13: 152270.48 | IQ13: 152403.75 | IR13: 212057.36 | IS13: 187319.09 | IT13: 102153.34 | IU13: 113807.07 | IV13: 247253.66 | IW13: 239693.85 | IX13: 131223.79 | IY13: 132123.32 | IZ13: 123591.95 | JA13: 150737.44 | JB13: 251671.71 | JC13: 219616.52
A14: 12 | B14: 100 | C14: 100 | D14: 2097.939 | E14: 1000 | F14: 57628.15 | G14: 29132.15 | J14: 507461.9 | K14: 592055.2 | L14: 200 | M14: 200 | O14: 225 | Q14: 250 | R14: 3395.19 | S14: 1000 | T14: 892530.9 | U14: 541578.7 | V14: 1330217 | W14: 1540429 | X14: 170753.6 | Y14: 335914.7 | Z14: 101685 | AA14: 129996.6 | AB14: 2935.849 | AC14: 13279.79 | AF14: 375 | AG14: 375 | AH14: 2386806 | AI14: 1724230 | AJ14: 400 | AK14: 400 | AL14: 425 | AM14: 425 | AN14: 450 | AP14: 475 | AQ14: 475 | AR14: 500 | AS14: 500 | AV14: 525 | AW14: 525 | AZ14: 575 | BA14: 575 | BB14: 10683.74 | BC14: 6272.254 | BJ14: 1422517.1 | BK14: 1206357.2 | BL14: 204330.86 | BM14: 200216.35 | BN14: 496362.03 | BO14: 540157.78 | BP14: 200949.86 | BQ14: 183993.71 | BT14: 192153.73 | BU14: 86676.903 | BX14: 376018.04 | BY14: 2469065.7 | BZ14: 1000 | CA14: 4524.2453 | CF14: 738702.27 | CG14: 731708.98 | CH14: 261404.91 | CI14: 262618.59 | CJ14: 200 | CK14: 200 | CL14: 300 | CM14: 300 | CN14: 400 | CO14: 400 | CR14: 1314850.3 | CS14: 1163766.5 | CT14: 700 | CU14: 700 | CX14: 900 | CY14: 900 | CZ14: 119533.83 | DA14: 116805.05 | DD14: 350 | DE14: 350 | DF14: 195099.52 | DG14: 204458.56 | DH14: 130453.12 | DI14: 111722.53 | DJ14: 606287.78 | DK14: 582046.2 | DN14: 117629.1 | DO14: 138735.66 | DP14: 115223.82 | DQ14: 119149.72 | DR14: 656952.27 | DS14: 729092.77 | DT14: 442313.54 | DU14: 394173.16 | DV14: 524692.81 | DW14: 702711.85 | DZ14: 1508123.3 | EA14: 1015530.6 | ED14: 109326.7 | EE14: 98491.074 | EF14: 318751.92 | EG14: 297185.82 | EH14: 401494.69 | EI14: 313927.8 | EJ14: 338792.3 | EK14: 250499.4 | EN14: 599987.67 | EO14: 565555.73 | EP14: 536363.04 | EQ14: 359821.35 | ER14: 3205862.5 | ES14: 2722077.9 | ET14: 207888.35 | EU14: 171217.86 | EV14: 72762.329 | EW14: 70651.802 | EX14: 33975.407 | EY14: 31281.191 | EZ14: 132846.05 | FA14: 135556.76 | FB14: 43525.356 | FC14: 50383.85 | FD14: 183932.79 | FE14: 178904.42 | FF14: 228838.85 | FG14: 204602.75 | FH14: 46543.144 | FI14: 40966.48 | FJ14: 83664.94 | FK14: 80200.981 | FL14: 76660.675 | FM14: 87570.808 | FN14: 108189.97 | FO14: 100859.9 | FP14: 176830.1 | FQ14: 184525.2 | FR14: 498098.3 | FS14: 352706.1 | FT14: 356409.3 | FU14: 348371.5 | FV14: 96800.95 | FW14: 50597.53 | FX14: 58515.93 | FY14: 69485.6 | FZ14: 212343 | GA14: 211218.7 | GD14: 42782.14 | GE14: 14657.05 | GF14: 279632.2 | GG14: 248520.4 | GH14: 78373.856 | GI14: 36493.462 | GJ14: 112575.16 | GK14: 145291.93 | GL14: 42408.894 | GM14: 33624.966 | GN14: 80122.162 | GO14: 84934.28 | GP14: 186259.25 | GQ14: 168090.03 | GR14: 93072.571 | GS14: 57236.691 | GT14: 39753.769 | GU14: 67945.038 | GV14: 132127.7 | GW14: 112831.02 | GX14: 112100.46 | GY14: 47865.894 | GZ14: 114028.27 | HA14: 103850.27 | HB14: 73037.109 | HC14: 81905.22 | HD14: 251059.42 | HE14: 244631 | HF14: 85136.253 | HG14: 90757.805 | HH14: 179712.81 | HI14: 158516.66 | HJ14: 60282.951 | HK14: 68968.399 | HL14: 16845.984 | HM14: 15427.27 | HN14: 36446.854 | HO14: 35931.74 | HP14: 147067.7 | HQ14: 158166.56 | HR14: 100539 | HS14: 102023.1 | HT14: 69932.365 | HU14: 75354.523 | HV14: 59089.108 | HW14: 55311.974 | HZ14: 282270.78 | IA14: 280592.25 | IB14: 66126.709 | IC14: 86884.75 | ID14: 251493.7 | IE14: 275639.98 | IF14: 278430.51 | IG14: 278692.93 | IH14: 924120.97 | II14: 895520.2 | IJ14: 1116631.1 | IK14: 1109969 | IL14: 176235.18 | IM14: 186992.02 | IN14: 174810.82 | IO14: 174081.57 | IP14: 184366.76 | IQ14: 202986.25 | IR14: 225520.31 | IS14: 225980.85 | IT14: 64080.261 | IU14: 66024.277 | IV14: 357401.37 | IW14: 355253.94 | IX14: 182645.42 | IY14: 190441.12 | IZ14: 130930.22 | JA14: 139200.33 | JB14: 358842.53 | JC14: 354856.23
A15: 13 | B15: 100 | C15: 100 | D15: 1409.507 | E15: 5797.37 | F15: 37029.22 | G15: 48183.79 | J15: 263226.2 | K15: 241339.4 | L15: 200 | M15: 200 | O15: 225 | P15: 1930.37 | Q15: 4312.544 | R15: 1095.942 | T15: 699051.4 | U15: 1135838 | V15: 959804 | W15: 1030323 | X15: 97180.48 | Y15: 138240.7 | Z15: 122794.2 | AA15: 121572.2 | AB15: 1166.982 | AC15: 1839.689 | AF15: 2030.119 | AG15: 2810.009 | AH15: 1104818 | AI15: 1249948 | AJ15: 400 | AK15: 400 | AL15: 425 | AM15: 425 | AN15: 450 | AO15: 450 | AP15: 475 | AQ15: 475 | AR15: 500 | AS15: 500 | AV15: 525 | AZ15: 575 | BA15: 575 | BB15: 5146.928 | BC15: 7058.751 | BJ15: 2407839.8 | BK15: 2944238.8 | BL15: 308781.04 | BM15: 406347.75 | BN15: 558218.63 | BO15: 547877.14 | BP15: 680404.36 | BQ15: 767512.63 | BT15: 246078.9 | BU15: 244896.04 | BX15: 465302.43 | BY15: 539933.23 | BZ15: 800 | CA15: 800 | CF15: 568186.77 | CG15: 596358.03 | CH15: 1910223.3 | CI15: 2636818.4 | CJ15: 1000 | CK15: 3956.1515 | CL15: 8181.7751 | CM15: 6672.6317 | CR15: 837487.73 | CS15: 740272.4 | CT15: 700 | CU15: 700 | CX15: 900 | CY15: 900 | CZ15: 146290.39 | DA15: 146920.85 | DD15: 350 | DE15: 350 | DF15: 162174.77 | DG15: 156007.25 | DH15: 127219.84 | DI15: 126823.65 | DJ15: 482594.64 | DK15: 436675.57 | DN15: 322701.29 | DO15: 288324.95 | DP15: 63382.858 | DQ15: 62076.752 | DR15: 914880.92 | DS15: 899657.35 | DT15: 484707.18 | DU15: 723468.57 | DV15: 863077.82 | DW15: 865800.23 | DZ15: 4006459.5 | EA15: 3982858.4 | ED15: 323797.91 | EE15: 330042.57 | EF15: 276499.18 | EG15: 270178.89 | EH15: 567776.12 | EI15: 706269.41 | EJ15: 2029931 | EK15: 2030761.5 | EN15: 690593.57 | EO15: 686622.31 | EP15: 557297.3 | EQ15: 500272.09 | ET15: 357984.77 | EU15: 372269.99 | EV15: 43314.751 | EW15: 48228.168 | EX15: 74193.336 | EY15: 54770.496 | EZ15: 122242.33 | FA15: 107575.04 | FB15: 80071.625 | FC15: 73222.45 | FD15: 293528.47 | FE15: 313638.09 | FF15: 229012.22 | FG15: 262517.97 | FH15: 6077.1832 | FI15: 7049.6054 | FJ15: 19206.696 | FK15: 16880.63 | FL15: 38360.493 | FM15: 37070.377 | FN15: 111052.89 | FO15: 110439.37 | FP15: 124196.5 | FQ15: 145065.7 | FR15: 147475.5 | FS15: 117603.7 | FT15: 351754.4 | FU15: 376508.1 | FV15: 614168.7 | FW15: 828492.3 | FX15: 494305.1 | FY15: 309400.9 | FZ15: 12173.38 | GA15: 13207.44 | GD15: 4243.209 | GE15: 9858.711 | GF15: 171578.6 | GG15: 103404.6 | GH15: 111677.22 | GI15: 325323.55 | GJ15: 518824.04 | GK15: 328207.37 | GL15: 749536.13 | GM15: 685783.75 | GN15: 168389.97 | GO15: 184755.54 | GP15: 213753.72 | GQ15: 228471.47 | GR15: 88117.493 | GS15: 226589.71 | GT15: 297308.5 | GU15: 226460.39 | GV15: 126584.45 | GW15: 113448.28 | GX15: 154196.47 | GY15: 143258.44 | GZ15: 227757.28 | HA15: 225353.56 | HB15: 347255.71 | HC15: 357459.23 | HD15: 546908.81 | HE15: 488270.17 | HF15: 279137.18 | HG15: 280601.87 | HH15: 303357.6 | HI15: 303237.85 | HJ15: 70282.379 | HK15: 71427.322 | HL15: 46029.606 | HM15: 52260.345 | HN15: 41613.43 | HO15: 41915.359 | HP15: 689052.55 | HQ15: 745294.25 | HR15: 97515.701 | HS15: 114824.34 | HT15: 60222.412 | HU15: 52327.839 | HV15: 102111.4 | HW15: 100252.3 | HZ15: 150626.25 | IA15: 171984.86 | IB15: 17016.375 | IC15: 25697.432 | ID15: 109252.95 | IE15: 114115.41 | IF15: 152443.44 | IG15: 168445.04 | IH15: 445821.96 | II15: 464338.17 | IL15: 51769.615 | IM15: 70505.989 | IN15: 69026.894 | IO15: 64635.368 | IP15: 162486.69 | IQ15: 188738.62 | IR15: 143169.49 | IS15: 147384.09 | IT15: 43504.513 | IU15: 42246.62 | IV15: 170305.36 | IW15: 191148.71 | IX15: 142378.42 | IY15: 185808.72 | IZ15: 90910.622 | JA15: 96642.471 | JB15: 142253.49 | JC15: 162945.57
