Workbook

Sheet REJOc Haplotypes Edited
D7: Geometric Mean Expression (μg/ml) | F7: Time to Escape (Weeks) | J7: REJO.c Pos | K7: 277 | L7: 280 | M7: 458 | S7: 277 | T7: 280 | U7: 458
B8: Escape Path | C8: Sample ID | H8: Set Point Viral Load (GC/mL) | J8: HXB2 Pos | K8: 276 | L8: 279 | M8: 460 | S8: 276 | T8: 279 | U8: 460
J9: WT AA | K9: N | L9: D | M9: N | S9: N | T9: D | U9: N
J10: Mut AA | K10: D | L10: A | M10: D | S10: D | T10: A | U10: D
B11: =VLOOKUP($C11,'REJOc Haplotypes'!$A$9:$BR$49,3,FALSE) -> A: D279A + N460D | C11: CD5-m265 | D11: =VLOOKUP($C11,'REJOc Haplotypes'!$A$9:$BR$49,4,FALSE) -> 37.9099 | E11: =GEOMEAN(D11:D21) -> 65.888025 | F11: =VLOOKUP($C11,'REJOc Haplotypes'!$A$9:$BR$49,5,FALSE) -> 5 | G11: =GEOMEAN(F11:F21) -> 4.5762168 | H11: =VLOOKUP(C11,'setpoint vl'!$A$1:$D$100,4,FALSE) -> 404054.5 | I11: =GEOMEAN(H11:H21) -> 385650.46 | K11: 0 | L11: 0.87471198 | M11: 0.99687744 | P11: CD5-m265 | Q11: A | S11: 0 | T11: 0.87471198 | U11: 0.99687744
B12: =VLOOKUP($C12,'REJOc Haplotypes'!$A$9:$BR$49,3,FALSE) -> A: D279A + N460D | C12: CD46-m336 | D12: =VLOOKUP($C12,'REJOc Haplotypes'!$A$9:$BR$49,4,FALSE) -> 79.2136 | F12: =VLOOKUP($C12,'REJOc Haplotypes'!$A$9:$BR$49,5,FALSE) -> 4 | H12: =VLOOKUP(C12,'setpoint vl'!$A$1:$D$100,4,FALSE) -> 394453.69 | K12: 0 | L12: 0.99401632 | M12: 0.99540018 | P12: CD46-m336 | Q12: A | S12: 0 | T12: 0.99401632 | U12: 0.99540018
B13: =VLOOKUP($C13,'REJOc Haplotypes'!$A$9:$BR$49,3,FALSE) -> A: D279A + N460D | C13: CD20-m026 | D13: =VLOOKUP($C13,'REJOc Haplotypes'!$A$9:$BR$49,4,FALSE) -> 49.6308 | F13: =VLOOKUP($C13,'REJOc Haplotypes'!$A$9:$BR$49,5,FALSE) -> 4 | H13: =VLOOKUP(C13,'setpoint vl'!$A$1:$D$100,4,FALSE) -> 346590.39 | K13: 0 | L13: 0.99584816 | M13: 0.98846947 | P13: CD20-m026 | Q13: A | S13: 0 | T13: 0.99584816 | U13: 0.98846947
B14: =VLOOKUP($C14,'REJOc Haplotypes'!$A$9:$BR$49,3,FALSE) -> A: D279A + N460D | C14: CD21-m017 | D14: =VLOOKUP($C14,'REJOc Haplotypes'!$A$9:$BR$49,4,FALSE) -> 177.065 | F14: =VLOOKUP($C14,'REJOc Haplotypes'!$A$9:$BR$49,5,FALSE) -> 5 | H14: =VLOOKUP(C14,'setpoint vl'!$A$1:$D$100,4,FALSE) -> 552020.11 | K14: 0 | L14: 0.99166667 | M14: 0.98684211 | P14: CD21-m017 | Q14: A | S14: 0 | T14: 0.99166667 | U14: 0.98684211
B15: =VLOOKUP($C15,'REJOc Haplotypes'!$A$9:$BR$49,3,FALSE) -> A: D279A + N460D | C15: CD20-m020 | D15: =VLOOKUP($C15,'REJOc Haplotypes'!$A$9:$BR$49,4,FALSE) -> 59.9141 | F15: =VLOOKUP($C15,'REJOc Haplotypes'!$A$9:$BR$49,5,FALSE) -> 3 | H15: =VLOOKUP(C15,'setpoint vl'!$A$1:$D$100,4,FALSE) -> 650717.9 | K15: 0 | L15: 0.96341858 | M15: 0.98538991 | P15: CD20-m020 | Q15: A | S15: 0 | T15: 0.96341858 | U15: 0.98538991
B16: =VLOOKUP($C16,'REJOc Haplotypes'!$A$9:$BR$49,3,FALSE) -> A: D279A + N460D | C16: CD20-m022 | D16: =VLOOKUP($C16,'REJOc Haplotypes'!$A$9:$BR$49,4,FALSE) -> 39.688 | F16: =VLOOKUP($C16,'REJOc Haplotypes'!$A$9:$BR$49,5,FALSE) -> 3 | H16: =VLOOKUP(C16,'setpoint vl'!$A$1:$D$100,4,FALSE) -> 510268.82 | K16: 0 | L16: 0.99283234 | M16: 0.98057208 | P16: CD20-m022 | Q16: A | S16: 0 | T16: 0.99283234 | U16: 0.98057208
B17: =VLOOKUP($C17,'REJOc Haplotypes'!$A$9:$BR$49,3,FALSE) -> A: D279A + N460D | C17: CD46-m331 | D17: =VLOOKUP($C17,'REJOc Haplotypes'!$A$9:$BR$49,4,FALSE) -> 79.3527 | F17: =VLOOKUP($C17,'REJOc Haplotypes'!$A$9:$BR$49,5,FALSE) -> 5 | H17: =VLOOKUP(C17,'setpoint vl'!$A$1:$D$100,4,FALSE) -> 145787.78 | K17: 0 | L17: 0.9902507 | M17: 0.94694245 | P17: CD46-m331 | Q17: A | S17: 0 | T17: 0.9902507 | U17: 0.94694245
B18: =VLOOKUP($C18,'REJOc Haplotypes'!$A$9:$BR$49,3,FALSE) -> A: D279A + N460D | C18: CD5-m273 | D18: =VLOOKUP($C18,'REJOc Haplotypes'!$A$9:$BR$49,4,FALSE) -> 70.4947 | F18: =VLOOKUP($C18,'REJOc Haplotypes'!$A$9:$BR$49,5,FALSE) -> 8 | H18: =VLOOKUP(C18,'setpoint vl'!$A$1:$D$100,4,FALSE) -> 255968.86 | K18: 0 | L18: 0.97777778 | M18: 0.9296875 | P18: CD5-m273 | Q18: A | S18: 0 | T18: 0.97777778 | U18: 0.9296875
B19: =VLOOKUP($C19,'REJOc Haplotypes'!$A$9:$BR$49,3,FALSE) -> A: D279A + N460D | C19: CD20-m023 | D19: =VLOOKUP($C19,'REJOc Haplotypes'!$A$9:$BR$49,4,FALSE) -> 49.7479 | F19: =VLOOKUP($C19,'REJOc Haplotypes'!$A$9:$BR$49,5,FALSE) -> 4 | H19: =VLOOKUP(C19,'setpoint vl'!$A$1:$D$100,4,FALSE) -> 527848.31 | K19: 0 | L19: 0.99609953 | M19: 0.50078392 | P19: CD20-m023 | Q19: A | S19: 0 | T19: 0.99609953 | U19: 0.50078392
B20: =VLOOKUP($C20,'REJOc Haplotypes'!$A$9:$BR$49,3,FALSE) -> A: D279A + N460D | C20: CD20-m038 | D20: =VLOOKUP($C20,'REJOc Haplotypes'!$A$9:$BR$49,4,FALSE) -> 77.9718 | F20: =VLOOKUP($C20,'REJOc Haplotypes'!$A$9:$BR$49,5,FALSE) -> 8 | H20: =VLOOKUP(C20,'setpoint vl'!$A$1:$D$100,4,FALSE) -> 421531.52 | K20: 0 | L20: 0.99140647 | M20: 0.1458744 | P20: CD20-m038 | Q20: A | S20: 0 | T20: 0.99140647 | U20: 0.1458744
B21: =VLOOKUP($C21,'REJOc Haplotypes'!$A$9:$BR$49,3,FALSE) -> A: D279A + N460D | C21: CD20-m021 | D21: =VLOOKUP($C21,'REJOc Haplotypes'!$A$9:$BR$49,4,FALSE) -> 74.6133 | F21: =VLOOKUP($C21,'REJOc Haplotypes'!$A$9:$BR$49,5,FALSE) -> 4 | H21: =VLOOKUP(C21,'setpoint vl'!$A$1:$D$100,4,FALSE) -> 333799.53 | K21: 0 | L21: 0.9926449 | M21: 0.14478397 | P21: CD20-m021 | Q21: A | S21: 0 | T21: 0.9926449 | U21: 0.14478397
B22: =VLOOKUP($C22,'REJOc Haplotypes'!$A$9:$BR$49,3,FALSE) -> B: D279A + N276D | C22: CD5-m281 | D22: =VLOOKUP($C22,'REJOc Haplotypes'!$A$9:$BR$49,4,FALSE) -> 109.9856 | E22: =GEOMEAN(D22:D26) -> 68.523413 | F22: =VLOOKUP($C22,'REJOc Haplotypes'!$A$9:$BR$49,5,FALSE) -> 2 | G22: =GEOMEAN(F22:F26) -> 3.8980598 | H22: =VLOOKUP(C22,'setpoint vl'!$A$1:$D$100,4,FALSE) -> 122541.87 | I22: =GEOMEAN(H22:H26) -> 607192.33 | K22: 0.99570201 | L22: 0.99712644 | M22: 0 | P22: CD5-m281 | Q22: B | S22: 0.99570201 | T22: 0.99712644 | U22: 0
B23: =VLOOKUP($C23,'REJOc Haplotypes'!$A$9:$BR$49,3,FALSE) -> B: D279A + N276D | C23: CD5-m272 | D23: =VLOOKUP($C23,'REJOc Haplotypes'!$A$9:$BR$49,4,FALSE) -> 32.7447 | F23: =VLOOKUP($C23,'REJOc Haplotypes'!$A$9:$BR$49,5,FALSE) -> 5 | H23: =VLOOKUP(C23,'setpoint vl'!$A$1:$D$100,4,FALSE) -> 720801.07 | K23: 0.99567848 | L23: 0.99453237 | M23: 0 | P23: CD5-m272 | Q23: B | S23: 0.99567848 | T23: 0.99453237 | U23: 0
B24: =VLOOKUP($C24,'REJOc Haplotypes'!$A$9:$BR$49,3,FALSE) -> B: D279A + N276D | C24: CD21-m010 | D24: =VLOOKUP($C24,'REJOc Haplotypes'!$A$9:$BR$49,4,FALSE) -> 185.365 | F24: =VLOOKUP($C24,'REJOc Haplotypes'!$A$9:$BR$49,5,FALSE) -> 5 | H24: =VLOOKUP(C24,'setpoint vl'!$A$1:$D$100,4,FALSE) -> 798264.47 | K24: 0.99477377 | L24: 0.99236289 | M24: 0 | P24: CD21-m010 | Q24: B | S24: 0.99477377 | T24: 0.99236289 | U24: 0
B25: =VLOOKUP($C25,'REJOc Haplotypes'!$A$9:$BR$49,3,FALSE) -> B: D279A + N276D | C25: CD20-m028 | D25: =VLOOKUP($C25,'REJOc Haplotypes'!$A$9:$BR$49,4,FALSE) -> 65.932 | F25: =VLOOKUP($C25,'REJOc Haplotypes'!$A$9:$BR$49,5,FALSE) -> 6 | H25: =VLOOKUP(C25,'setpoint vl'!$A$1:$D$100,4,FALSE) -> 1244025.3 | K25: 0.72665037 | L25: 0.98327595 | M25: 0 | P25: CD20-m028 | Q25: B | S25: 0.72665037 | T25: 0.98327595 | U25: 0
B26: =VLOOKUP($C26,'REJOc Haplotypes'!$A$9:$BR$49,3,FALSE) -> B: D279A + N276D | C26: CD46-m332 | D26: =VLOOKUP($C26,'REJOc Haplotypes'!$A$9:$BR$49,4,FALSE) -> 34.3237 | F26: =VLOOKUP($C26,'REJOc Haplotypes'!$A$9:$BR$49,5,FALSE) -> 3 | H26: =VLOOKUP(C26,'setpoint vl'!$A$1:$D$100,4,FALSE) -> 940925.93 | K26: 0.36007326 | L26: 0.99175721 | M26: 0 | P26: CD46-m332 | Q26: B | S26: 0.36007326 | T26: 0.99175721 | U26: 0
B27: =VLOOKUP($C27,'REJOc Haplotypes'!$A$9:$BR$49,3,FALSE) -> C: D279A + Other | C27: CD20-m027 | D27: =VLOOKUP($C27,'REJOc Haplotypes'!$A$9:$BR$49,4,FALSE) -> 45.0467 | E27: =GEOMEAN(D27:D30) -> 57.622468 | F27: =VLOOKUP($C27,'REJOc Haplotypes'!$A$9:$BR$49,5,FALSE) -> 4 | G27: =GEOMEAN(F27:F30) -> 4.8645986 | H27: =VLOOKUP(C27,'setpoint vl'!$A$1:$D$100,4,FALSE) -> 297641.83 | I27: =GEOMEAN(H27:H30) -> 350756.93 | K27: 0 | L27: 0.99876847 | M27: 0 | P27: CD20-m027 | Q27: C | S27: 0 | T27: 0.99876847 | U27: 0
B28: =VLOOKUP($C28,'REJOc Haplotypes'!$A$9:$BR$49,3,FALSE) -> C: D279A + Other | C28: CD5-m263 | D28: =VLOOKUP($C28,'REJOc Haplotypes'!$A$9:$BR$49,4,FALSE) -> 32.966 | F28: =VLOOKUP($C28,'REJOc Haplotypes'!$A$9:$BR$49,5,FALSE) -> 7 | H28: =VLOOKUP(C28,'setpoint vl'!$A$1:$D$100,4,FALSE) -> 100475.34 | K28: 0 | L28: 0.99504281 | M28: 0 | P28: CD5-m263 | Q28: C | S28: 0 | T28: 0.99504281 | U28: 0
B29: =VLOOKUP($C29,'REJOc Haplotypes'!$A$9:$BR$49,3,FALSE) -> C: D279A + Other | C29: CD10-m880 | D29: =VLOOKUP($C29,'REJOc Haplotypes'!$A$9:$BR$49,4,FALSE) -> 75.5241 | F29: =VLOOKUP($C29,'REJOc Haplotypes'!$A$9:$BR$49,5,FALSE) -> 10 | H29: =VLOOKUP(C29,'setpoint vl'!$A$1:$D$100,4,FALSE) -> 792706.09 | K29: 0 | L29: 0.98674286 | M29: 0 | P29: CD10-m880 | Q29: C | S29: 0 | T29: 0.98674286 | U29: 0
B30: =VLOOKUP($C30,'REJOc Haplotypes'!$A$9:$BR$49,3,FALSE) -> C: D279A + Other | C30: CD5-m285 | D30: =VLOOKUP($C30,'REJOc Haplotypes'!$A$9:$BR$49,4,FALSE) -> 98.2998 | F30: =VLOOKUP($C30,'REJOc Haplotypes'!$A$9:$BR$49,5,FALSE) -> 2 | H30: =VLOOKUP(C30,'setpoint vl'!$A$1:$D$100,4,FALSE) -> 638497.79 | K30: 0 | L30: 0.61190476 | M30: 0 | P30: CD5-m285 | Q30: C | S30: 0 | T30: 0.61190476 | U30: 0
B31: =VLOOKUP($C31,'REJOc Haplotypes'!$A$9:$BR$49,3,FALSE) -> D: Other | C31: CD5-m260 | D31: =VLOOKUP($C31,'REJOc Haplotypes'!$A$9:$BR$49,4,FALSE) -> 20.088 | E31: =GEOMEAN(D31:D35) -> 36.151832 | F31: =VLOOKUP($C31,'REJOc Haplotypes'!$A$9:$BR$49,5,FALSE) -> 12 | G31: =GEOMEAN(F31:F35) -> 10.713163 | H31: =VLOOKUP(C31,'setpoint vl'!$A$1:$D$100,4,FALSE) -> 806206.6 | I31: =GEOMEAN(H31:H35) -> 236602.8 | K31: 0 | L31: 0 | M31: 0 | P31: CD5-m260 | Q31: D | S31: 0 | T31: 0 | U31: 0
B32: =VLOOKUP($C32,'REJOc Haplotypes'!$A$9:$BR$49,3,FALSE) -> D: Other | C32: CD5-m264 | D32: =VLOOKUP($C32,'REJOc Haplotypes'!$A$9:$BR$49,4,FALSE) -> 18.2003 | F32: =VLOOKUP($C32,'REJOc Haplotypes'!$A$9:$BR$49,5,FALSE) -> 4 | H32: =VLOOKUP(C32,'setpoint vl'!$A$1:$D$100,4,FALSE) -> 271203.9 | K32: 0 | L32: 0 | M32: 0 | P32: CD5-m264 | Q32: D | S32: 0 | T32: 0 | U32: 0
B33: =VLOOKUP($C33,'REJOc Haplotypes'!$A$9:$BR$49,3,FALSE) -> D: Other | C33: CD5-m269 | D33: =VLOOKUP($C33,'REJOc Haplotypes'!$A$9:$BR$49,4,FALSE) -> 33.6268 | F33: =VLOOKUP($C33,'REJOc Haplotypes'!$A$9:$BR$49,5,FALSE) -> 14 | H33: =VLOOKUP(C33,'setpoint vl'!$A$1:$D$100,4,FALSE) -> 199202.09 | K33: 0 | L33: 0 | M33: 0 | P33: CD5-m269 | Q33: D | S33: 0 | T33: 0 | U33: 0
B34: =VLOOKUP($C34,'REJOc Haplotypes'!$A$9:$BR$49,3,FALSE) -> D: Other | C34: CD46-m333 | D34: =VLOOKUP($C34,'REJOc Haplotypes'!$A$9:$BR$49,4,FALSE) -> 71.9408 | F34: =VLOOKUP($C34,'REJOc Haplotypes'!$A$9:$BR$49,5,FALSE) -> 14 | H34: =VLOOKUP(C34,'setpoint vl'!$A$1:$D$100,4,FALSE) -> 1293465.8 | K34: 0 | L34: 0 | M34: 0 | P34: CD46-m333 | Q34: D | S34: 0 | T34: 0 | U34: 0
B35: =VLOOKUP($C35,'REJOc Haplotypes'!$A$9:$BR$49,3,FALSE) -> D: Other | C35: CD20-m034 | D35: =VLOOKUP($C35,'REJOc Haplotypes'!$A$9:$BR$49,4,FALSE) -> 69.8193 | F35: =VLOOKUP($C35,'REJOc Haplotypes'!$A$9:$BR$49,5,FALSE) -> 15 | H35: =VLOOKUP(C35,'setpoint vl'!$A$1:$D$100,4,FALSE) -> 13161.588 | K35: 0 | L35: 0 | M35: 0 | P35: CD20-m034 | S35: 0 | T35: 0 | U35: 0
D38: 0 | F38: 2 | H38: 10000 | K38: 0 | Q38: D
D39: 200 | F39: 15 | H39: 1000000 | K39: 1

Sheet REJOc Haplotype Count
A3: Row Labels | B3: Count of Escape Path | C3: Count of Escape Path2 | E3: Scaled Escape | F3: Percent Explained
A4: A: D279A + N460D | B4: 11 | C4: 0.42307692 | D4: =B4/26 -> 0.42307692 | E4: =B4/SUM(B4,B5) -> 0.64705882 | F4: =SUM(B4:B5)/SUM(B4:B7) -> 0.65384615
A5: B: D279A + N276D | B5: 6 | C5: 0.23076923 | D5: =B5/26 -> 0.23076923 | E5: =B5/SUM(B4,B5) -> 0.35294118
A6: C: D279A + Other | B6: 4 | C6: 0.15384615 | D6: =B6/26 -> 0.15384615
A7: D: Other | B7: 5 | C7: 0.19230769 | D7: =B7/26 -> 0.19230769
A8: (blank) | C8: 0
A9: Grand Total | B9: 26 | C9: 1
C11: =SUM(C4:C7) -> 1 | D11: =42+23+15+19 -> 99

Sheet REJOc Haplotypes
I6: aa_pos | J6: 17 | K6: 48 | L6: 53 | M6: 96 | N6: 97 | O6: 112 | P6: 121 | Q6: 127 | R6: 142 | S6: 163 | T6: 166 | U6: 166 | V6: 168 | W6: 168 | X6: 171 | Y6: 193 | Z6: 199 | AA6: 203 | AB6: 235 | AC6: 261 | AD6: 276 | AE6: 277 | AF6: 280 | AG6: 280 | AH6: 282 | AI6: 285 | AJ6: 288 | AK6: 289 | AL6: 293 | AM6: 294 | AN6: 318 | AO6: 339 | AP6: 343 | AQ6: 348 | AR6: 353 | AS6: 354 | AT6: 361 | AU6: 362 | AV6: 364 | AW6: 397 | AX6: 408 | AY6: 432 | AZ6: 450 | BA6: 457 | BB6: 458 | BC6: 458 | BD6: 459 | BE6: 460 | BF6: 462 | BG6: 464 | BH6: 464 | BI6: 464 | BJ6: 464 | BK6: 473 | BL6: 476 | BM6: 476 | BN6: 480 | BO6: 505 | BP6: 538 | BQ6: 582 | BR6: 606 | BS6: 660 | BT6: 662 | BU6: 672 | BV6: 689 | BW6: 701 | BX6: 716 | BY6: 722 | BZ6: 723 | CA6: 727 | CB6: 745 | CC6: 762 | CD6: 783 | CE6: 821 | CF6: 839 | CG6: 839 | CH6: 849 | CI6: 853 | CJ6: 854
I7: HXB2_pos | J7: 18 | K7: 49 | L7: 54 | M7: 97 | N7: 98 | O7: 113 | P7: 122 | Q7: 128 | R7: 141 | S7: 162 | T7: 165 | U7: 165 | V7: 167 | W7: 167 | X7: 170 | Y7: 192 | Z7: 198 | AA7: 202 | AB7: 234 | AC7: 260 | AD7: 275 | AE7: 276 | AF7: 279 | AG7: 279 | AH7: 281 | AI7: 284 | AJ7: 287 | AK7: 288 | AL7: 292 | AM7: 293 | AN7: 319 | AO7: 339 | AP7: 343 | AQ7: 348 | AR7: 353 | AS7: 354 | AT7: 362 | AU7: 363 | AV7: 365 | AW7: 398 | AX7: 409 | AY7: 434 | AZ7: 452 | BA7: 459 | BB7: 460 | BC7: 460 | BD7: 461 | BE7: 462 | BF7: 464 | BG7: 465 | BH7: 465 | BI7: 465 | BJ7: 465 | BK7: 474 | BL7: 477 | BM7: 477 | BN7: 481 | BO7: 506 | BP7: 539 | BQ7: 583 | BR7: 607 | BS7: 661 | BT7: 663 | BU7: 673 | BV7: 690 | BW7: 702 | BX7: 717 | BY7: 723 | BZ7: 724 | CA7: 728 | CB7: 746 | CC7: 763 | CD7: 784 | CE7: 822 | CF7: 840 | CG7: 840 | CH7: 850 | CI7: 854 | CJ7: 855
I8: REJOc_aa | J8: G | K8: T | L8: C | M8: K | N8: S | O8: D | P8: L | Q8: T | R8: D | S8: T | T8: P | U8: P | V8: D | W8: D | X8: Q | Y8: R | Z8: T | AA8: T | AB8: N | AC8: L | AD8: E | AE8: N | AF8: D | AG8: D | AH8: A | AI8: I | AJ8: H | AK8: L | AL8: V | AM8: K | AN8: A | AO8: N | AP8: Q | AQ8: T | AR8: F | AS8: R | AT8: N | AU8: Q | AV8: S | AW8: N | AX8: E | AY8: I | AZ8: L | BA8: G | BB8: N | BC8: N | BD8: S | BE8: S | BF8: S | BG8: P | BH8: P | BI8: P | BJ8: P | BK8: D | BL8: D | BM8: D | BN8: S | BO8: V | BP8: V | BQ8: M | BR8: T | BS8: L | BT8: L | BU8: F | BV8: G | BW8: L | BX8: F | BY8: A | BZ8: P | CA8: D | CB8: G | CC8: L | CD8: L | CE8: V | CF8: L | CG8: L | CH8: G | CI8: A | CJ8: L
A9: Samples | B9: Escape Path ID | C9: Escape Path | D9: Geometric Mean Expression (mg/ml) | E9: Time to Escape (Weeks) | F9: Time of Sequencing | G9: Time After Escape | H9: Number of Mutations | I9: aa_alt | J9: S | K9: N | L9: C | M9: E | N9: N | O9: E | P9: I | Q9: N | R9: N | S9: P | T9: S | U9: Q | V9: G | W9: N | X9: Q | Y9: K | Z9: A | AA9: K | AB9: S | AC9: L | AD9: K | AE9: D | AF9: A | AG9: K | AH9: K | AI9: DEL | AJ9: Q | AK9: 0 | AL9: V | AM9: K | AN9: T | AO9: K | AP9: R | AQ9: A | AR9: Y | AS9: G | AT9: K | AU9: P | AV9: T | AW9: T | AX9: K | AY9: M | AZ9: M | BA9: D | BB9: D | BC9: S | BD9: N | BE9: G | BF9: N | BG9: T | BH9: S | BI9: H | BJ9: L | BK9: N | BL9: E | BM9: N | BN9: N | BO9: M | BP9: I | BQ9: I | BR9: T | BS9: L | BT9: L | BU9: V | BV9: G | BW9: Q | BX9: F | BY9: T | BZ9: P | CA9: N | CB9: G | CC9: L | CD9: L | CE9: S | CF9: F | CG9: S | CH9: G | CI9: A | CJ9: M
A10: CD5-m265 | B10: A | C10: =VLOOKUP(B10,'REJO.c Escape Paths'!$A$1:$C$5,3,FALSE) -> A: D279A + N460D | D10: =VLOOKUP(A10,Expression!$C$1:$D$462,2,FALSE) -> 37.9099 | E10: =VLOOKUP(A10,'REJOc Survival Analysis'!$A$1:$C$60,3,FALSE) -> 5 | F10: =VLOOKUP(A10,'sequencing metadata'!$A$1:$B$34,2,FALSE) -> 25 | G10: =F10-E10 -> 20 | H10: =COUNTIF(J10:CJ10,">.1") -> 10 | I10: CD5-m265 | J10: 0 | K10: 0 | L10: 0 | M10: 0 | N10: 0.86976744 | O10: 0 | P10: 0 | Q10: 0 | R10: 0 | S10: 0 | T10: 0 | U10: 0 | V10: 0 | W10: 0.48985801 | X10: 0 | Y10: 0.47968545 | Z10: 0 | AA10: 0 | AB10: 0 | AC10: 0 | AD10: 0 | AE10: 0 | AF10: 0.87471198 | AG10: 0.12125576 | AH10: 0 | AI10: 0 | AJ10: 0.25976769 | AK10: 0 | AL10: 0.25672372 | AM10: 0 | AN10: 0 | AO10: 0 | AP10: 0 | AQ10: 0 | AR10: 0 | AS10: 0 | AT10: 0.22915417 | AU10: 0 | AV10: 0 | AW10: 0 | AX10: 0.16235191 | AY10: 0 | AZ10: 0 | BA10: 0 | BB10: 0.99687744 | BC10: 0 | BD10: 0 | BE10: 0 | BF10: 0 | BG10: 0 | BH10: 0 | BI10: 0 | BJ10: 0 | BK10: 0 | BL10: 0 | BM10: 0 | BN10: 0 | BO10: 0 | BP10: 0 | BQ10: 0 | BR10: 0 | BS10: 0 | BT10: 0 | BU10: 0 | BV10: 0 | BW10: 0 | BX10: 0 | BY10: 0 | BZ10: 0 | CA10: 0 | CB10: 0 | CC10: 0 | CD10: 0 | CE10: 0 | CF10: 0 | CG10: 0 | CH10: 0 | CI10: 0 | CJ10: 0
A11: CD46-m336 | B11: A | C11: =VLOOKUP(B11,'REJO.c Escape Paths'!$A$1:$C$5,3,FALSE) -> A: D279A + N460D | D11: =VLOOKUP(A11,Expression!$C$1:$D$462,2,FALSE) -> 79.2136 | E11: =VLOOKUP(A11,'REJOc Survival Analysis'!$A$1:$C$60,3,FALSE) -> 4 | F11: =VLOOKUP(A11,'sequencing metadata'!$A$1:$B$34,2,FALSE) -> 24 | G11: =F11-E11 -> 20 | H11: =COUNTIF(J11:CJ11,">.1") -> 10 | I11: CD46-m336 | J11: 0 | K11: 0 | L11: 0 | M11: 0 | N11: 0.9951087 | O11: 0 | P11: 0 | Q11: 0 | R11: 0 | S11: 0 | T11: 0 | U11: 0 | V11: 0 | W11: 0.48346909 | X11: 0 | Y11: 0.16862839 | Z11: 0 | AA11: 0 | AB11: 0 | AC11: 0 | AD11: 0 | AE11: 0 | AF11: 0.99401632 | AG11: 0 | AH11: 0 | AI11: 0 | AJ11: 0 | AK11: 0 | AL11: 0 | AM11: 0 | AN11: 0 | AO11: 0 | AP11: 0 | AQ11: 0 | AR11: 0 | AS11: 0.18010292 | AT11: 0.32050029 | AU11: 0 | AV11: 0 | AW11: 0 | AX11: 0.19491035 | AY11: 0 | AZ11: 0 | BA11: 0 | BB11: 0.99540018 | BC11: 0 | BD11: 0 | BE11: 0 | BF11: 0.20998811 | BG11: 0 | BH11: 0 | BI11: 0 | BJ11: 0 | BK11: 0 | BL11: 0 | BM11: 0 | BN11: 0 | BO11: 0 | BP11: 0 | BQ11: 0.2267244 | BR11: 0 | BS11: 0 | BT11: 0 | BU11: 0 | BV11: 0 | BW11: 0 | BX11: 0 | BY11: 0 | BZ11: 0 | CA11: 0 | CB11: 0 | CC11: 0 | CD11: 0 | CE11: 0 | CF11: 0 | CG11: 0 | CH11: 0 | CI11: 0 | CJ11: 0
A12: CD20-m026 | B12: A | C12: =VLOOKUP(B12,'REJO.c Escape Paths'!$A$1:$C$5,3,FALSE) -> A: D279A + N460D | D12: =VLOOKUP(A12,Expression!$C$1:$D$462,2,FALSE) -> 49.6308 | E12: =VLOOKUP(A12,'REJOc Survival Analysis'!$A$1:$C$60,3,FALSE) -> 4 | F12: =VLOOKUP(A12,'sequencing metadata'!$A$1:$B$34,2,FALSE) -> 17 | G12: =F12-E12 -> 13 | H12: =COUNTIF(J12:CJ12,">.1") -> 4 | I12: CD20-m026 | J12: 0 | K12: 0 | L12: 0 | M12: 0 | N12: 0.7421981 | O12: 0 | P12: 0 | Q12: 0 | R12: 0 | S12: 0 | T12: 0 | U12: 0 | V12: 0 | W12: 0 | X12: 0 | Y12: 0 | Z12: 0 | AA12: 0 | AB12: 0 | AC12: 0 | AD12: 0 | AE12: 0 | AF12: 0.99584816 | AG12: 0 | AH12: 0 | AI12: 0 | AJ12: 0 | AK12: 0 | AL12: 0 | AM12: 0 | AN12: 0 | AO12: 0 | AP12: 0 | AQ12: 0 | AR12: 0 | AS12: 0 | AT12: 0 | AU12: 0 | AV12: 0 | AW12: 0 | AX12: 0.14009243 | AY12: 0 | AZ12: 0 | BA12: 0 | BB12: 0.98846947 | BC12: 0 | BD12: 0 | BE12: 0 | BF12: 0 | BG12: 0 | BH12: 0 | BI12: 0 | BJ12: 0 | BK12: 0 | BL12: 0 | BM12: 0 | BN12: 0 | BO12: 0 | BP12: 0 | BQ12: 0 | BR12: 0 | BS12: 0 | BT12: 0 | BU12: 0 | BV12: 0 | BW12: 0 | BX12: 0 | BY12: 0 | BZ12: 0 | CA12: 0 | CB12: 0 | CC12: 0 | CD12: 0 | CE12: 0 | CF12: 0 | CG12: 0 | CH12: 0 | CI12: 0 | CJ12: 0
A13: CD21-m017 | B13: A | C13: =VLOOKUP(B13,'REJO.c Escape Paths'!$A$1:$C$5,3,FALSE) -> A: D279A + N460D | D13: =VLOOKUP(A13,Expression!$C$1:$D$462,2,FALSE) -> 177.065 | E13: =VLOOKUP(A13,'REJOc Survival Analysis'!$A$1:$C$60,3,FALSE) -> 5 | F13: =VLOOKUP(A13,'sequencing metadata'!$A$1:$B$34,2,FALSE) -> 22 | G13: =F13-E13 -> 17 | H13: =COUNTIF(J13:CJ13,">.1") -> 12 | I13: CD21-m017 | J13: 0.24365208 | K13: 0 | L13: 0 | M13: 0 | N13: 0.99052242 | O13: 0 | P13: 0 | Q13: 0 | R13: 0 | S13: 0 | T13: 0 | U13: 0 | V13: 0 | W13: 0 | X13: 0 | Y13: 0 | Z13: 0 | AA13: 0 | AB13: 0 | AC13: 0 | AD13: 0 | AE13: 0 | AF13: 0.99166667 | AG13: 0 | AH13: 0 | AI13: 0 | AJ13: 0.24293702 | AK13: 0 | AL13: 0 | AM13: 0 | AN13: 0 | AO13: 0 | AP13: 0 | AQ13: 0.31888812 | AR13: 0 | AS13: 0 | AT13: 0.26345934 | AU13: 0 | AV13: 0 | AW13: 0 | AX13: 0 | AY13: 0.25214736 | AZ13: 0 | BA13: 0 | BB13: 0.98684211 | BC13: 0 | BD13: 0 | BE13: 0 | BF13: 0 | BG13: 0 | BH13: 0 | BI13: 0 | BJ13: 0 | BK13: 0 | BL13: 0 | BM13: 0 | BN13: 0 | BO13: 0 | BP13: 0 | BQ13: 0.24238411 | BR13: 0 | BS13: 0 | BT13: 0.99414303 | BU13: 0 | BV13: 0 | BW13: 0 | BX13: 0 | BY13: 0 | BZ13: 0 | CA13: 0.33697234 | CB13: 0 | CC13: 0 | CD13: 0 | CE13: 0 | CF13: 0 | CG13: 0 | CH13: 0 | CI13: 0 | CJ13: 0.98331194
A14: CD20-m020 | B14: A | C14: =VLOOKUP(B14,'REJO.c Escape Paths'!$A$1:$C$5,3,FALSE) -> A: D279A + N460D | D14: =VLOOKUP(A14,Expression!$C$1:$D$462,2,FALSE) -> 59.9141 | E14: =VLOOKUP(A14,'REJOc Survival Analysis'!$A$1:$C$60,3,FALSE) -> 3 | F14: =VLOOKUP(A14,'sequencing metadata'!$A$1:$B$34,2,FALSE) -> 18 | G14: =F14-E14 -> 15 | H14: =COUNTIF(J14:CJ14,">.1") -> 7 | I14: CD20-m020 | J14: 0.31366362 | K14: 0 | L14: 0 | M14: 0 | N14: 0.62283642 | O14: 0 | P14: 0 | Q14: 0 | R14: 0.9901727 | S14: 0 | T14: 0 | U14: 0 | V14: 0 | W14: 0 | X14: 0 | Y14: 0 | Z14: 0 | AA14: 0 | AB14: 0 | AC14: 0 | AD14: 0 | AE14: 0 | AF14: 0.96341858 | AG14: 0 | AH14: 0 | AI14: 0 | AJ14: 0 | AK14: 0 | AL14: 0 | AM14: 0 | AN14: 0 | AO14: 0 | AP14: 0 | AQ14: 0 | AR14: 0 | AS14: 0 | AT14: 0.99051676 | AU14: 0 | AV14: 0 | AW14: 0 | AX14: 0 | AY14: 0 | AZ14: 0 | BA14: 0 | BB14: 0.98538991 | BC14: 0 | BD14: 0 | BE14: 0 | BF14: 0 | BG14: 0 | BH14: 0 | BI14: 0 | BJ14: 0 | BK14: 0 | BL14: 0 | BM14: 0 | BN14: 0 | BO14: 0 | BP14: 0 | BQ14: 0.19271949 | BR14: 0 | BS14: 0 | BT14: 0 | BU14: 0 | BV14: 0 | BW14: 0 | BX14: 0 | BY14: 0 | BZ14: 0 | CA14: 0 | CB14: 0 | CC14: 0 | CD14: 0 | CE14: 0 | CF14: 0 | CG14: 0 | CH14: 0 | CI14: 0 | CJ14: 0
A15: CD20-m022 | B15: A | C15: =VLOOKUP(B15,'REJO.c Escape Paths'!$A$1:$C$5,3,FALSE) -> A: D279A + N460D | D15: =VLOOKUP(A15,Expression!$C$1:$D$462,2,FALSE) -> 39.688 | E15: =VLOOKUP(A15,'REJOc Survival Analysis'!$A$1:$C$60,3,FALSE) -> 3 | F15: =VLOOKUP(A15,'sequencing metadata'!$A$1:$B$34,2,FALSE) -> 19 | G15: =F15-E15 -> 16 | H15: =COUNTIF(J15:CJ15,">.1") -> 4 | I15: CD20-m022 | J15: 0 | K15: 0 | L15: 0 | M15: 0 | N15: 0.35964288 | O15: 0 | P15: 0 | Q15: 0 | R15: 0 | S15: 0 | T15: 0 | U15: 0 | V15: 0 | W15: 0 | X15: 0 | Y15: 0.2082931 | Z15: 0 | AA15: 0 | AB15: 0 | AC15: 0 | AD15: 0 | AE15: 0 | AF15: 0.99283234 | AG15: 0 | AH15: 0 | AI15: 0 | AJ15: 0 | AK15: 0 | AL15: 0 | AM15: 0 | AN15: 0 | AO15: 0 | AP15: 0 | AQ15: 0 | AR15: 0 | AS15: 0 | AT15: 0 | AU15: 0 | AV15: 0 | AW15: 0 | AX15: 0 | AY15: 0 | AZ15: 0 | BA15: 0 | BB15: 0.98057208 | BC15: 0 | BD15: 0 | BE15: 0 | BF15: 0 | BG15: 0 | BH15: 0 | BI15: 0 | BJ15: 0 | BK15: 0 | BL15: 0 | BM15: 0 | BN15: 0 | BO15: 0 | BP15: 0 | BQ15: 0 | BR15: 0 | BS15: 0 | BT15: 0 | BU15: 0 | BV15: 0 | BW15: 0 | BX15: 0 | BY15: 0 | BZ15: 0 | CA15: 0 | CB15: 0 | CC15: 0 | CD15: 0 | CE15: 0 | CF15: 0 | CG15: 0 | CH15: 0 | CI15: 0 | CJ15: 0
A16: CD46-m331 | B16: A | C16: =VLOOKUP(B16,'REJO.c Escape Paths'!$A$1:$C$5,3,FALSE) -> A: D279A + N460D | D16: =VLOOKUP(A16,Expression!$C$1:$D$462,2,FALSE) -> 79.3527 | E16: =VLOOKUP(A16,'REJOc Survival Analysis'!$A$1:$C$60,3,FALSE) -> 5 | F16: =VLOOKUP(A16,'sequencing metadata'!$A$1:$B$34,2,FALSE) -> 19 | G16: =F16-E16 -> 14 | H16: =COUNTIF(J16:CJ16,">.1") -> 8 | I16: CD46-m331 | J16: 0 | K16: 0 | L16: 0.997921 | M16: 0.16835017 | N16: 0.82706767 | O16: 0 | P16: 0 | Q16: 0 | R16: 0 | S16: 0 | T16: 0 | U16: 0 | V16: 0 | W16: 0 | X16: 0 | Y16: 0 | Z16: 0 | AA16: 0 | AB16: 0.33417722 | AC16: 0 | AD16: 0 | AE16: 0 | AF16: 0.9902507 | AG16: 0 | AH16: 0 | AI16: 0 | AJ16: 0 | AK16: 0 | AL16: 0 | AM16: 0 | AN16: 0 | AO16: 0 | AP16: 0 | AQ16: 0 | AR16: 0 | AS16: 0.56681223 | AT16: 0.18604651 | AU16: 0 | AV16: 0 | AW16: 0 | AX16: 0 | AY16: 0 | AZ16: 0 | BA16: 0 | BB16: 0.94694245 | BC16: 0 | BD16: 0 | BE16: 0 | BF16: 0 | BG16: 0 | BH16: 0 | BI16: 0 | BJ16: 0 | BK16: 0 | BL16: 0 | BM16: 0 | BN16: 0 | BO16: 0 | BP16: 0 | BQ16: 0 | BR16: 0 | BS16: 0 | BT16: 0 | BU16: 0 | BV16: 0 | BW16: 0 | BX16: 0 | BY16: 0 | BZ16: 0 | CA16: 0 | CB16: 0 | CC16: 0 | CD16: 0 | CE16: 0 | CF16: 0 | CG16: 0 | CH16: 0 | CI16: 0 | CJ16: 0
A17: CD5-m273 | B17: A | C17: =VLOOKUP(B17,'REJO.c Escape Paths'!$A$1:$C$5,3,FALSE) -> A: D279A + N460D | D17: =VLOOKUP(A17,Expression!$C$1:$D$462,2,FALSE) -> 70.4947 | E17: =VLOOKUP(A17,'REJOc Survival Analysis'!$A$1:$C$60,3,FALSE) -> 8 | F17: =VLOOKUP(A17,'sequencing metadata'!$A$1:$B$34,2,FALSE) -> 18 | G17: =F17-E17 -> 10 | H17: =COUNTIF(J17:CJ17,">.1") -> 4 | I17: CD5-m273 | J17: 0 | K17: 0 | L17: 0 | M17: 0 | N17: 0.13243762 | O17: 0 | P17: 0 | Q17: 0 | R17: 0 | S17: 0 | T17: 0 | U17: 0 | V17: 0 | W17: 0 | X17: 0 | Y17: 0 | Z17: 0 | AA17: 0 | AB17: 0 | AC17: 0 | AD17: 0 | AE17: 0 | AF17: 0.97777778 | AG17: 0 | AH17: 0 | AI17: 0 | AJ17: 0.38740458 | AK17: 0 | AL17: 0 | AM17: 0 | AN17: 0 | AO17: 0 | AP17: 0 | AQ17: 0 | AR17: 0 | AS17: 0 | AT17: 0 | AU17: 0 | AV17: 0 | AW17: 0 | AX17: 0 | AY17: 0 | AZ17: 0 | BA17: 0 | BB17: 0.9296875 | BC17: 0 | BD17: 0 | BE17: 0 | BF17: 0 | BG17: 0 | BH17: 0 | BI17: 0 | BJ17: 0 | BK17: 0 | BL17: 0 | BM17: 0 | BN17: 0 | BO17: 0 | BP17: 0 | BQ17: 0 | BR17: 0 | BS17: 0 | BT17: 0 | BU17: 0 | BV17: 0 | BW17: 0 | BX17: 0 | BY17: 0 | BZ17: 0 | CA17: 0 | CB17: 0 | CC17: 0 | CD17: 0 | CE17: 0 | CF17: 0 | CG17: 0 | CH17: 0 | CI17: 0 | CJ17: 0
A18: CD20-m023 | B18: A | C18: =VLOOKUP(B18,'REJO.c Escape Paths'!$A$1:$C$5,3,FALSE) -> A: D279A + N460D | D18: =VLOOKUP(A18,Expression!$C$1:$D$462,2,FALSE) -> 49.7479 | E18: =VLOOKUP(A18,'REJOc Survival Analysis'!$A$1:$C$60,3,FALSE) -> 4 | F18: =VLOOKUP(A18,'sequencing metadata'!$A$1:$B$34,2,FALSE) -> 12 | G18: =F18-E18 -> 8 | H18: =COUNTIF(J18:CJ18,">.1") -> 7 | I18: CD20-m023 | J18: 0 | K18: 0 | L18: 0 | M18: 0 | N18: 0 | O18: 0 | P18: 0 | Q18: 0 | R18: 0 | S18: 0 | T18: 0 | U18: 0 | V18: 0 | W18: 0 | X18: 0 | Y18: 0 | Z18: 0 | AA18: 0 | AB18: 0 | AC18: 0 | AD18: 0 | AE18: 0 | AF18: 0.99609953 | AG18: 0 | AH18: 0 | AI18: 0 | AJ18: 0 | AK18: 0 | AL18: 0 | AM18: 0 | AN18: 0 | AO18: 0 | AP18: 0 | AQ18: 0 | AR18: 0 | AS18: 0 | AT18: 0 | AU18: 0 | AV18: 0 | AW18: 0 | AX18: 0 | AY18: 0 | AZ18: 0 | BA18: 0 | BB18: 0.50078392 | BC18: 0.35198119 | BD18: 0 | BE18: 0 | BF18: 0 | BG18: 0 | BH18: 0 | BI18: 0 | BJ18: 0 | BK18: 0 | BL18: 0 | BM18: 0 | BN18: 0 | BO18: 0 | BP18: 0 | BQ18: 0 | BR18: 0 | BS18: 0 | BT18: 0 | BU18: 0 | BV18: 0 | BW18: 0 | BX18: 0 | BY18: 0 | BZ18: 0 | CA18: 0 | CB18: 0 | CC18: 0 | CD18: 0.339866 | CE18: 0.25093671 | CF18: 0 | CG18: 0.3033737 | CH18: 0.21440875 | CI18: 0 | CJ18: 0
A19: CD20-m038 | B19: A | C19: =VLOOKUP(B19,'REJO.c Escape Paths'!$A$1:$C$5,3,FALSE) -> A: D279A + N460D | D19: =VLOOKUP(A19,Expression!$C$1:$D$462,2,FALSE) -> 77.9718 | E19: =VLOOKUP(A19,'REJOc Survival Analysis'!$A$1:$C$60,3,FALSE) -> 8 | F19: =VLOOKUP(A19,'sequencing metadata'!$A$1:$B$34,2,FALSE) -> 17 | G19: =F19-E19 -> 9 | H19: =COUNTIF(J19:CJ19,">.1") -> 4 | I19: CD20-m038 | J19: 0 | K19: 0 | L19: 0 | M19: 0 | N19: 0.64925568 | O19: 0 | P19: 0 | Q19: 0 | R19: 0 | S19: 0 | T19: 0 | U19: 0 | V19: 0 | W19: 0 | X19: 0 | Y19: 0 | Z19: 0 | AA19: 0 | AB19: 0 | AC19: 0 | AD19: 0 | AE19: 0 | AF19: 0.99140647 | AG19: 0 | AH19: 0 | AI19: 0 | AJ19: 0 | AK19: 0 | AL19: 0 | AM19: 0 | AN19: 0 | AO19: 0 | AP19: 0 | AQ19: 0 | AR19: 0 | AS19: 0 | AT19: 0 | AU19: 0 | AV19: 0 | AW19: 0 | AX19: 0 | AY19: 0 | AZ19: 0 | BA19: 0.72065418 | BB19: 0.1458744 | BC19: 0 | BD19: 0 | BE19: 0 | BF19: 0 | BG19: 0 | BH19: 0 | BI19: 0 | BJ19: 0 | BK19: 0 | BL19: 0 | BM19: 0 | BN19: 0 | BO19: 0 | BP19: 0 | BQ19: 0 | BR19: 0 | BS19: 0 | BT19: 0 | BU19: 0 | BV19: 0 | BW19: 0 | BX19: 0 | BY19: 0 | BZ19: 0 | CA19: 0 | CB19: 0 | CC19: 0 | CD19: 0 | CE19: 0 | CF19: 0 | CG19: 0 | CH19: 0 | CI19: 0 | CJ19: 0
A20: CD20-m021 | B20: A | C20: =VLOOKUP(B20,'REJO.c Escape Paths'!$A$1:$C$5,3,FALSE) -> A: D279A + N460D | D20: =VLOOKUP(A20,Expression!$C$1:$D$462,2,FALSE) -> 74.6133 | E20: =VLOOKUP(A20,'REJOc Survival Analysis'!$A$1:$C$60,3,FALSE) -> 4 | F20: =VLOOKUP(A20,'sequencing metadata'!$A$1:$B$34,2,FALSE) -> 20 | G20: =F20-E20 -> 16 | H20: =COUNTIF(J20:CJ20,">.1") -> 11 | I20: CD20-m021 | J20: 0 | K20: 0 | L20: 0 | M20: 0.52473629 | N20: 0.9860223 | O20: 0 | P20: 0 | Q20: 0 | R20: 0 | S20: 0 | T20: 0 | U20: 0 | V20: 0 | W20: 0.26851336 | X20: 0 | Y20: 0 | Z20: 0 | AA20: 0 | AB20: 0.13901345 | AC20: 0 | AD20: 0 | AE20: 0 | AF20: 0.9926449 | AG20: 0 | AH20: 0 | AI20: 0 | AJ20: 0 | AK20: 0 | AL20: 0 | AM20: 0 | AN20: 0 | AO20: 0 | AP20: 0 | AQ20: 0 | AR20: 0.27401243 | AS20: 0 | AT20: 0.16364259 | AU20: 0 | AV20: 0 | AW20: 0 | AX20: 0 | AY20: 0 | AZ20: 0 | BA20: 0.30905849 | BB20: 0.14478397 | BC20: 0.53760573 | BD20: 0 | BE20: 0 | BF20: 0 | BG20: 0 | BH20: 0 | BI20: 0 | BJ20: 0 | BK20: 0 | BL20: 0 | BM20: 0 | BN20: 0 | BO20: 0 | BP20: 0 | BQ20: 0 | BR20: 0 | BS20: 0 | BT20: 0 | BU20: 0 | BV20: 0 | BW20: 0 | BX20: 0 | BY20: 0 | BZ20: 0 | CA20: 0 | CB20: 0 | CC20: 0.99429961 | CD20: 0 | CE20: 0 | CF20: 0 | CG20: 0 | CH20: 0 | CI20: 0 | CJ20: 0
A21: CD5-m281 | B21: B | C21: =VLOOKUP(B21,'REJO.c Escape Paths'!$A$1:$C$5,3,FALSE) -> B: D279A + N276D | D21: =VLOOKUP(A21,Expression!$C$1:$D$462,2,FALSE) -> 109.9856 | E21: =VLOOKUP(A21,'REJOc Survival Analysis'!$A$1:$C$60,3,FALSE) -> 2 | F21: =VLOOKUP(A21,'sequencing metadata'!$A$1:$B$34,2,FALSE) -> 20 | G21: =F21-E21 -> 18 | H21: =COUNTIF(J21:CJ21,">.1") -> 5 | I21: CD5-m281 | J21: 0 | K21: 0 | L21: 0 | M21: 0 | N21: 0.99701937 | O21: 0 | P21: 0 | Q21: 0 | R21: 0 | S21: 0 | T21: 0 | U21: 0 | V21: 0 | W21: 0 | X21: 0 | Y21: 0 | Z21: 0 | AA21: 0 | AB21: 0 | AC21: 0 | AD21: 0 | AE21: 0.99570201 | AF21: 0.99712644 | AG21: 0 | AH21: 0 | AI21: 0 | AJ21: 0 | AK21: 0 | AL21: 0 | AM21: 0 | AN21: 0 | AO21: 0 | AP21: 0 | AQ21: 0 | AR21: 0 | AS21: 0 | AT21: 0 | AU21: 0 | AV21: 0 | AW21: 0 | AX21: 0 | AY21: 0 | AZ21: 0 | BA21: 0 | BB21: 0 | BC21: 0 | BD21: 0.99517491 | BE21: 0 | BF21: 0 | BG21: 0 | BH21: 0 | BI21: 0 | BJ21: 0 | BK21: 0 | BL21: 0 | BM21: 0 | BN21: 0 | BO21: 0 | BP21: 0 | BQ21: 0 | BR21: 0 | BS21: 0 | BT21: 0 | BU21: 0 | BV21: 0 | BW21: 0 | BX21: 0 | BY21: 0.62894818 | BZ21: 0 | CA21: 0 | CB21: 0 | CC21: 0 | CD21: 0 | CE21: 0 | CF21: 0 | CG21: 0 | CH21: 0 | CI21: 0 | CJ21: 0
... A35: CD20-m034 | B35: D | C35: =VLOOKUP(B35,'REJO.c Escape Paths'!$A$1:$C$5,3,FALSE) -> D: Other | D35: =VLOOKUP(A35,Expression!$C$1:$D$462,2,FALSE) -> 69.8193 | E35: =VLOOKUP(A35,'REJOc Survival Analysis'!$A$1:$C$60,3,FALSE) -> 15 | F35: =VLOOKUP(A35,'sequencing metadata'!$A$1:$B$34,2,FALSE) -> 20 | G35: =F35-E35 -> 5 | H35: =COUNTIF(J35:CJ35,">.1") -> 7 | I35: CD20-m034 | J35: 0 | K35: 0 | L35: 0 | M35: 0 | N35: 0 | O35: 0 | P35: 0 | Q35: 0 | R35: 0 | S35: 0 | T35: 0 | U35: 0 | V35: 0 | W35: 0 | X35: 0 | Y35: 0 | Z35: 0 | AA35: 0 | AB35: 0 | AC35: 0 | AD35: 0 | AE35: 0 | AF35: 0 | AG35: 0 | AH35: 0 | AI35: 0 | AJ35: 0 | AK35: 0 | AL35: 0 | AM35: 0.31544703 | AN35: 0 | AO35: 0 | AP35: 0 | AQ35: 0 | AR35: 0 | AS35: 0 | AT35: 0 | AU35: 0 | AV35: 0 | AW35: 0 | AX35: 0 | AY35: 0 | AZ35: 0 | BA35: 0 | BB35: 0 | BC35: 0 | BD35: 0 | BE35: 0 | BF35: 0.32704387 | BG35: 0.74587208 | BH35: 0.16399438 | BI35: 0 | BJ35: 0 | BK35: 0 | BL35: 0 | BM35: 0.9105171 | BN35: 0 | BO35: 0 | BP35: 0 | BQ35: 0 | BR35: 0 | BS35: 0.30125038 | BT35: 0 | BU35: 0 | BV35: 0 | BW35: 0 | BX35: 0.14124549 | BY35: 0 | BZ35: 0 | CA35: 0 | CB35: 0 | CC35: 0 | CD35: 0 | CE35: 0 | CF35: 0 | CG35: 0 | CH35: 0 | CI35: 0 | CJ35: 0

Sheet REJO.c Escape Paths
A1: Escape Path ID | B1: Escape Path | C1: Escape Path + ID
A2: A | B2: D279A + N460D | C2: =_xlfn.CONCAT(A2,": ",B2) -> A: D279A + N460D
A3: B | B3: D279A + N276D | C3: =_xlfn.CONCAT(A3,": ",B3) -> B: D279A + N276D
A4: C | B4: D279A + Other | C4: =_xlfn.CONCAT(A4,": ",B4) -> C: D279A + Other
A5: D | B5: Other | C5: =_xlfn.CONCAT(A5,": ",B5) -> D: Other

Sheet REJOc Raw 0.1
B1: aa_pos | C1: HXB2_pos | D1: REJOc_aa | E1: HXB2_aa | F1: Syn | G1: aa_alt | H1: CD10-m880 | I1: CD20-m020 | J1: CD20-m021 | K1: CD20-m022 | L1: CD20-m023 | M1: CD20-m026 | N1: CD20-m027 | O1: CD20-m028 | P1: CD20-m034 | Q1: CD20-m038 | R1: CD21-m010 | S1: CD21-m017 | T1: CD46-m331 | U1: CD46-m332 | V1: CD46-m333 | W1: CD46-m334 | X1: CD46-m336 | Y1: CD46-m339 | Z1: CD46-m340 | AA1: CD5-m260 | AB1: CD5-m263 | AC1: CD5-m264 | AD1: CD5-m265 | AE1: CD5-m269 | AF1: CD5-m272 | AG1: CD5-m273 | AH1: CD5-m281 | AI1: CD5-m285 | AJ1: Score
A2: 0 | B2: 1 | C2: 1 | D2: M | E2: M | F2: =D2=G2 -> FALSE | G2: 0 | H2: 0 | I2: 0 | J2: 0 | K2: 0 | L2: 0 | M2: 0 | N2: 0 | O2: 0 | P2: 0 | Q2: 0 | R2: 0 | S2: 0 | T2: 0 | U2: 0 | V2: 0 | W2: 0 | X2: 0 | Y2: 0 | Z2: 0 | AA2: 0 | AB2: 0 | AC2: 0 | AD2: 0 | AE2: 0 | AF2: 0 | AG2: 0 | AH2: 0 | AI2: 0 | AJ2: =COUNTIF(H2:AI2,">0.1") -> 0
A3: 1 | B3: 2 | C3: 2 | D3: K | E3: R | F3: =D3=G3 -> FALSE | G3: 0 | H3: 0 | I3: 0 | J3: 0 | K3: 0 | L3: 0 | M3: 0 | N3: 0 | O3: 0 | P3: 0 | Q3: 0 | R3: 0 | S3: 0 | T3: 0 | U3: 0 | V3: 0 | W3: 0 | X3: 0 | Y3: 0 | Z3: 0 | AA3: 0 | AB3: 0 | AC3: 0 | AD3: 0 | AE3: 0 | AF3: 0 | AG3: 0 | AH3: 0 | AI3: 0 | AJ3: =COUNTIF(H3:AI3,">0.25") -> 0
A4: 2 | B4: 3 | C4: 3 | D4: V | E4: V | F4: =D4=G4 -> FALSE | G4: 0 | H4: 0 | I4: 0 | J4: 0 | K4: 0 | L4: 0 | M4: 0 | N4: 0 | O4: 0 | P4: 0 | Q4: 0 | R4: 0 | S4: 0 | T4: 0 | U4: 0 | V4: 0 | W4: 0 | X4: 0 | Y4: 0 | Z4: 0 | AA4: 0 | AB4: 0 | AC4: 0 | AD4: 0 | AE4: 0 | AF4: 0 | AG4: 0 | AH4: 0 | AI4: 0 | AJ4: =COUNTIF(H4:AI4,">0.25") -> 0
A5: 3 | B5: 4 | C5: 4 | D5: K | E5: K | F5: =D5=G5 -> FALSE | G5: 0 | H5: 0 | I5: 0 | J5: 0 | K5: 0 | L5: 0 | M5: 0 | N5: 0 | O5: 0 | P5: 0 | Q5: 0 | R5: 0 | S5: 0 | T5: 0 | U5: 0 | V5: 0 | W5: 0 | X5: 0 | Y5: 0 | Z5: 0 | AA5: 0 | AB5: 0 | AC5: 0 | AD5: 0 | AE5: 0 | AF5: 0 | AG5: 0 | AH5: 0 | AI5: 0 | AJ5: =COUNTIF(H5:AI5,">0.25") -> 0
A6: 4 | B6: 5 | C6: 4a | D6: G | E6: - | F6: =D6=G6 -> FALSE | G6: R | H6: 0 | I6: 0 | J6: 0 | K6: 0 | L6: 0 | M6: 0 | N6: 0.15284974 | O6: 0 | P6: 0 | Q6: 0 | R6: 0 | S6: 0 | T6: 0 | U6: 0 | V6: 0 | W6: 0 | X6: 0 | Y6: 0 | Z6: 0 | AA6: 0 | AB6: 0 | AC6: 0 | AD6: 0 | AE6: 0 | AF6: 0 | AG6: 0 | AH6: 0 | AI6: 0 | AJ6: =COUNTIF(H6:AI6,">0.25") -> 0
A7: 5 | B7: 6 | C7: 4b | D7: I | E7: - | F7: =D7=G7 -> FALSE | G7: 0 | H7: 0 | I7: 0 | J7: 0 | K7: 0 | L7: 0 | M7: 0 | N7: 0 | O7: 0 | P7: 0 | Q7: 0 | R7: 0 | S7: 0 | T7: 0 | U7: 0 | V7: 0 | W7: 0 | X7: 0 | Y7: 0 | Z7: 0 | AA7: 0 | AB7: 0 | AC7: 0 | AD7: 0 | AE7: 0 | AF7: 0 | AG7: 0 | AH7: 0 | AI7: 0 | AJ7: =COUNTIF(H7:AI7,">0.25") -> 0
A8: 6 | B8: 7 | C8: 4c | D8: R | E8: - | F8: =D8=G8 -> FALSE | G8: K | H8: 0 | I8: 0 | J8: 0 | K8: 0 | L8: 0 | M8: 0 | N8: 0 | O8: 0 | P8: 0 | Q8: 0 | R8: 0 | S8: 0 | T8: 0 | U8: 0 | V8: 0 | W8: 0 | X8: 0 | Y8: 0 | Z8: 0 | AA8: 0 | AB8: 0 | AC8: 0 | AD8: 0.23738872 | AE8: 0 | AF8: 0 | AG8: 0 | AH8: 0 | AI8: 0 | AJ8: =COUNTIF(H8:AI8,">0.25") -> 0
A9: 7 | B9: 7 | C9: 4c | D9: R | E9: - | F9: =D9=G9 -> TRUE | G9: R | H9: 0 | I9: 0 | J9: 0 | K9: 0 | L9: 0 | M9: 0 | N9: 0 | O9: 0 | P9: 0 | Q9: 0 | R9: 0 | S9: 0 | T9: 0 | U9: 0 | V9: 0 | W9: 0 | X9: 0 | Y9: 0 | Z9: 0 | AA9: 0 | AB9: 0 | AC9: 0 | AD9: 0.1305638 | AE9: 0 | AF9: 0 | AG9: 0 | AH9: 0 | AI9: 0 | AJ9: =COUNTIF(H9:AI9,">0.25") -> 0
A10: 8 | B10: 8 | C10: 5 | D10: R | E10: E | F10: =D10=G10 -> FALSE | G10: 0 | H10: 0 | I10: 0 | J10: 0 | K10: 0 | L10: 0 | M10: 0 | N10: 0 | O10: 0 | P10: 0 | Q10: 0 | R10: 0 | S10: 0 | T10: 0 | U10: 0 | V10: 0 | W10: 0 | X10: 0 | Y10: 0 | Z10: 0 | AA10: 0 | AB10: 0 | AC10: 0 | AD10: 0 | AE10: 0 | AF10: 0 | AG10: 0 | AH10: 0 | AI10: 0 | AJ10: =COUNTIF(H10:AI10,">0.25") -> 0
A11: 9 | B11: 9 | C11: 6 | D11: N | E11: K | F11: =D11=G11 -> FALSE | G11: 0 | H11: 0 | I11: 0 | J11: 0 | K11: 0 | L11: 0 | M11: 0 | N11: 0 | O11: 0 | P11: 0 | Q11: 0 | R11: 0 | S11: 0 | T11: 0 | U11: 0 | V11: 0 | W11: 0 | X11: 0 | Y11: 0 | Z11: 0 | AA11: 0 | AB11: 0 | AC11: 0 | AD11: 0 | AE11: 0 | AF11: 0 | AG11: 0 | AH11: 0 | AI11: 0 | AJ11: =COUNTIF(H11:AI11,">0.25") -> 0
A12: 10 | B12: 10 | C12: 7 | D12: Y | E12: Y | F12: =D12=G12 -> FALSE | G12: 0 | H12: 0 | I12: 0 | J12: 0 | K12: 0 | L12: 0 | M12: 0 | N12: 0 | O12: 0 | P12: 0 | Q12: 0 | R12: 0 | S12: 0 | T12: 0 | U12: 0 | V12: 0 | W12: 0 | X12: 0 | Y12: 0 | Z12: 0 | AA12: 0 | AB12: 0 | AC12: 0 | AD12: 0 | AE12: 0 | AF12: 0 | AG12: 0 | AH12: 0 | AI12: 0 | AJ12: =COUNTIF(H12:AI12,">0.25") -> 0
A13: 11 | B13: 11 | C13: 8 | D13: Q | E13: Q | F13: =D13=G13 -> FALSE | G13: 0 | H13: 0 | I13: 0 | J13: 0 | K13: 0 | L13: 0 | M13: 0 | N13: 0 | O13: 0 | P13: 0 | Q13: 0 | R13: 0 | S13: 0 | T13: 0 | U13: 0 | V13: 0 | W13: 0 | X13: 0 | Y13: 0 | Z13: 0 | AA13: 0 | AB13: 0 | AC13: 0 | AD13: 0 | AE13: 0 | AF13: 0 | AG13: 0 | AH13: 0 | AI13: 0 | AJ13: =COUNTIF(H13:AI13,">0.25") -> 0
A14: 12 | B14: 12 | C14: 9 | D14: H | E14: H | F14: =D14=G14 -> FALSE | G14: 0 | H14: 0 | I14: 0 | J14: 0 | K14: 0 | L14: 0 | M14: 0 | N14: 0 | O14: 0 | P14: 0 | Q14: 0 | R14: 0 | S14: 0 | T14: 0 | U14: 0 | V14: 0 | W14: 0 | X14: 0 | Y14: 0 | Z14: 0 | AA14: 0 | AB14: 0 | AC14: 0 | AD14: 0 | AE14: 0 | AF14: 0 | AG14: 0 | AH14: 0 | AI14: 0 | AJ14: =COUNTIF(H14:AI14,">0.25") -> 0
A15: 13 | B15: 13 | C15: 10 | D15: L | E15: L | F15: =D15=G15 -> TRUE | G15: L | H15: 0 | I15: 0 | J15: 0 | K15: 0 | L15: 0 | M15: 0 | N15: 0 | O15: 0 | P15: 0 | Q15: 0 | R15: 0 | S15: 0.16634554 | T15: 0 | U15: 0 | V15: 0 | W15: 0 | X15: 0 | Y15: 0 | Z15: 0 | AA15: 0 | AB15: 0 | AC15: 0 | AD15: 0 | AE15: 0 | AF15: 0 | AG15: 0 | AH15: 0 | AI15: 0 | AJ15: =COUNTIF(H15:AI15,">0.25") -> 0
A16: 14 | B16: 14 | C16: 11 | D16: W | E16: W | F16: =D16=G16 -> FALSE | G16: 0 | H16: 0 | I16: 0 | J16: 0 | K16: 0 | L16: 0 | M16: 0 | N16: 0 | O16: 0 | P16: 0 | Q16: 0 | R16: 0 | S16: 0 | T16: 0 | U16: 0 | V16: 0 | W16: 0 | X16: 0 | Y16: 0 | Z16: 0 | AA16: 0 | AB16: 0 | AC16: 0 | AD16: 0 | AE16: 0 | AF16: 0 | AG16: 0 | AH16: 0 | AI16: 0 | AJ16: =COUNTIF(H16:AI16,">0.25") -> 0
A17: 15 | B17: 15 | C17: 12 | D17: R | E17: R | F17: =D17=G17 -> FALSE | G17: S | H17: 0 | I17: 0 | J17: 0 | K17: 0 | L17: 0 | M17: 0 | N17: 0 | O17: 0 | P17: 0 | Q17: 0 | R17: 0 | S17: 0.18597561 | T17: 0 | U17: 0 | V17: 0 | W17: 0 | X17: 0 | Y17: 0 | Z17: 0 | AA17: 0 | AB17: 0 | AC17: 0 | AD17: 0 | AE17: 0 | AF17: 0 | AG17: 0 | AH17: 0 | AI17: 0 | AJ17: =COUNTIF(H17:AI17,">0.25") -> 0
A18: 16 | B18: 15a | C18: 13 | D18: - | E18: W | F18: =D18=G18 -> FALSE | G18: 0 | H18: 0 | I18: 0 | J18: 0 | K18: 0 | L18: 0 | M18: 0 | N18: 0 | O18: 0 | P18: 0 | Q18: 0 | R18: 0 | S18: 0 | T18: 0 | U18: 0 | V18: 0 | W18: 0 | X18: 0 | Y18: 0 | Z18: 0 | AA18: 0 | AB18: 0 | AC18: 0 | AD18: 0 | AE18: 0 | AF18: 0 | AG18: 0 | AH18: 0 | AI18: 0 | AJ18: =COUNTIF(H18:AI18,">0.25") -> 0
A19: 17 | B19: 15b | C19: 14 | D19: - | E19: G | F19: =D19=G19 -> FALSE | G19: 0 | H19: 0 | I19: 0 | J19: 0 | K19: 0 | L19: 0 | M19: 0 | N19: 0 | O19: 0 | P19: 0 | Q19: 0 | R19: 0 | S19: 0 | T19: 0 | U19: 0 | V19: 0 | W19: 0 | X19: 0 | Y19: 0 | Z19: 0 | AA19: 0 | AB19: 0 | AC19: 0 | AD19: 0 | AE19: 0 | AF19: 0 | AG19: 0 | AH19: 0 | AI19: 0 | AJ19: =COUNTIF(H19:AI19,">0.25") -> 0
A20: 18 | B20: 15c | C20: 15 | D20: - | E20: W | F20: =D20=G20 -> FALSE | G20: 0 | H20: 0 | I20: 0 | J20: 0 | K20: 0 | L20: 0 | M20: 0 | N20: 0 | O20: 0 | P20: 0 | Q20: 0 | R20: 0 | S20: 0 | T20: 0 | U20: 0 | V20: 0 | W20: 0 | X20: 0 | Y20: 0 | Z20: 0 | AA20: 0 | AB20: 0 | AC20: 0 | AD20: 0 | AE20: 0 | AF20: 0 | AG20: 0 | AH20: 0 | AI20: 0 | AJ20: =COUNTIF(H20:AI20,">0.25") -> 0
A21: 19 | B21: 15d | C21: 16 | D21: - | E21: R | F21: =D21=G21 -> FALSE | G21: 0 | H21: 0 | I21: 0 | J21: 0 | K21: 0 | L21: 0 | M21: 0 | N21: 0 | O21: 0 | P21: 0 | Q21: 0 | R21: 0 | S21: 0 | T21: 0 | U21: 0 | V21: 0 | W21: 0 | X21: 0 | Y21: 0 | Z21: 0 | AA21: 0 | AB21: 0 | AC21: 0 | AD21: 0 | AE21: 0 | AF21: 0 | AG21: 0 | AH21: 0 | AI21: 0 | AJ21: =COUNTIF(H21:AI21,">0.25") -> 0
A22: 20 | B22: 16 | C22: 17 | D22: W | E22: W | F22: =D22=G22 -> FALSE | G22: 0 | H22: 0 | I22: 0 | J22: 0 | K22: 0 | L22: 0 | M22: 0 | N22: 0 | O22: 0 | P22: 0 | Q22: 0 | R22: 0 | S22: 0 | T22: 0 | U22: 0 | V22: 0 | W22: 0 | X22: 0 | Y22: 0 | Z22: 0 | AA22: 0 | AB22: 0 | AC22: 0 | AD22: 0 | AE22: 0 | AF22: 0 | AG22: 0 | AH22: 0 | AI22: 0 | AJ22: =COUNTIF(H22:AI22,">0.25") -> 0
A23: 21 | B23: 17 | C23: 18 | D23: G | E23: G | F23: =D23=G23 -> FALSE | G23: S | H23: 0 | I23: 0.31366362 | J23: 0 | K23: 0 | L23: 0 | M23: 0 | N23: 0 | O23: 0 | P23: 0 | Q23: 0 | R23: 0 | S23: 0.24365208 | T23: 0 | U23: 0 | V23: 0 | W23: 0 | X23: 0 | Y23: 0 | Z23: 0 | AA23: 0 | AB23: 0 | AC23: 0 | AD23: 0 | AE23: 0 | AF23: 0 | AG23: 0 | AH23: 0 | AI23: 0 | AJ23: =COUNTIF(H23:AI23,">0.25") -> 1
A24: 22 | B24: 18 | C24: 19 | D24: I | E24: T | F24: =D24=G24 -> FALSE | G24: 0 | H24: 0 | I24: 0 | J24: 0 | K24: 0 | L24: 0 | M24: 0 | N24: 0 | O24: 0 | P24: 0 | Q24: 0 | R24: 0 | S24: 0 | T24: 0 | U24: 0 | V24: 0 | W24: 0 | X24: 0 | Y24: 0 | Z24: 0 | AA24: 0 | AB24: 0 | AC24: 0 | AD24: 0 | AE24: 0 | AF24: 0 | AG24: 0 | AH24: 0 | AI24: 0 | AJ24: =COUNTIF(H24:AI24,">0.25") -> 0
A25: 23 | B25: 19 | C25: 20 | D25: M | E25: M | F25: =D25=G25 -> FALSE | G25: 0 | H25: 0 | I25: 0 | J25: 0 | K25: 0 | L25: 0 | M25: 0 | N25: 0 | O25: 0 | P25: 0 | Q25: 0 | R25: 0 | S25: 0 | T25: 0 | U25: 0 | V25: 0 | W25: 0 | X25: 0 | Y25: 0 | Z25: 0 | AA25: 0 | AB25: 0 | AC25: 0 | AD25: 0 | AE25: 0 | AF25: 0 | AG25: 0 | AH25: 0 | AI25: 0 | AJ25: =COUNTIF(H25:AI25,">0.25") -> 0
A26: 24 | B26: 20 | C26: 21 | D26: L | E26: L | F26: =D26=G26 -> FALSE | G26: 0 | H26: 0 | I26: 0 | J26: 0 | K26: 0 | L26: 0 | M26: 0 | N26: 0 | O26: 0 | P26: 0 | Q26: 0 | R26: 0 | S26: 0 | T26: 0 | U26: 0 | V26: 0 | W26: 0 | X26: 0 | Y26: 0 | Z26: 0 | AA26: 0 | AB26: 0 | AC26: 0 | AD26: 0 | AE26: 0 | AF26: 0 | AG26: 0 | AH26: 0 | AI26: 0 | AJ26: =COUNTIF(H26:AI26,">0.25") -> 0
A27: 25 | B27: 21 | C27: 22 | D27: L | E27: L | F27: =D27=G27 -> FALSE | G27: 0 | H27: 0 | I27: 0 | J27: 0 | K27: 0 | L27: 0 | M27: 0 | N27: 0 | O27: 0 | P27: 0 | Q27: 0 | R27: 0 | S27: 0 | T27: 0 | U27: 0 | V27: 0 | W27: 0 | X27: 0 | Y27: 0 | Z27: 0 | AA27: 0 | AB27: 0 | AC27: 0 | AD27: 0 | AE27: 0 | AF27: 0 | AG27: 0 | AH27: 0 | AI27: 0 | AJ27: =COUNTIF(H27:AI27,">0.25") -> 0
A28: 26 | B28: 22 | C28: 23 | D28: G | E28: G | F28: =D28=G28 -> FALSE | G28: E | H28: 0 | I28: 0 | J28: 0 | K28: 0 | L28: 0 | M28: 0 | N28: 0.14056225 | O28: 0 | P28: 0 | Q28: 0 | R28: 0 | S28: 0 | T28: 0 | U28: 0 | V28: 0 | W28: 0 | X28: 0 | Y28: 0 | Z28: 0 | AA28: 0 | AB28: 0 | AC28: 0 | AD28: 0 | AE28: 0 | AF28: 0 | AG28: 0 | AH28: 0 | AI28: 0 | AJ28: =COUNTIF(H28:AI28,">0.25") -> 0
A29: 27 | B29: 23 | C29: 24 | D29: I | E29: M | F29: =D29=G29 -> FALSE | G29: 0 | H29: 0 | I29: 0 | J29: 0 | K29: 0 | L29: 0 | M29: 0 | N29: 0 | O29: 0 | P29: 0 | Q29: 0 | R29: 0 | S29: 0 | T29: 0 | U29: 0 | V29: 0 | W29: 0 | X29: 0 | Y29: 0 | Z29: 0 | AA29: 0 | AB29: 0 | AC29: 0 | AD29: 0 | AE29: 0 | AF29: 0 | AG29: 0 | AH29: 0 | AI29: 0 | AJ29: =COUNTIF(H29:AI29,">0.25") -> 0
A30: 28 | B30: 24 | C30: 25 | D30: L | E30: L | F30: =D30=G30 -> TRUE | G30: L | H30: 0 | I30: 0 | J30: 0 | K30: 0 | L30: 0 | M30: 0 | N30: 0 | O30: 0 | P30: 0 | Q30: 0 | R30: 0 | S30: 0 | T30: 0.11111111 | U30: 0 | V30: 0 | W30: 0 | X30: 0 | Y30: 0 | Z30: 0 | AA30: 0 | AB30: 0 | AC30: 0 | AD30: 0 | AE30: 0 | AF30: 0 | AG30: 0 | AH30: 0 | AI30: 0 | AJ30: =COUNTIF(H30:AI30,">0.25") -> 0
A31: 29 | B31: 25 | C31: 26 | D31: M | E31: M | F31: =D31=G31 -> FALSE | G31: 0 | H31: 0 | I31: 0 | J31: 0 | K31: 0 | L31: 0 | M31: 0 | N31: 0 | O31: 0 | P31: 0 | Q31: 0 | R31: 0 | S31: 0 | T31: 0 | U31: 0 | V31: 0 | W31: 0 | X31: 0 | Y31: 0 | Z31: 0 | AA31: 0 | AB31: 0 | AC31: 0 | AD31: 0 | AE31: 0 | AF31: 0 | AG31: 0 | AH31: 0 | AI31: 0 | AJ31: =COUNTIF(H31:AI31,">0.25") -> 0
A32: 30 | B32: 26 | C32: 27 | D32: I | E32: I | F32: =D32=G32 -> FALSE | G32: 0 | H32: 0 | I32: 0 | J32: 0 | K32: 0 | L32: 0 | M32: 0 | N32: 0 | O32: 0 | P32: 0 | Q32: 0 | R32: 0 | S32: 0 | T32: 0 | U32: 0 | V32: 0 | W32: 0 | X32: 0 | Y32: 0 | Z32: 0 | AA32: 0 | AB32: 0 | AC32: 0 | AD32: 0 | AE32: 0 | AF32: 0 | AG32: 0 | AH32: 0 | AI32: 0 | AJ32: =COUNTIF(H32:AI32,">0.25") -> 0
A33: 31 | B33: 27 | C33: 28 | D33: C | E33: C | F33: =D33=G33 -> FALSE | G33: 0 | H33: 0 | I33: 0 | J33: 0 | K33: 0 | L33: 0 | M33: 0 | N33: 0 | O33: 0 | P33: 0 | Q33: 0 | R33: 0 | S33: 0 | T33: 0 | U33: 0 | V33: 0 | W33: 0 | X33: 0 | Y33: 0 | Z33: 0 | AA33: 0 | AB33: 0 | AC33: 0 | AD33: 0 | AE33: 0 | AF33: 0 | AG33: 0 | AH33: 0 | AI33: 0 | AJ33: =COUNTIF(H33:AI33,">0.25") -> 0
A34: 32 | B34: 28 | C34: 29 | D34: S | E34: S | F34: =D34=G34 -> FALSE | G34: 0 | H34: 0 | I34: 0 | J34: 0 | K34: 0 | L34: 0 | M34: 0 | N34: 0 | O34: 0 | P34: 0 | Q34: 0 | R34: 0 | S34: 0 | T34: 0 | U34: 0 | V34: 0 | W34: 0 | X34: 0 | Y34: 0 | Z34: 0 | AA34: 0 | AB34: 0 | AC34: 0 | AD34: 0 | AE34: 0 | AF34: 0 | AG34: 0 | AH34: 0 | AI34: 0 | AJ34: =COUNTIF(H34:AI34,">0.25") -> 0
A35: 33 | B35: 29 | C35: 30 | D35: A | E35: A | F35: =D35=G35 -> FALSE | G35: 0 | H35: 0 | I35: 0 | J35: 0 | K35: 0 | L35: 0 | M35: 0 | N35: 0 | O35: 0 | P35: 0 | Q35: 0 | R35: 0 | S35: 0 | T35: 0 | U35: 0 | V35: 0 | W35: 0 | X35: 0 | Y35: 0 | Z35: 0 | AA35: 0 | AB35: 0 | AC35: 0 | AD35: 0 | AE35: 0 | AF35: 0 | AG35: 0 | AH35: 0 | AI35: 0 | AJ35: =COUNTIF(H35:AI35,">0.25") -> 0
A36: 34 | B36: 30 | C36: 31 | D36: T | E36: T | F36: =D36=G36 -> FALSE | G36: 0 | H36: 0 | I36: 0 | J36: 0 | K36: 0 | L36: 0 | M36: 0 | N36: 0 | O36: 0 | P36: 0 | Q36: 0 | R36: 0 | S36: 0 | T36: 0 | U36: 0 | V36: 0 | W36: 0 | X36: 0 | Y36: 0 | Z36: 0 | AA36: 0 | AB36: 0 | AC36: 0 | AD36: 0 | AE36: 0 | AF36: 0 | AG36: 0 | AH36: 0 | AI36: 0 | AJ36: =COUNTIF(H36:AI36,">0.25") -> 0
A37: 35 | B37: 31 | C37: 32 | D37: E | E37: E | F37: =D37=G37 -> FALSE | G37: 0 | H37: 0 | I37: 0 | J37: 0 | K37: 0 | L37: 0 | M37: 0 | N37: 0 | O37: 0 | P37: 0 | Q37: 0 | R37: 0 | S37: 0 | T37: 0 | U37: 0 | V37: 0 | W37: 0 | X37: 0 | Y37: 0 | Z37: 0 | AA37: 0 | AB37: 0 | AC37: 0 | AD37: 0 | AE37: 0 | AF37: 0 | AG37: 0 | AH37: 0 | AI37: 0 | AJ37: =COUNTIF(H37:AI37,">0.25") -> 0
A38: 36 | B38: 32 | C38: 33 | D38: K | E38: K | F38: =D38=G38 -> FALSE | G38: 0 | H38: 0 | I38: 0 | J38: 0 | K38: 0 | L38: 0 | M38: 0 | N38: 0 | O38: 0 | P38: 0 | Q38: 0 | R38: 0 | S38: 0 | T38: 0 | U38: 0 | V38: 0 | W38: 0 | X38: 0 | Y38: 0 | Z38: 0 | AA38: 0 | AB38: 0 | AC38: 0 | AD38: 0 | AE38: 0 | AF38: 0 | AG38: 0 | AH38: 0 | AI38: 0 | AJ38: =COUNTIF(H38:AI38,">0.25") -> 0
A39: 37 | B39: 33 | C39: 34 | D39: L | E39: L | F39: =D39=G39 -> FALSE | G39: 0 | H39: 0 | I39: 0 | J39: 0 | K39: 0 | L39: 0 | M39: 0 | N39: 0 | O39: 0 | P39: 0 | Q39: 0 | R39: 0 | S39: 0 | T39: 0 | U39: 0 | V39: 0 | W39: 0 | X39: 0 | Y39: 0 | Z39: 0 | AA39: 0 | AB39: 0 | AC39: 0 | AD39: 0 | AE39: 0 | AF39: 0 | AG39: 0 | AH39: 0 | AI39: 0 | AJ39: =COUNTIF(H39:AI39,">0.25") -> 0
A40: 38 | B40: 34 | C40: 35 | D40: W | E40: W | F40: =D40=G40 -> FALSE | G40: 0 | H40: 0 | I40: 0 | J40: 0 | K40: 0 | L40: 0 | M40: 0 | N40: 0 | O40: 0 | P40: 0 | Q40: 0 | R40: 0 | S40: 0 | T40: 0 | U40: 0 | V40: 0 | W40: 0 | X40: 0 | Y40: 0 | Z40: 0 | AA40: 0 | AB40: 0 | AC40: 0 | AD40: 0 | AE40: 0 | AF40: 0 | AG40: 0 | AH40: 0 | AI40: 0 | AJ40: =COUNTIF(H40:AI40,">0.25") -> 0
...

Sheet sequencing metadata
A1: sample | B1: week
A2: CD5-m260 | B2: 24
A3: CD5-m263 | B3: 15
A4: CD5-m264 | B4: 9
A5: CD5-m265 | B5: 25
A6: CD5-m269 | B6: 22
A7: CD5-m271 | B7: 26
A8: CD5-m272 | B8: 26
A9: CD5-m273 | B9: 18
A10: CD5-m281 | B10: 20
A11: CD5-m285 | B11: 26
A12: CD10-m880 | B12: 24
A13: CD20-m020 | B13: 18
... A28: CD46-m336 | B28: 24
A29: CD46-m337
A30: CD46-m339 | B30: 13
A31: CD46-m340 | B31: 22
A32: CD50-m131 | B32: 15
A33: CD50-m134 | B33: 12
A34: CD50-m136 | B34: 12
A35: CD21-m998 | B35: 24
A36: CD21-m999 | B36: 24
A37: CD21-m002 | B37: 18
A38: CD21-m003 | B38: 24
A39: CD21-m004 | B39: 12
A40: CD21-m006 | B40: 24
A41: CD21-m007 | B41: 21
... A50: CD30-m205 | B50: 20
A51: CD30-m206
A52: CD30-m207 | B52: 20
A53: CD30-m228
A54: CD30-m229 | B54: 20
A55: CD30-m230 | B55: 16
A56: CD30-m231 | B56: 20
A57: CD30-m232 | B57: 12
A58: CD50-m066 | B58: 24
A59: CD50-m067
A60: CD50-m068 | B60: 24
A61: CD50-m069 | B61: 24
A62: CD50-m071 | B62: 24
...

Sheet survival
A1: Sample | B1: Weeks Post-AAV | C1: Luciferase | D1: VRC07 | E1: PGDM140 | F1: N6
A2: CD5-m260 | B2: 12 | D2: 1
A3: CD5-m263 | B3: 7 | D3: 1
A4: CD5-m264 | B4: 4 | D4: 1
A5: CD5-m265 | B5: 5 | D5: 1
A6: CD5-m269 | B6: 14 | D6: 1
A7: CD5-m271 | B7: 3 | D7: 1
A8: CD5-m272 | B8: 5 | D8: 1
A9: CD5-m273 | B9: 8 | D9: 1
A10: CD5-m281 | B10: 2 | D10: 1
A11: CD5-m285 | B11: 2 | D11: 1
A12: CD10-m880 | B12: 10 | D12: 1
A13: CD20-m020 | B13: 3 | D13: 1
... A57: CD21-m020 | B57: 20 | D57: 0
A58: CD5-m245 | B58: 2 | C58: 1
A59: CD5-m246 | B59: 2 | C59: 1
A60: CD5-m247 | B60: 2 | C60: 1
A61: CD5-m248 | B61: 2 | C61: 1
A62: CD5-m249 | B62: 2 | C62: 1
A63: CD5-m250 | B63: 2 | C63: 1
A64: CD5-m251 | B64: 2 | C64: 1
A65: CD5-m253 | B65: 2 | C65: 1
A66: CD5-m254 | B66: 2 | C66: 1
A67: CD5-m255 | B67: 2 | C67: 1
A68: CD5-m256 | B68: 2 | C68: 1
A69: CD5-m257 | B69: 2 | C69: 1
... A101: CD21-m013 | B101: 2 | C101: 1
A102: CD21-m021*
A103: CD21-m022 | B103: 2 | C103: 1
A104: CD21-m023 | B104: 2 | C104: 1
A105: CD21-m024 | B105: 2 | C105: 1
A106: CD21-m025 | B106: 2 | C106: 1
A107: CD21-m026 | B107: 2 | C107: 1
A108: CD46-m324 | B108: 2 | C108: 1
A109: CD46-m327*
A110: CD46-m328 | B110: 2 | C110: 1
A111: CD46-m330 | B111: 2 | C111: 1
A112: CD5-m283*
A113: CD10-m876*
A114: CD20-m025*
...

Sheet REJOc Survival Analysis
A1: Sample | B1: Expression | C1: Weeks Post-AAV | D1: Luciferase | E1: VRC07
A2: CD5-m265 | B2: =VLOOKUP(A2,Expression!$C$1:$D$462,2,FALSE) -> 37.9099 | C2: 5 | E2: 1
A3: CD5-m273 | B3: =VLOOKUP(A3,Expression!$C$1:$D$462,2,FALSE) -> 70.4947 | C3: 8 | E3: 1
A4: CD20-m020 | B4: =VLOOKUP(A4,Expression!$C$1:$D$462,2,FALSE) -> 59.9141 | C4: 3 | E4: 1
A5: CD20-m021 | B5: =VLOOKUP(A5,Expression!$C$1:$D$462,2,FALSE) -> 74.6133 | C5: 4 | E5: 1
A6: CD20-m022 | B6: =VLOOKUP(A6,Expression!$C$1:$D$462,2,FALSE) -> 39.688 | C6: 3 | E6: 1
A7: CD20-m023 | B7: =VLOOKUP(A7,Expression!$C$1:$D$462,2,FALSE) -> 49.7479 | C7: 4 | E7: 1
A8: CD21-m017 | B8: =VLOOKUP(A8,Expression!$C$1:$D$462,2,FALSE) -> 177.065 | C8: 5 | E8: 1
A9: CD46-m331 | B9: =VLOOKUP(A9,Expression!$C$1:$D$462,2,FALSE) -> 79.3527 | C9: 5 | E9: 1
A10: CD46-m336 | B10: =VLOOKUP(A10,Expression!$C$1:$D$462,2,FALSE) -> 79.2136 | C10: 4 | E10: 1
A11: CD5-m272 | B11: =VLOOKUP(A11,Expression!$C$1:$D$462,2,FALSE) -> 32.7447 | C11: 5 | E11: 1
A12: CD5-m281 | B12: =VLOOKUP(A12,Expression!$C$1:$D$462,2,FALSE) -> 109.9856 | C12: 2 | E12: 1
A13: CD20-m028 | B13: =VLOOKUP(A13,Expression!$C$1:$D$462,2,FALSE) -> 65.932 | C13: 6 | E13: 1
... A56: CD50-m131 | B56: =VLOOKUP(A56,Expression!$C$1:$D$462,2,FALSE) -> 21.2032 | C56: 7 | E56: 1

Sheet Expression
A1: Experiment | B1: Mouse | C1: ID | D1: Geomean
A2: CD5 | B2: 260 | C2: =_xlfn.CONCAT(A2,"-m",B2) -> CD5-m260 | D2: 20.088
A3: CD5 | B3: 261 | C3: =_xlfn.CONCAT(A3,"-m",B3) -> CD5-m261 | D3: 40.2419
A4: CD5 | B4: 263 | C4: =_xlfn.CONCAT(A4,"-m",B4) -> CD5-m263 | D4: 32.966
A5: CD5 | B5: 264 | C5: =_xlfn.CONCAT(A5,"-m",B5) -> CD5-m264 | D5: 18.2003
A6: CD5 | B6: 265 | C6: =_xlfn.CONCAT(A6,"-m",B6) -> CD5-m265 | D6: 37.9099
A7: CD5 | B7: 266 | C7: =_xlfn.CONCAT(A7,"-m",B7) -> CD5-m266 | D7: 49.7924
A8: CD5 | B8: 267 | C8: =_xlfn.CONCAT(A8,"-m",B8) -> CD5-m267 | D8: 41.9774
A9: CD5 | B9: 269 | C9: =_xlfn.CONCAT(A9,"-m",B9) -> CD5-m269 | D9: 33.6268
A10: CD5 | B10: 270 | C10: =_xlfn.CONCAT(A10,"-m",B10) -> CD5-m270 | D10: 50.4443
A11: CD5 | B11: 271 | C11: =_xlfn.CONCAT(A11,"-m",B11) -> CD5-m271 | D11: 15.9094
A12: CD5 | B12: 272 | C12: =_xlfn.CONCAT(A12,"-m",B12) -> CD5-m272 | D12: 32.7447
A13: CD5 | B13: 273 | C13: =_xlfn.CONCAT(A13,"-m",B13) -> CD5-m273 | D13: 70.4947
... A53: CD10 | B53: 900 | C53: =_xlfn.CONCAT(A53,"-m",B53) -> CD10-m900 | D53: 42.3516
A54: CD20 | B54: m004 | C54: =_xlfn.CONCAT(A54,"-",B54) -> CD20-m004 | D54: 15.3163
A55: CD20 | B55: m005 | C55: =_xlfn.CONCAT(A55,"-",B55) -> CD20-m005 | D55: 13.9864
A56: CD20 | B56: m006 | C56: =_xlfn.CONCAT(A56,"-",B56) -> CD20-m006 | D56: 15.93
A57: CD20 | B57: m007 | C57: =_xlfn.CONCAT(A57,"-",B57) -> CD20-m007 | D57: 11.8393
A58: CD20 | B58: m008 | C58: =_xlfn.CONCAT(A58,"-",B58) -> CD20-m008 | D58: 14.6341
A59: CD20 | B59: m009 | C59: =_xlfn.CONCAT(A59,"-",B59) -> CD20-m009 | D59: 2.3771
A60: CD20 | B60: m010 | C60: =_xlfn.CONCAT(A60,"-",B60) -> CD20-m010 | D60: 11.8213
A61: CD20 | B61: m011 | C61: =_xlfn.CONCAT(A61,"-",B61) -> CD20-m011 | D61: 17.4849
A62: CD20 | B62: m012 | C62: =_xlfn.CONCAT(A62,"-",B62) -> CD20-m012 | D62: 16.7985
A63: CD20 | B63: m013 | C63: =_xlfn.CONCAT(A63,"-",B63) -> CD20-m013 | D63: 14.5655
A64: CD20 | B64: m029 | C64: =_xlfn.CONCAT(A64,"-",B64) -> CD20-m029 | D64: 4.3733
A65: CD20 | B65: m030 | C65: =_xlfn.CONCAT(A65,"-",B65) -> CD20-m030 | D65: 17.6805
... A171: CD27 | B171: m803 | C171: =_xlfn.CONCAT(A171,"-",B171) -> CD27-m803 | D171: 0.5787
A172: CD30 | B172: 158 | C172: =_xlfn.CONCAT(A172,"-m",B172) -> CD30-m158 | D172: 586.3097
A173: CD30 | B173: 159 | C173: =_xlfn.CONCAT(A173,"-m",B173) -> CD30-m159 | D173: 315.0203
A174: CD30 | B174: 160 | C174: =_xlfn.CONCAT(A174,"-m",B174) -> CD30-m160 | D174: 347.1628
A175: CD30 | B175: 161 | C175: =_xlfn.CONCAT(A175,"-m",B175) -> CD30-m161 | D175: 274.6268
A176: CD30 | B176: 162 | C176: =_xlfn.CONCAT(A176,"-m",B176) -> CD30-m162 | D176: 794.0524
A177: CD30 | B177: 164 | C177: =_xlfn.CONCAT(A177,"-m",B177) -> CD30-m164 | D177: 244.8502
A178: CD30 | B178: 165 | C178: =_xlfn.CONCAT(A178,"-m",B178) -> CD30-m165 | D178: 337.2518
A179: CD30 | B179: 166 | C179: =_xlfn.CONCAT(A179,"-m",B179) -> CD30-m166 | D179: 490.1936
A180: CD30 | B180: 167 | C180: =_xlfn.CONCAT(A180,"-m",B180) -> CD30-m167 | D180: 338.1059
A181: CD30 | B181: 168 | C181: =_xlfn.CONCAT(A181,"-m",B181) -> CD30-m168 | D181: 550.2127
A182: CD30 | B182: 169 | C182: =_xlfn.CONCAT(A182,"-m",B182) -> CD30-m169 | D182: 262.5437
A183: CD30 | B183: 170 | C183: =_xlfn.CONCAT(A183,"-m",B183) -> CD30-m170 | D183: 341.9487
... A311: CD46 | B311: 402 | C311: =_xlfn.CONCAT(A311,"-m",B311) -> CD46-m402 | D311: 20.7454
...

Sheet setpoint vl
A1: SampleID | B1: Count of Value | C1: Product of Value2 | D1: Average of Value2 | E1: GeoMean
A2: CD10-m851 | B2: 27 | C2: 5.3881599e+123 | D2: 122312.99 | E2: 38251.277
A3: CD10-m852 | B3: 22 | C3: 2.0365848e+121 | D3: 495151.58 | E3: 326618.68
A4: CD10-m853 | B4: 40 | C4: 1.6040472e+202 | D4: 154289.07 | E4: 113535.17
A5: CD10-m854 | B5: 34 | C5: 4.7981414e+175 | D5: 222531.39 | E5: 146923.2
A6: CD10-m855 | B6: 36 | C6: 1.6971311e+185 | D6: 287974.89 | E6: 139723.63
A7: CD10-m880 | B7: 20 | C7: 1.3554678e+117 | D7: 792706.09 | E7: 718794.03
A8: CD10-m896 | B8: 34 | C8: 3.7540516e+168 | D8: 133979.99 | E8: 90797.426
A9: CD10-m898 | B9: 8 | C9: 8.1687966e+45 | D9: 816046.5 | E9: 548301.91
A10: CD10-m899 | B10: 22 | C10: 1.1688106e+107 | D10: 102858.14 | E10: 73572.522
A11: CD10-m900 | B11: 27 | C11: 1.0334888e+126 | D11: 168421.93 | E11: 46472.551
A12: CD20-m004 | B12: 22 | C12: 4.3149168e+123 | D12: 570842.25 | E12: 416650.08
A13: CD20-m005 | B13: 19 | C13: 5.948822e+108 | D13: 1187582.1 | E13: 530847.84
... A55: CD20-m034 | B55: 2 | C55: 1.5344283e+08 | D55: 13161.588 | E55: 12387.204
