Workbook

Sheet JRCSF Haplotype Counts
A3: Row Labels | B3: Count of Escape Path | C3: Count of Escape Path2
A4: B: Other | B4: 2 | C4: 0.4 | E4: =B4/SUM(B4:B5) -> 0.4
A5: A: A281D | B5: 3 | C5: 0.6 | E5: =B5/SUM(B4:B5) -> 0.6
A6: (blank) | C6: 0
A7: Grand Total | B7: 5 | C7: 1 | D7: =SUM(C7:C9) -> 1

Sheet JR-CSF Haplotypes
K7: aa_pos | L7: 13 | M7: 94 | N7: 120 | O7: 162 | P7: 164 | Q7: 182 | R7: 185 | S7: 199 | T7: 274 | U7: 274 | V7: 276 | W7: 276 | X7: 279 | Y7: 304 | Z7: 336 | AA7: 336 | AB7: 338 | AC7: 369 | AD7: 403 | AE7: 405 | AF7: 405 | AG7: 466 | AH7: 501 | AI7: 526 | AJ7: 746 | AK7: 783 | AL7: 823 | AM7: 826 | AN7: 828
K8: HXB2_pos | L8: 10 | M8: 95 | N8: 121 | O8: 165 | P8: 167 | Q8: 185 | R8: 187a | S8: 201 | T8: 276 | U8: 276 | V8: 278 | W8: 278 | X8: 281 | Y8: 306 | Z8: 339 | AA8: 339 | AB8: 341 | AC8: 373 | AD8: 411 | AE8: 413 | AF8: 413 | AG8: 474 | AH8: 509 | AI8: 534 | AJ8: 754 | AK8: 791 | AL8: 831 | AM8: 834 | AN8: 836
K9: JRCSF_aa | L9: L | M9: M | N9: K | O9: I | P9: D | Q9: D | R9: N | S9: I | T9: N | U9: N | V9: T | W9: T | X9: A | Y9: S | Z9: N | AA9: N | AB9: T | AC9: M | AD9: N | AE9: T | AF9: T | AG9: D | AH9: E | AI9: S | AJ9: A | AK9: E | AL9: E | AM9: Q | AN9: V
A10: Samples | B10: Escape Path ID | C10: Escape Path | D10: Geometric Mean Expression (mg/ml) | E10: Time to Escape (Weeks) | F10: Time of Sequencing | G10: Time After Escape | H10: Number of Mutations (>.1) | I10: Number of Mutations (>.5) | J10: Number of Mutations (>.9) | K10: aa_alt | L10: W | M10: I | N10: T | O10: R | P10: N | Q10: N | R10: T | S10: V | T10: D | U10: S | V10: K | W10: M | X10: D | Y10: G | Z10: S | AA10: D | AB10: N | AC10: T | AD10: D | AE10: I | AF10: P | AG10: N | AH10: K | AI10: A | AJ10: T | AK10: K | AL10: K | AM10: H | AN10: A
A11: =K11 -> CD27-m806 | B11: B | C11: B: Other | D11: =VLOOKUP(A11,Expression!$C$1:$D$462,2,FALSE) -> 6.0638 | E11: =VLOOKUP(A11,survival!A1:B174,2,FALSE) -> 2 | F11: =VLOOKUP(A11,'sequencing metadata'!$A$1:$B$100,2,FALSE) -> 20 | G11: =F11-E11 -> 18 | H11: =COUNTIF(L11:EM11,">0.1") -> 10 | I11: =COUNTIF(L11:EM11,">0.5") -> 10 | J11: =COUNTIF(L11:EM11,">0.9") -> 10 | K11: CD27-m806 | L11: 0.98571429 | M11: 0 | N11: 0.99311532 | O11: 0 | P11: 0 | Q11: 0 | R11: 0.99801587 | S11: 0 | T11: 0 | U11: 0 | V11: 0 | W11: 0 | X11: 0 | Y11: 0 | Z11: 0 | AA11: 0 | AB11: 0.99445471 | AC11: 0 | AD11: 0 | AE11: 0 | AF11: 0.99395161 | AG11: 0 | AH11: 1 | AI11: 0 | AJ11: 0.99358974 | AK11: 0 | AL11: 0.99342105 | AM11: 0.99662162 | AN11: 1
A12: =K12 -> CD27-m810 | B12: B | C12: B: Other | D12: =VLOOKUP(A12,Expression!$C$1:$D$462,2,FALSE) -> 2.4628 | E12: =VLOOKUP(A12,survival!A2:B175,2,FALSE) -> 2 | F12: =VLOOKUP(A12,'sequencing metadata'!$A$1:$B$100,2,FALSE) -> 11 | G12: =F12-E12 -> 9 | H12: =COUNTIF(L12:EM12,">0.1") -> 5 | I12: =COUNTIF(L12:EM12,">0.5") -> 0 | J12: =COUNTIF(L12:EM12,">0.9") -> 0 | K12: CD27-m810 | L12: 0 | M12: 0 | N12: 0 | O12: 0 | P12: 0.26852659 | Q12: 0 | R12: 0.14679715 | S12: 0 | T12: 0 | U12: 0 | V12: 0 | W12: 0 | X12: 0 | Y12: 0 | Z12: 0 | AA12: 0.29143315 | AB12: 0 | AC12: 0 | AD12: 0.14126712 | AE12: 0 | AF12: 0 | AG12: 0 | AH12: 0 | AI12: 0 | AJ12: 0 | AK12: 0.24585219 | AL12: 0 | AM12: 0 | AN12: 0
A13: =K13 -> CD27-m808 | B13: A | C13: A: A281D + N276D | D13: =VLOOKUP(A13,Expression!$C$1:$D$462,2,FALSE) -> 1.732 | E13: =VLOOKUP(A13,survival!A3:B176,2,FALSE) -> 2 | F13: =VLOOKUP(A13,'sequencing metadata'!$A$1:$B$100,2,FALSE) -> 20 | G13: =F13-E13 -> 18 | H13: =COUNTIF(L13:EM13,">0.1") -> 11 | I13: =COUNTIF(L13:EM13,">0.5") -> 3 | J13: =COUNTIF(L13:EM13,">0.9") -> 0 | K13: CD27-m808 | L13: 0 | M13: 0.28067701 | N13: 0 | O13: 0 | P13: 0.83905325 | Q13: 0 | R13: 0 | S13: 0.25485009 | T13: 0 | U13: 0.32960894 | V13: 0.35009548 | W13: 0 | X13: 0.66186557 | Y13: 0 | Z13: 0.19927798 | AA13: 0.73357401 | AB13: 0 | AC13: 0.34471803 | AD13: 0 | AE13: 0 | AF13: 0 | AG13: 0.33067275 | AH13: 0 | AI13: 0 | AJ13: 0 | AK13: 0.35212888 | AL13: 0 | AM13: 0 | AN13: 0
A14: =K14 -> CD27-m756 | B14: A | C14: A: A281D + N276D | D14: =VLOOKUP(A14,Expression!$C$1:$D$462,2,FALSE) -> 4.7882 | E14: =VLOOKUP(A14,survival!A4:B177,2,FALSE) -> 2 | F14: =VLOOKUP(A14,'sequencing metadata'!$A$1:$B$100,2,FALSE) -> 20 | G14: =F14-E14 -> 18 | H14: =COUNTIF(L14:EM14,">0.1") -> 12 | I14: =COUNTIF(L14:EM14,">0.5") -> 5 | J14: =COUNTIF(L14:EM14,">0.9") -> 2 | K14: CD27-m756 | L14: 0 | M14: 0 | N14: 0 | O14: 0.57911065 | P14: 0.49342682 | Q14: 0.98928919 | R14: 0.99091735 | S14: 0 | T14: 0.41458027 | U14: 0 | V14: 0 | W14: 0.39833449 | X14: 0.80387931 | Y14: 0.52690763 | Z14: 0.45581395 | AA14: 0 | AB14: 0 | AC14: 0 | AD14: 0 | AE14: 0.33930254 | AF14: 0 | AG14: 0.36122178 | AH14: 0 | AI14: 0.2778865 | AJ14: 0 | AK14: 0 | AL14: 0 | AM14: 0 | AN14: 0
A15: =K15 -> CD27-m809 | B15: A | C15: A: A281D + N276D | D15: =VLOOKUP(A15,Expression!$C$1:$D$462,2,FALSE) -> 1.6536 | E15: =VLOOKUP(A15,survival!A5:B178,2,FALSE) -> 2 | F15: =VLOOKUP(A15,'sequencing metadata'!$A$1:$B$100,2,FALSE) -> 20 | G15: =F15-E15 -> 18 | H15: =COUNTIF(L15:EM15,">0.1") -> 13 | I15: =COUNTIF(L15:EM15,">0.5") -> 4 | J15: =COUNTIF(L15:EM15,">0.9") -> 0 | K15: CD27-m809 | L15: 0 | M15: 0 | N15: 0 | O15: 0.11497326 | P15: 0.74202128 | Q15: 0 | R15: 0.1402214 | S15: 0 | T15: 0.27290076 | U15: 0.11641221 | V15: 0 | W15: 0.31881533 | X15: 0.86212914 | Y15: 0.81541219 | Z15: 0 | AA15: 0.38515081 | AB15: 0 | AC15: 0 | AD15: 0.73658537 | AE15: 0.104 | AF15: 0 | AG15: 0.22168675 | AH15: 0 | AI15: 0 | AJ15: 0 | AK15: 0.31355932 | AL15: 0 | AM15: 0 | AN15: 0
K16: Score | L16: =COUNTIF(L11:L15,">0.25") -> 1 | M16: =COUNTIF(M11:M15,">0.25") -> 1 | N16: =COUNTIF(N11:N15,">0.25") -> 1 | O16: =COUNTIF(O11:O15,">0.25") -> 1 | P16: =COUNTIF(P11:P15,">0.25") -> 4 | Q16: =COUNTIF(Q11:Q15,">0.25") -> 1 | R16: =COUNTIF(R11:R15,">0.25") -> 2 | S16: =COUNTIF(S11:S15,">0.25") -> 1 | ... AN16: =COUNTIF(AN11:AN15,">0.25") -> 1

Sheet JR-CSF N6 Raw 0.1
B1: aa_pos | C1: HXB2_pos | D1: JRCSF_aa | E1: HXB2_aa | F1: Syn | G1: aa_alt | H1: CD27-m756 | I1: CD27-m806 | J1: CD27-m808 | K1: CD27-m809 | L1: CD27-m810 | M1: Score
A2: 0 | B2: 1 | C2: 1 | D2: M | E2: M | F2: =D2=G2 -> FALSE | G2: 0 | H2: 0 | I2: 0 | J2: 0 | K2: 0 | L2: 0 | M2: =COUNTIF(H2:L2,">0.25") -> 0
A3: 1 | B3: 2 | C3: 2 | D3: R | E3: R | F3: =D3=G3 -> FALSE | G3: K | H3: 0 | I3: 0 | J3: 0.18367347 | K3: 0 | L3: 0 | M3: =COUNTIF(H3:L3,">0.25") -> 0
A4: 2 | B4: 3 | C4: 3 | D4: V | E4: V | F4: =D4=G4 -> FALSE | G4: 0 | H4: 0 | I4: 0 | J4: 0 | K4: 0 | L4: 0 | M4: =COUNTIF(H4:L4,">0.25") -> 0
A5: 3 | B5: 4 | C5: 4 | D5: K | E5: K | F5: =D5=G5 -> FALSE | G5: 0 | H5: 0 | I5: 0 | J5: 0 | K5: 0 | L5: 0 | M5: =COUNTIF(H5:L5,">0.25") -> 0
A6: 4 | B6: 5 | C6: 4a | D6: G | E6: - | F6: =D6=G6 -> FALSE | G6: 0 | H6: 0 | I6: 0 | J6: 0 | K6: 0 | L6: 0 | M6: =COUNTIF(H6:L6,">0.25") -> 0
A7: 5 | B7: 6 | C7: 4b | D7: I | E7: - | F7: =D7=G7 -> FALSE | G7: 0 | H7: 0 | I7: 0 | J7: 0 | K7: 0 | L7: 0 | M7: =COUNTIF(H7:L7,">0.25") -> 0
A8: 6 | B8: 7 | C8: 4c | D8: R | E8: - | F8: =D8=G8 -> FALSE | G8: 0 | H8: 0 | I8: 0 | J8: 0 | K8: 0 | L8: 0 | M8: =COUNTIF(H8:L8,">0.25") -> 0
A9: 7 | B9: 8 | C9: 5 | D9: K | E9: E | F9: =D9=G9 -> FALSE | G9: 0 | H9: 0 | I9: 0 | J9: 0 | K9: 0 | L9: 0 | M9: =COUNTIF(H9:L9,">0.25") -> 0
A10: 8 | B10: 9 | C10: 6 | D10: N | E10: K | F10: =D10=G10 -> FALSE | G10: 0 | H10: 0 | I10: 0 | J10: 0 | K10: 0 | L10: 0 | M10: =COUNTIF(H10:L10,">0.25") -> 0
A11: 9 | B11: 10 | C11: 7 | D11: Y | E11: Y | F11: =D11=G11 -> FALSE | G11: 0 | H11: 0 | I11: 0 | J11: 0 | K11: 0 | L11: 0 | M11: =COUNTIF(H11:L11,">0.25") -> 0
A12: 10 | B12: 11 | C12: 8 | D12: Q | E12: Q | F12: =D12=G12 -> FALSE | G12: 0 | H12: 0 | I12: 0 | J12: 0 | K12: 0 | L12: 0 | M12: =COUNTIF(H12:L12,">0.25") -> 0
A13: 11 | B13: 12 | C13: 9 | D13: H | E13: H | F13: =D13=G13 -> FALSE | G13: 0 | H13: 0 | I13: 0 | J13: 0 | K13: 0 | L13: 0 | M13: =COUNTIF(H13:L13,">0.25") -> 0
A14: 12 | B14: 13 | C14: 10 | D14: L | E14: L | F14: =D14=G14 -> FALSE | G14: W | H14: 0 | I14: 0.98571429 | J14: 0 | K14: 0 | L14: 0 | M14: =COUNTIF(H14:L14,">0.25") -> 1
A15: 13 | B15: 14 | C15: 11 | D15: W | E15: W | F15: =D15=G15 -> FALSE | G15: 0 | H15: 0 | I15: 0 | J15: 0 | K15: 0 | L15: 0 | M15: =COUNTIF(H15:L15,">0.25") -> 0
A16: 14 | B16: 15 | C16: 12 | D16: K | E16: R | F16: =D16=G16 -> FALSE | G16: 0 | H16: 0 | I16: 0 | J16: 0 | K16: 0 | L16: 0 | M16: =COUNTIF(H16:L16,">0.25") -> 0
A17: 15 | B17: 15a | C17: 13 | D17: - | E17: W | F17: =D17=G17 -> FALSE | G17: 0 | H17: 0 | I17: 0 | J17: 0 | K17: 0 | L17: 0 | M17: =COUNTIF(H17:L17,">0.25") -> 0
A18: 16 | B18: 15b | C18: 14 | D18: - | E18: G | F18: =D18=G18 -> FALSE | G18: 0 | H18: 0 | I18: 0 | J18: 0 | K18: 0 | L18: 0 | M18: =COUNTIF(H18:L18,">0.25") -> 0
A19: 17 | B19: 15c | C19: 15 | D19: - | E19: W | F19: =D19=G19 -> FALSE | G19: 0 | H19: 0 | I19: 0 | J19: 0 | K19: 0 | L19: 0 | M19: =COUNTIF(H19:L19,">0.25") -> 0
A20: 18 | B20: 15d | C20: 16 | D20: - | E20: R | F20: =D20=G20 -> FALSE | G20: 0 | H20: 0 | I20: 0 | J20: 0 | K20: 0 | L20: 0 | M20: =COUNTIF(H20:L20,">0.25") -> 0
A21: 19 | B21: 16 | C21: 17 | D21: G | E21: W | F21: =D21=G21 -> TRUE | G21: G | H21: 0 | I21: 0 | J21: 0 | K21: 0.11009174 | L21: 0 | M21: =COUNTIF(H21:L21,">0.25") -> 0
A22: 20 | B22: 17 | C22: 18 | D22: G | E22: G | F22: =D22=G22 -> FALSE | G22: 0 | H22: 0 | I22: 0 | J22: 0 | K22: 0 | L22: 0 | M22: =COUNTIF(H22:L22,">0.25") -> 0
A23: 21 | B23: 18 | C23: 19 | D23: I | E23: T | F23: =D23=G23 -> FALSE | G23: 0 | H23: 0 | I23: 0 | J23: 0 | K23: 0 | L23: 0 | M23: =COUNTIF(H23:L23,">0.25") -> 0
A24: 22 | B24: 19 | C24: 20 | D24: L | E24: M | F24: =D24=G24 -> FALSE | G24: 0 | H24: 0 | I24: 0 | J24: 0 | K24: 0 | L24: 0 | M24: =COUNTIF(H24:L24,">0.25") -> 0
A25: 23 | B25: 20 | C25: 21 | D25: L | E25: L | F25: =D25=G25 -> FALSE | G25: 0 | H25: 0 | I25: 0 | J25: 0 | K25: 0 | L25: 0 | M25: =COUNTIF(H25:L25,">0.25") -> 0
A26: 24 | B26: 21 | C26: 22 | D26: L | E26: L | F26: =D26=G26 -> FALSE | G26: 0 | H26: 0 | I26: 0 | J26: 0 | K26: 0 | L26: 0 | M26: =COUNTIF(H26:L26,">0.25") -> 0
A27: 25 | B27: 22 | C27: 23 | D27: G | E27: G | F27: =D27=G27 -> FALSE | G27: 0 | H27: 0 | I27: 0 | J27: 0 | K27: 0 | L27: 0 | M27: =COUNTIF(H27:L27,">0.25") -> 0
A28: 26 | B28: 23 | C28: 24 | D28: T | E28: M | F28: =D28=G28 -> FALSE | G28: 0 | H28: 0 | I28: 0 | J28: 0 | K28: 0 | L28: 0 | M28: =COUNTIF(H28:L28,">0.25") -> 0
A29: 27 | B29: 24 | C29: 25 | D29: L | E29: L | F29: =D29=G29 -> FALSE | G29: 0 | H29: 0 | I29: 0 | J29: 0 | K29: 0 | L29: 0 | M29: =COUNTIF(H29:L29,">0.25") -> 0
A30: 28 | B30: 25 | C30: 26 | D30: M | E30: M | F30: =D30=G30 -> FALSE | G30: 0 | H30: 0 | I30: 0 | J30: 0 | K30: 0 | L30: 0 | M30: =COUNTIF(H30:L30,">0.25") -> 0
A31: 29 | B31: 26 | C31: 27 | D31: I | E31: I | F31: =D31=G31 -> FALSE | G31: 0 | H31: 0 | I31: 0 | J31: 0 | K31: 0 | L31: 0 | M31: =COUNTIF(H31:L31,">0.25") -> 0
A32: 30 | B32: 27 | C32: 28 | D32: C | E32: C | F32: =D32=G32 -> FALSE | G32: 0 | H32: 0 | I32: 0 | J32: 0 | K32: 0 | L32: 0 | M32: =COUNTIF(H32:L32,">0.25") -> 0
A33: 31 | B33: 28 | C33: 29 | D33: S | E33: S | F33: =D33=G33 -> FALSE | G33: 0 | H33: 0 | I33: 0 | J33: 0 | K33: 0 | L33: 0 | M33: =COUNTIF(H33:L33,">0.25") -> 0
... A62: 60 | B62: 57 | C62: 58 | D62: A | E62: A | F62: =D62=G62 -> FALSE | G62: 0 | H62: 0 | I62: 0 | J62: 0 | K62: 0 | L62: 0 | M62: =COUNTIF(H62:L62,">0.25") -> 0
A63: 61 | B63: 58 | C63: 59 | D63: K | E63: K | F63: =D63=G63 -> TRUE | G63: K | H63: 0 | I63: 0 | J63: 0 | K63: 0 | L63: 0.12 | M63: =COUNTIF(H63:L63,">0.25") -> 0
A64: 62 | B64: 59 | C64: 60 | D64: A | E64: A | F64: =D64=G64 -> FALSE | G64: 0 | H64: 0 | I64: 0 | J64: 0 | K64: 0 | L64: 0 | M64: =COUNTIF(H64:L64,">0.25") -> 0
A65: 63 | B65: 60 | C65: 61 | D65: Y | E65: Y | F65: =D65=G65 -> FALSE | G65: 0 | H65: 0 | I65: 0 | J65: 0 | K65: 0 | L65: 0 | M65: =COUNTIF(H65:L65,">0.25") -> 0
A66: 64 | B66: 61 | C66: 62 | D66: D | E66: D | F66: =D66=G66 -> FALSE | G66: 0 | H66: 0 | I66: 0 | J66: 0 | K66: 0 | L66: 0 | M66: =COUNTIF(H66:L66,">0.25") -> 0
A67: 65 | B67: 62 | C67: 63 | D67: T | E67: T | F67: =D67=G67 -> FALSE | G67: 0 | H67: 0 | I67: 0 | J67: 0 | K67: 0 | L67: 0 | M67: =COUNTIF(H67:L67,">0.25") -> 0
A68: 66 | B68: 63 | C68: 64 | D68: E | E68: E | F68: =D68=G68 -> TRUE | G68: E | H68: 0.33605442 | I68: 0 | J68: 0 | K68: 0 | L68: 0 | M68: =COUNTIF(H68:L68,">0.25") -> 1
...

Sheet JRCSF Survival Analysis
A1: Sample | B1: Weeks Post-AAV | C1: VRC07
A2: CD50-m066 | B2: 3 | C2: 1
A3: CD50-m067 | B3: 2 | C3: 1
A4: CD50-m068 | B4: 2 | C4: 1
A5: CD50-m069 | B5: 3 | C5: 1
A6: CD50-m071 | B6: 2 | C6: 1
A7: CD50-m072 | B7: 3 | C7: 1
A8: CD50-m073 | B8: 3 | C8: 1
A9: CD50-m074 | B9: 3 | C9: 1
A10: CD21-m998 | B10: 2
A11: CD21-m999 | B11: 2
A12: CD21-m002 | B12: 2
A13: CD21-m003 | B13: 2
A14: CD21-m004 | B14: 2
A15: CD21-m006 | B15: 2
A16: CD21-m007 | B16: 2
A17: CD21-m008 | B17: 2
A18: CD21-m009 | B18: 2
A19: CD30-m193 | B19: 2
A20: CD30-m195 | B20: 2
A21: CD30-m196 | B21: 3
... A32: CD30-m232 | B32: 2

Sheet sequencing metadata
A1: sample | B1: week
A2: CD5-m260 | B2: 24
A3: CD5-m263 | B3: 15
A4: CD5-m264 | B4: 9
A5: CD5-m265 | B5: 25
A6: CD5-m269 | B6: 22
A7: CD5-m271 | B7: 26
A8: CD5-m272 | B8: 26
A9: CD5-m273 | B9: 18
A10: CD5-m281 | B10: 20
A11: CD5-m285 | B11: 26
A12: CD10-m880 | B12: 24
A13: CD20-m020 | B13: 18
... A28: CD46-m336 | B28: 24
A29: CD46-m337
A30: CD46-m339 | B30: 13
A31: CD46-m340 | B31: 22
A32: CD50-m131 | B32: 15
A33: CD50-m134 | B33: 12
A34: CD50-m136 | B34: 12
A35: CD21-m998 | B35: 24
A36: CD21-m999 | B36: 24
A37: CD21-m002 | B37: 18
A38: CD21-m003 | B38: 24
A39: CD21-m004 | B39: 12
A40: CD21-m006 | B40: 24
A41: CD21-m007 | B41: 21
... A50: CD30-m205 | B50: 20
A51: CD30-m206
A52: CD30-m207 | B52: 20
A53: CD30-m228
A54: CD30-m229 | B54: 20
A55: CD30-m230 | B55: 16
A56: CD30-m231 | B56: 20
A57: CD30-m232 | B57: 12
A58: CD50-m066 | B58: 24
A59: CD50-m067
A60: CD50-m068 | B60: 24
A61: CD50-m069 | B61: 24
A62: CD50-m071 | B62: 24
...

Sheet Expression
A1: Experiment | B1: Mouse | C1: ID | D1: Geomean
A2: CD5 | B2: 260 | C2: =_xlfn.CONCAT(A2,"-m",B2) -> CD5-m260 | D2: 20.088
A3: CD5 | B3: 261 | C3: =_xlfn.CONCAT(A3,"-m",B3) -> CD5-m261 | D3: 40.2419
A4: CD5 | B4: 263 | C4: =_xlfn.CONCAT(A4,"-m",B4) -> CD5-m263 | D4: 32.966
A5: CD5 | B5: 264 | C5: =_xlfn.CONCAT(A5,"-m",B5) -> CD5-m264 | D5: 18.2003
A6: CD5 | B6: 265 | C6: =_xlfn.CONCAT(A6,"-m",B6) -> CD5-m265 | D6: 37.9099
A7: CD5 | B7: 266 | C7: =_xlfn.CONCAT(A7,"-m",B7) -> CD5-m266 | D7: 49.7924
A8: CD5 | B8: 267 | C8: =_xlfn.CONCAT(A8,"-m",B8) -> CD5-m267 | D8: 41.9774
A9: CD5 | B9: 269 | C9: =_xlfn.CONCAT(A9,"-m",B9) -> CD5-m269 | D9: 33.6268
A10: CD5 | B10: 270 | C10: =_xlfn.CONCAT(A10,"-m",B10) -> CD5-m270 | D10: 50.4443
A11: CD5 | B11: 271 | C11: =_xlfn.CONCAT(A11,"-m",B11) -> CD5-m271 | D11: 15.9094
A12: CD5 | B12: 272 | C12: =_xlfn.CONCAT(A12,"-m",B12) -> CD5-m272 | D12: 32.7447
A13: CD5 | B13: 273 | C13: =_xlfn.CONCAT(A13,"-m",B13) -> CD5-m273 | D13: 70.4947
... A53: CD10 | B53: 900 | C53: =_xlfn.CONCAT(A53,"-m",B53) -> CD10-m900 | D53: 42.3516
A54: CD20 | B54: m004 | C54: =_xlfn.CONCAT(A54,"-",B54) -> CD20-m004 | D54: 15.3163
A55: CD20 | B55: m005 | C55: =_xlfn.CONCAT(A55,"-",B55) -> CD20-m005 | D55: 13.9864
A56: CD20 | B56: m006 | C56: =_xlfn.CONCAT(A56,"-",B56) -> CD20-m006 | D56: 15.93
A57: CD20 | B57: m007 | C57: =_xlfn.CONCAT(A57,"-",B57) -> CD20-m007 | D57: 11.8393
A58: CD20 | B58: m008 | C58: =_xlfn.CONCAT(A58,"-",B58) -> CD20-m008 | D58: 14.6341
A59: CD20 | B59: m009 | C59: =_xlfn.CONCAT(A59,"-",B59) -> CD20-m009 | D59: 2.3771
A60: CD20 | B60: m010 | C60: =_xlfn.CONCAT(A60,"-",B60) -> CD20-m010 | D60: 11.8213
A61: CD20 | B61: m011 | C61: =_xlfn.CONCAT(A61,"-",B61) -> CD20-m011 | D61: 17.4849
A62: CD20 | B62: m012 | C62: =_xlfn.CONCAT(A62,"-",B62) -> CD20-m012 | D62: 16.7985
A63: CD20 | B63: m013 | C63: =_xlfn.CONCAT(A63,"-",B63) -> CD20-m013 | D63: 14.5655
A64: CD20 | B64: m029 | C64: =_xlfn.CONCAT(A64,"-",B64) -> CD20-m029 | D64: 4.3733
A65: CD20 | B65: m030 | C65: =_xlfn.CONCAT(A65,"-",B65) -> CD20-m030 | D65: 17.6805
... A171: CD27 | B171: m803 | C171: =_xlfn.CONCAT(A171,"-",B171) -> CD27-m803 | D171: 0.5787
A172: CD30 | B172: 158 | C172: =_xlfn.CONCAT(A172,"-m",B172) -> CD30-m158 | D172: 586.3097
A173: CD30 | B173: 159 | C173: =_xlfn.CONCAT(A173,"-m",B173) -> CD30-m159 | D173: 315.0203
A174: CD30 | B174: 160 | C174: =_xlfn.CONCAT(A174,"-m",B174) -> CD30-m160 | D174: 347.1628
A175: CD30 | B175: 161 | C175: =_xlfn.CONCAT(A175,"-m",B175) -> CD30-m161 | D175: 274.6268
A176: CD30 | B176: 162 | C176: =_xlfn.CONCAT(A176,"-m",B176) -> CD30-m162 | D176: 794.0524
A177: CD30 | B177: 164 | C177: =_xlfn.CONCAT(A177,"-m",B177) -> CD30-m164 | D177: 244.8502
A178: CD30 | B178: 165 | C178: =_xlfn.CONCAT(A178,"-m",B178) -> CD30-m165 | D178: 337.2518
A179: CD30 | B179: 166 | C179: =_xlfn.CONCAT(A179,"-m",B179) -> CD30-m166 | D179: 490.1936
A180: CD30 | B180: 167 | C180: =_xlfn.CONCAT(A180,"-m",B180) -> CD30-m167 | D180: 338.1059
A181: CD30 | B181: 168 | C181: =_xlfn.CONCAT(A181,"-m",B181) -> CD30-m168 | D181: 550.2127
A182: CD30 | B182: 169 | C182: =_xlfn.CONCAT(A182,"-m",B182) -> CD30-m169 | D182: 262.5437
A183: CD30 | B183: 170 | C183: =_xlfn.CONCAT(A183,"-m",B183) -> CD30-m170 | D183: 341.9487
... A311: CD46 | B311: 402 | C311: =_xlfn.CONCAT(A311,"-m",B311) -> CD46-m402 | D311: 20.7454
...

Sheet survival
A1: Sample | B1: Weeks Post-AAV | C1: Luciferase | D1: VRC07 | E1: PGDM140 | F1: N6
A2: CD5-m260 | B2: 12 | D2: 1
A3: CD5-m263 | B3: 7 | D3: 1
A4: CD5-m264 | B4: 4 | D4: 1
A5: CD5-m265 | B5: 5 | D5: 1
A6: CD5-m269 | B6: 14 | D6: 1
A7: CD5-m271 | B7: 3 | D7: 1
A8: CD5-m272 | B8: 5 | D8: 1
A9: CD5-m273 | B9: 8 | D9: 1
A10: CD5-m281 | B10: 2 | D10: 1
A11: CD5-m285 | B11: 2 | D11: 1
A12: CD10-m880 | B12: 10 | D12: 1
A13: CD20-m020 | B13: 3 | D13: 1
... A57: CD21-m020 | B57: 20 | D57: 0
A58: CD5-m245 | B58: 2 | C58: 1
A59: CD5-m246 | B59: 2 | C59: 1
A60: CD5-m247 | B60: 2 | C60: 1
A61: CD5-m248 | B61: 2 | C61: 1
A62: CD5-m249 | B62: 2 | C62: 1
A63: CD5-m250 | B63: 2 | C63: 1
A64: CD5-m251 | B64: 2 | C64: 1
A65: CD5-m253 | B65: 2 | C65: 1
A66: CD5-m254 | B66: 2 | C66: 1
A67: CD5-m255 | B67: 2 | C67: 1
A68: CD5-m256 | B68: 2 | C68: 1
A69: CD5-m257 | B69: 2 | C69: 1
... A101: CD21-m013 | B101: 2 | C101: 1
A102: CD21-m021*
A103: CD21-m022 | B103: 2 | C103: 1
A104: CD21-m023 | B104: 2 | C104: 1
A105: CD21-m024 | B105: 2 | C105: 1
A106: CD21-m025 | B106: 2 | C106: 1
A107: CD21-m026 | B107: 2 | C107: 1
A108: CD46-m324 | B108: 2 | C108: 1
A109: CD46-m327*
A110: CD46-m328 | B110: 2 | C110: 1
A111: CD46-m330 | B111: 2 | C111: 1
A112: CD5-m283*
A113: CD10-m876*
A114: CD20-m025*
...
