Workbook

Sheet RV Haplotypes Edited
D7: Geometric Mean Expression (mg/ml) | E7: Time to Escape (Weeks) | F7: RV Pos | G7: 280
B8: Escape Path | C8: Sample ID | F8: HXB2 Pos | G8: 279
F9: WT AA | G9: D
F10: Mut AA | G10: A | H10: K | I10: H
B11: =VLOOKUP($C11,'RD Haplotypes'!$A$10:$BR$30,3,FALSE) -> #N/A | C11: CD50-m168 | D11: =VLOOKUP($C11,'RD Haplotypes'!$A$10:$BR$30,4,FALSE) -> #N/A | E11: =VLOOKUP($C11,'RD Haplotypes'!$A$10:$BR$30,5,FALSE) -> #N/A | G11: 0.84979716 | H11: 0 | I11: 0.1464503
C12: CD50-m167 | D12: =VLOOKUP($C12,'RD Haplotypes'!$A$10:$BR$30,4,FALSE) -> #N/A | E12: =VLOOKUP($C12,'RD Haplotypes'!$A$10:$BR$30,5,FALSE) -> #N/A | G12: 0.97213904 | H12: 0 | I12: 0
C13: CD50-m169 | D13: =VLOOKUP($C13,'RD Haplotypes'!$A$10:$BR$30,4,FALSE) -> #N/A | E13: =VLOOKUP($C13,'RD Haplotypes'!$A$10:$BR$30,5,FALSE) -> #N/A | G13: 0.99513627 | H13: 0 | I13: 0
C14: CD50-m163 | D14: =VLOOKUP($C14,'RD Haplotypes'!$A$10:$BR$30,4,FALSE) -> #N/A | E14: =VLOOKUP($C14,'RD Haplotypes'!$A$10:$BR$30,5,FALSE) -> #N/A | G14: 0.9959894 | H14: 0 | I14: 0
C15: CD50-m166 | D15: =VLOOKUP($C15,'RD Haplotypes'!$A$10:$BR$30,4,FALSE) -> #N/A | E15: =VLOOKUP($C15,'RD Haplotypes'!$A$10:$BR$30,5,FALSE) -> #N/A | G15: 0.99651422 | H15: 0 | I15: 0
B16: =VLOOKUP($C16,'RD Haplotypes'!$A$10:$BR$30,3,FALSE) -> #N/A | C16: CD50-m172 | D16: =VLOOKUP($C16,'RD Haplotypes'!$A$10:$BR$30,4,FALSE) -> #N/A | E16: =VLOOKUP($C16,'RD Haplotypes'!$A$10:$BR$30,5,FALSE) -> #N/A | G16: 0 | H16: 0.99771347 | I16: 0
C17: CD50-m175 | D17: =VLOOKUP($C17,'RD Haplotypes'!$A$10:$BR$30,4,FALSE) -> #N/A | E17: =VLOOKUP($C17,'RD Haplotypes'!$A$10:$BR$30,5,FALSE) -> #N/A | G17: 0 | H17: 0.99725421 | I17: 0
C18: CD50-m176 | D18: =VLOOKUP($C18,'RD Haplotypes'!$A$10:$BR$30,4,FALSE) -> #N/A | E18: =VLOOKUP($C18,'RD Haplotypes'!$A$10:$BR$30,5,FALSE) -> #N/A | G18: 0 | H18: 0.76339042 | I18: 0
B19: =VLOOKUP($C19,'RD Haplotypes'!$A$10:$BR$30,3,FALSE) -> #N/A | C19: CD50-m161 | D19: =VLOOKUP($C19,'RD Haplotypes'!$A$10:$BR$30,4,FALSE) -> #N/A | E19: =VLOOKUP($C19,'RD Haplotypes'!$A$10:$BR$30,5,FALSE) -> #N/A | G19: 0 | H19: 0 | I19: 0.992232

Sheet RD Haplotypes
H7: aa_pos | I7: 97 | J7: 168 | K7: 168 | L7: 237 | M7: 256 | N7: 260 | O7: 262 | P7: 269 | Q7: 271 | R7: 276 | S7: 278 | T7: 280 | U7: 282 | V7: 282 | W7: 283 | X7: 283 | Y7: 284 | Z7: 288 | AA7: 292 | AB7: 453 | AC7: 473 | AD7: 477 | AE7: 489 | AF7: 502 | AG7: 650 | AH7: 667 | AI7: 761 | AJ7: 854 | AK7: 854
H8: HXB2_pos | I8: 98 | J8: 167 | K8: 167 | L8: 236 | M8: 255 | N8: 259 | O8: 261 | P8: 268 | Q8: 270 | R8: 275 | S8: 277 | T8: 279 | U8: 281 | V8: 281 | W8: 282 | X8: 282 | Y8: 283 | Z8: 287 | AA8: 291 | AB8: 455 | AC8: 474 | AD8: 478 | AE8: 490 | AF8: 503 | AG8: 651 | AH8: 668 | AI8: 762 | AJ8: 855 | AK8: 856
H9: RD_aa | I9: S | J9: D | K9: D | L9: T | M9: I | N9: L | O9: L | P9: D | Q9: V | R9: D | S9: F | T9: D | U9: A | V9: A | W9: K | X9: K | Y9: T | Z9: H | AA9: T | AB9: T | AC9: D | AD9: N | AE9: Q | AF9: R | AG9: N | AH9: S | AI9: S | AJ9: L | AK9: L
A10: Samples | B10: Escape Path ID | C10: Escape Path | D10: Geometric Mean Expression (mg/ml) | E10: Time to Escape (Weeks) | F10: Time of Sequencing | G10: Time After Escape | H10: aa_alt | I10: N | J10: G | K10: N | L10: K | M10: V | N10: L | O10: L | P10: E | Q10: V | R10: E | S10: F | T10: N | U10: DEL | V10: T | W10: N | X10: DEL | Y10: I | Z10: Q | AA10: S | AB10: I | AC10: D | AD10: N | AE10: K | AF10: K | AG10: S | AH10: G | AI10: N | AJ10: M | AK10: I
A11: CD50-m151 | B11: A | C11: =VLOOKUP(B11,'RV Escape Paths'!$A$1:$C$5,3,FALSE) -> A: D279A | D11: =VLOOKUP(A11,Expression!$C$1:$D$462,2,FALSE) -> 64.1636 | E11: =VLOOKUP(A11,'RV Survival Analysis'!$A$1:$C$100,3,FALSE) -> #N/A | F11: =VLOOKUP(A11,'sequencing metadata'!$A$1:$B$34,2,FALSE) -> #N/A | G11: =F11-E11 -> #N/A | I11: 0.50228675 | J11: 0 | K11: 0.70874959 | L11: 0 | M11: 0.99423868 | N11: 0.86423358 | O11: 0.99190283 | P11: 0.9738806 | Q11: 0.97520661 | R11: 0.98947368 | S11: 0.98412698 | T11: 0 | U11: 0.6080402 | V11: 0 | W11: 0.32017544 | X11: 0.53070175 | Y11: 0.98888889 | Z11: 0.99434229 | AA11: 0.9939759 | AB11: 0.99667837 | AC11: 0.99636713 | AD11: 0.9967557 | AE11: 0.93257318 | AF11: 0 | AG11: 0 | AH11: 0 | AI11: 0 | AJ11: 0.35344418 | AK11: 0
A12: CD50-m152 | B12: A | C12: =VLOOKUP(B12,'RV Escape Paths'!$A$1:$C$5,3,FALSE) -> A: D279A | D12: =VLOOKUP(A12,Expression!$C$1:$D$462,2,FALSE) -> 65.4274 | E12: =VLOOKUP(A12,'RV Survival Analysis'!$A$1:$C$100,3,FALSE) -> #N/A | F12: =VLOOKUP(A12,'sequencing metadata'!$A$1:$B$34,2,FALSE) -> #N/A | G12: =F12-E12 -> #N/A | I12: 0 | J12: 0.99607623 | K12: 0 | L12: 0.99509403 | M12: 0 | N12: 0 | O12: 0 | P12: 0 | Q12: 0 | R12: 0 | S12: 0 | T12: 0.93771962 | U12: 0 | V12: 0.94370263 | W12: 0 | X12: 0 | Y12: 0 | Z12: 0 | AA12: 0 | AB12: 0 | AC12: 0 | AD12: 0 | AE12: 0 | AF12: 0.34282836 | AG12: 0.46633593 | AH12: 0.67981528 | AI12: 0.3595679 | AJ12: 0 | AK12: 0
H13: Score | I13: =COUNTIF(I11:I12,">0.25") -> 1 | J13: =COUNTIF(J11:J12,">0.25") -> 1 | K13: =COUNTIF(K11:K12,">0.25") -> 1 | L13: =COUNTIF(L11:L12,">0.25") -> 1 | M13: =COUNTIF(M11:M12,">0.25") -> 1 | N13: =COUNTIF(N11:N12,">0.25") -> 1 | O13: =COUNTIF(O11:O12,">0.25") -> 1 | P13: =COUNTIF(P11:P12,">0.25") -> 1 | ... AJ13: =COUNTIF(AJ11:AJ12,">0.25") -> 1 | AK13: 0

Sheet RV Hap Count
A3: Row Labels | B3: Count of Escape Path | C3: Count of Escape Path2
A4: A: D279A | B4: 2 | C4: 1
A5: (blank) | C5: 0
A6: Grand Total | B6: 2 | C6: 1

Sheet RV Escape Paths
A1: Escape Path ID | B1: Escape Path | C1: Escape Path + ID
A2: A | B2: D279A | C2: =_xlfn.CONCAT(A2,": ",B2) -> A: D279A
A3: B | B3: D279K | C3: =_xlfn.CONCAT(A3,": ",B3) -> B: D279K
A4: C | B4: D279H | C4: =_xlfn.CONCAT(A4,": ",B4) -> C: D279H
A5: D | B5: Other | C5: =_xlfn.CONCAT(A5,": ",B5) -> D: Other

Sheet RD Raw 0.1
B1: aa_pos | C1: HXB2_pos | D1: RD_aa | E1: HXB2_aa | F1: aa_alt | G1: CD50-m151 | H1: CD50-m152 | I1: Score
A2: 0 | B2: 1 | C2: 1 | D2: M | E2: M | F2: 0 | G2: 0 | H2: 0 | I2: =COUNTIF(G2:H2,">0.1") -> 0
A3: 1 | B3: 2 | C3: 2 | D3: K | E3: R | F3: 0 | G3: 0 | H3: 0 | I3: =COUNTIF(G3:H3,">0.1") -> 0
A4: 2 | B4: 3 | C4: 3 | D4: V | E4: V | F4: 0 | G4: 0 | H4: 0 | I4: =COUNTIF(G4:H4,">0.1") -> 0
A5: 3 | B5: 4 | C5: 4 | D5: K | E5: K | F5: 0 | G5: 0 | H5: 0 | I5: =COUNTIF(G5:H5,">0.1") -> 0
A6: 4 | B6: 5 | C6: 4a | D6: G | E6: - | F6: 0 | G6: 0 | H6: 0 | I6: =COUNTIF(G6:H6,">0.1") -> 0
A7: 5 | B7: 6 | C7: 4b | D7: I | E7: - | F7: 0 | G7: 0 | H7: 0 | I7: =COUNTIF(G7:H7,">0.1") -> 0
A8: 6 | B8: 7 | C8: 4c | D8: R | E8: - | F8: 0 | G8: 0 | H8: 0 | I8: =COUNTIF(G8:H8,">0.1") -> 0
A9: 7 | B9: 8 | C9: 5 | D9: R | E9: E | F9: 0 | G9: 0 | H9: 0 | I9: =COUNTIF(G9:H9,">0.1") -> 0
A10: 8 | B10: 9 | C10: 6 | D10: N | E10: K | F10: 0 | G10: 0 | H10: 0 | I10: =COUNTIF(G10:H10,">0.1") -> 0
A11: 9 | B11: 10 | C11: 7 | D11: Y | E11: Y | F11: 0 | G11: 0 | H11: 0 | I11: =COUNTIF(G11:H11,">0.1") -> 0
A12: 10 | B12: 11 | C12: 8 | D12: Q | E12: Q | F12: 0 | G12: 0 | H12: 0 | I12: =COUNTIF(G12:H12,">0.1") -> 0
A13: 11 | B13: 12 | C13: 9 | D13: H | E13: H | F13: 0 | G13: 0 | H13: 0 | I13: =COUNTIF(G13:H13,">0.1") -> 0
A14: 12 | B14: 13 | C14: 10 | D14: L | E14: L | F14: 0 | G14: 0 | H14: 0 | I14: =COUNTIF(G14:H14,">0.1") -> 0
A15: 13 | B15: 14 | C15: 11 | D15: W | E15: W | F15: 0 | G15: 0 | H15: 0 | I15: =COUNTIF(G15:H15,">0.1") -> 0
A16: 14 | B16: 15 | C16: 12 | D16: R | E16: R | F16: 0 | G16: 0 | H16: 0 | I16: =COUNTIF(G16:H16,">0.1") -> 0
A17: 15 | B17: 15a | C17: 13 | D17: - | E17: W | F17: 0 | G17: 0 | H17: 0 | I17: =COUNTIF(G17:H17,">0.1") -> 0
A18: 16 | B18: 15b | C18: 14 | D18: - | E18: G | F18: 0 | G18: 0 | H18: 0 | I18: =COUNTIF(G18:H18,">0.1") -> 0
A19: 17 | B19: 15c | C19: 15 | D19: - | E19: W | F19: 0 | G19: 0 | H19: 0 | I19: =COUNTIF(G19:H19,">0.1") -> 0
A20: 18 | B20: 15d | C20: 16 | D20: - | E20: R | F20: 0 | G20: 0 | H20: 0 | I20: =COUNTIF(G20:H20,">0.1") -> 0
A21: 19 | B21: 16 | C21: 17 | D21: W | E21: W | F21: 0 | G21: 0 | H21: 0 | I21: =COUNTIF(G21:H21,">0.1") -> 0
A22: 20 | B22: 17 | C22: 18 | D22: G | E22: G | F22: S | G22: 0.16896502 | H22: 0 | I22: =COUNTIF(G22:H22,">0.1") -> 1
A23: 21 | B23: 18 | C23: 19 | D23: I | E23: T | F23: 0 | G23: 0 | H23: 0 | I23: =COUNTIF(G23:H23,">0.1") -> 0
A24: 22 | B24: 19 | C24: 20 | D24: M | E24: M | F24: 0 | G24: 0 | H24: 0 | I24: =COUNTIF(G24:H24,">0.1") -> 0
A25: 23 | B25: 20 | C25: 21 | D25: L | E25: L | F25: 0 | G25: 0 | H25: 0 | I25: =COUNTIF(G25:H25,">0.1") -> 0
A26: 24 | B26: 21 | C26: 22 | D26: L | E26: L | F26: 0 | G26: 0 | H26: 0 | I26: =COUNTIF(G26:H26,">0.1") -> 0
A27: 25 | B27: 22 | C27: 23 | D27: G | E27: G | F27: 0 | G27: 0 | H27: 0 | I27: =COUNTIF(G27:H27,">0.1") -> 0
A28: 26 | B28: 23 | C28: 24 | D28: I | E28: M | F28: 0 | G28: 0 | H28: 0 | I28: =COUNTIF(G28:H28,">0.1") -> 0
A29: 27 | B29: 24 | C29: 25 | D29: L | E29: L | F29: 0 | G29: 0 | H29: 0 | I29: =COUNTIF(G29:H29,">0.1") -> 0
A30: 28 | B30: 25 | C30: 26 | D30: M | E30: M | F30: 0 | G30: 0 | H30: 0 | I30: =COUNTIF(G30:H30,">0.1") -> 0
A31: 29 | B31: 26 | C31: 27 | D31: I | E31: I | F31: 0 | G31: 0 | H31: 0 | I31: =COUNTIF(G31:H31,">0.1") -> 0
A32: 30 | B32: 27 | C32: 28 | D32: C | E32: C | F32: 0 | G32: 0 | H32: 0 | I32: =COUNTIF(G32:H32,">0.1") -> 0
A33: 31 | B33: 28 | C33: 29 | D33: S | E33: S | F33: 0 | G33: 0 | H33: 0 | I33: =COUNTIF(G33:H33,">0.1") -> 0
A34: 32 | B34: 29 | C34: 30 | D34: A | E34: A | F34: 0 | G34: 0 | H34: 0 | I34: =COUNTIF(G34:H34,">0.1") -> 0
... A101: 99 | B101: 96 | C101: 97 | D101: K | E101: K | F101: 0 | G101: 0 | H101: 0 | I101: =COUNTIF(G101:H101,">0.1") -> 0
A102: 100 | B102: 97 | C102: 98 | D102: S | E102: N | F102: N | G102: 0.50228675 | H102: 0 | I102: =COUNTIF(G102:H102,">0.1") -> 1
A103: 101 | B103: 98 | C103: 99 | D103: N | E103: D | F103: 0 | G103: 0 | H103: 0 | I103: =COUNTIF(G103:H103,">0.1") -> 0
A104: 102 | B104: 99 | C104: 100 | D104: M | E104: M | F104: 0 | G104: 0 | H104: 0 | I104: =COUNTIF(G104:H104,">0.1") -> 0
A105: 103 | B105: 100 | C105: 101 | D105: V | E105: V | F105: 0 | G105: 0 | H105: 0 | I105: =COUNTIF(G105:H105,">0.1") -> 0
A106: 104 | B106: 101 | C106: 102 | D106: E | E106: E | F106: 0 | G106: 0 | H106: 0 | I106: =COUNTIF(G106:H106,">0.1") -> 0
...

Sheet survival
A1: Sample | B1: Weeks Post-AAV | C1: Luciferase | D1: VRC07 | E1: PGDM140 | F1: N6
A2: CD5-m260 | B2: 12 | D2: 1
A3: CD5-m263 | B3: 7 | D3: 1
A4: CD5-m264 | B4: 4 | D4: 1
A5: CD5-m265 | B5: 5 | D5: 1
A6: CD5-m269 | B6: 14 | D6: 1
A7: CD5-m271 | B7: 3 | D7: 1
A8: CD5-m272 | B8: 5 | D8: 1
A9: CD5-m273 | B9: 8 | D9: 1
A10: CD5-m281 | B10: 2 | D10: 1
A11: CD5-m285 | B11: 2 | D11: 1
A12: CD10-m880 | B12: 10 | D12: 1
A13: CD20-m020 | B13: 3 | D13: 1
... A57: CD21-m020 | B57: 20 | D57: 0
A58: CD5-m245 | B58: 2 | C58: 1
A59: CD5-m246 | B59: 2 | C59: 1
A60: CD5-m247 | B60: 2 | C60: 1
A61: CD5-m248 | B61: 2 | C61: 1
A62: CD5-m249 | B62: 2 | C62: 1
A63: CD5-m250 | B63: 2 | C63: 1
A64: CD5-m251 | B64: 2 | C64: 1
A65: CD5-m253 | B65: 2 | C65: 1
A66: CD5-m254 | B66: 2 | C66: 1
A67: CD5-m255 | B67: 2 | C67: 1
A68: CD5-m256 | B68: 2 | C68: 1
A69: CD5-m257 | B69: 2 | C69: 1
... A101: CD21-m013 | B101: 2 | C101: 1
A102: CD21-m021*
A103: CD21-m022 | B103: 2 | C103: 1
A104: CD21-m023 | B104: 2 | C104: 1
A105: CD21-m024 | B105: 2 | C105: 1
A106: CD21-m025 | B106: 2 | C106: 1
A107: CD21-m026 | B107: 2 | C107: 1
A108: CD46-m324 | B108: 2 | C108: 1
A109: CD46-m327*
A110: CD46-m328 | B110: 2 | C110: 1
A111: CD46-m330 | B111: 2 | C111: 1
A112: CD5-m283*
A113: CD10-m876*
A114: CD20-m025*
...

Sheet Expression
A1: Experiment | B1: Mouse | C1: ID | D1: Geomean
A2: CD5 | B2: 260 | C2: =_xlfn.CONCAT(A2,"-m",B2) -> CD5-m260 | D2: 20.088
A3: CD5 | B3: 261 | C3: =_xlfn.CONCAT(A3,"-m",B3) -> CD5-m261 | D3: 40.2419
A4: CD5 | B4: 263 | C4: =_xlfn.CONCAT(A4,"-m",B4) -> CD5-m263 | D4: 32.966
A5: CD5 | B5: 264 | C5: =_xlfn.CONCAT(A5,"-m",B5) -> CD5-m264 | D5: 18.2003
A6: CD5 | B6: 265 | C6: =_xlfn.CONCAT(A6,"-m",B6) -> CD5-m265 | D6: 37.9099
A7: CD5 | B7: 266 | C7: =_xlfn.CONCAT(A7,"-m",B7) -> CD5-m266 | D7: 49.7924
A8: CD5 | B8: 267 | C8: =_xlfn.CONCAT(A8,"-m",B8) -> CD5-m267 | D8: 41.9774
A9: CD5 | B9: 269 | C9: =_xlfn.CONCAT(A9,"-m",B9) -> CD5-m269 | D9: 33.6268
A10: CD5 | B10: 270 | C10: =_xlfn.CONCAT(A10,"-m",B10) -> CD5-m270 | D10: 50.4443
A11: CD5 | B11: 271 | C11: =_xlfn.CONCAT(A11,"-m",B11) -> CD5-m271 | D11: 15.9094
A12: CD5 | B12: 272 | C12: =_xlfn.CONCAT(A12,"-m",B12) -> CD5-m272 | D12: 32.7447
A13: CD5 | B13: 273 | C13: =_xlfn.CONCAT(A13,"-m",B13) -> CD5-m273 | D13: 70.4947
... A53: CD10 | B53: 900 | C53: =_xlfn.CONCAT(A53,"-m",B53) -> CD10-m900 | D53: 42.3516
A54: CD20 | B54: m004 | C54: =_xlfn.CONCAT(A54,"-",B54) -> CD20-m004 | D54: 15.3163
A55: CD20 | B55: m005 | C55: =_xlfn.CONCAT(A55,"-",B55) -> CD20-m005 | D55: 13.9864
A56: CD20 | B56: m006 | C56: =_xlfn.CONCAT(A56,"-",B56) -> CD20-m006 | D56: 15.93
A57: CD20 | B57: m007 | C57: =_xlfn.CONCAT(A57,"-",B57) -> CD20-m007 | D57: 11.8393
A58: CD20 | B58: m008 | C58: =_xlfn.CONCAT(A58,"-",B58) -> CD20-m008 | D58: 14.6341
A59: CD20 | B59: m009 | C59: =_xlfn.CONCAT(A59,"-",B59) -> CD20-m009 | D59: 2.3771
A60: CD20 | B60: m010 | C60: =_xlfn.CONCAT(A60,"-",B60) -> CD20-m010 | D60: 11.8213
A61: CD20 | B61: m011 | C61: =_xlfn.CONCAT(A61,"-",B61) -> CD20-m011 | D61: 17.4849
A62: CD20 | B62: m012 | C62: =_xlfn.CONCAT(A62,"-",B62) -> CD20-m012 | D62: 16.7985
A63: CD20 | B63: m013 | C63: =_xlfn.CONCAT(A63,"-",B63) -> CD20-m013 | D63: 14.5655
A64: CD20 | B64: m029 | C64: =_xlfn.CONCAT(A64,"-",B64) -> CD20-m029 | D64: 4.3733
A65: CD20 | B65: m030 | C65: =_xlfn.CONCAT(A65,"-",B65) -> CD20-m030 | D65: 17.6805
... A171: CD27 | B171: m803 | C171: =_xlfn.CONCAT(A171,"-",B171) -> CD27-m803 | D171: 0.5787
A172: CD30 | B172: 158 | C172: =_xlfn.CONCAT(A172,"-m",B172) -> CD30-m158 | D172: 586.3097
A173: CD30 | B173: 159 | C173: =_xlfn.CONCAT(A173,"-m",B173) -> CD30-m159 | D173: 315.0203
A174: CD30 | B174: 160 | C174: =_xlfn.CONCAT(A174,"-m",B174) -> CD30-m160 | D174: 347.1628
A175: CD30 | B175: 161 | C175: =_xlfn.CONCAT(A175,"-m",B175) -> CD30-m161 | D175: 274.6268
A176: CD30 | B176: 162 | C176: =_xlfn.CONCAT(A176,"-m",B176) -> CD30-m162 | D176: 794.0524
A177: CD30 | B177: 164 | C177: =_xlfn.CONCAT(A177,"-m",B177) -> CD30-m164 | D177: 244.8502
A178: CD30 | B178: 165 | C178: =_xlfn.CONCAT(A178,"-m",B178) -> CD30-m165 | D178: 337.2518
A179: CD30 | B179: 166 | C179: =_xlfn.CONCAT(A179,"-m",B179) -> CD30-m166 | D179: 490.1936
A180: CD30 | B180: 167 | C180: =_xlfn.CONCAT(A180,"-m",B180) -> CD30-m167 | D180: 338.1059
A181: CD30 | B181: 168 | C181: =_xlfn.CONCAT(A181,"-m",B181) -> CD30-m168 | D181: 550.2127
A182: CD30 | B182: 169 | C182: =_xlfn.CONCAT(A182,"-m",B182) -> CD30-m169 | D182: 262.5437
A183: CD30 | B183: 170 | C183: =_xlfn.CONCAT(A183,"-m",B183) -> CD30-m170 | D183: 341.9487
... A311: CD46 | B311: 402 | C311: =_xlfn.CONCAT(A311,"-m",B311) -> CD46-m402 | D311: 20.7454
...

Sheet RV Survival Analysis
A1: Sample | B1: Expression | C1: Weeks Post-AAV | D1: Luciferase | E1: VRC07
A2: CD50-m161 | B2: =VLOOKUP(A2,Expression!$C$1:$D$462,2,FALSE) -> 72.2074 | C2: 3 | E2: 1
A3: CD50-m163 | B3: =VLOOKUP(A3,Expression!$C$1:$D$462,2,FALSE) -> 66.6016 | C3: 2 | E3: 1
A4: CD50-m166 | B4: =VLOOKUP(A4,Expression!$C$1:$D$462,2,FALSE) -> 81.6119 | C4: 3 | E4: 1
A5: CD50-m167 | B5: =VLOOKUP(A5,Expression!$C$1:$D$462,2,FALSE) -> 59.3852 | C5: 2 | E5: 1
A6: CD50-m168 | B6: =VLOOKUP(A6,Expression!$C$1:$D$462,2,FALSE) -> 69.7866 | C6: 3 | E6: 1
A7: CD50-m169 | B7: =VLOOKUP(A7,Expression!$C$1:$D$462,2,FALSE) -> 71.5889 | C7: 2 | E7: 1
A8: CD50-m170 | B8: =VLOOKUP(A8,Expression!$C$1:$D$462,2,FALSE) -> 48.2679 | C8: 3 | E8: 1
A9: CD50-m172 | B9: =VLOOKUP(A9,Expression!$C$1:$D$462,2,FALSE) -> 87.1257 | C9: 7 | E9: 1
A10: CD50-m175 | B10: =VLOOKUP(A10,Expression!$C$1:$D$462,2,FALSE) -> 74.0363 | C10: 5 | E10: 1
A11: CD50-m176 | B11: =VLOOKUP(A11,Expression!$C$1:$D$462,2,FALSE) -> 46.3611 | C11: 5 | E11: 1

Sheet sequencing metadata
A1: sample | B1: week
A2: CD50-m161 | B2: 15
A3: CD50-m163 | B3: 21
A4: CD50-m166 | B4: 23
A5: CD50-m167 | B5: 18
A6: CD50-m168 | B6: 17
A7: CD50-m169 | B7: 23
A8: CD50-m170
A9: CD50-m172 | B9: 24
A10: CD50-m175 | B10: 17
A11: CD50-m176 | B11: 23
