Workbook

Sheet JR-CSF Haplotypes - only CD50
D7: Geometric Mean Expression (ug/ml) | F7: Time to Escape (Weeks) | G7: REJO.c Pos | H7: 277
B8: Escape Path | C8: Sample ID | G8: HXB2 Pos | H8: 279
G9: WT AA | H9: D
G10: Mut AA | H10: A | I10: E | J10: H | K10: K | L10: N | M10: Y | O10: Mean Expression
B11: =VLOOKUP(C11,'JR-CSF Haplotypes'!$A$11:$C$36,3,FALSE) -> A: D279A | C11: CD50-m069 | D11: =VLOOKUP(C11,'JR-CSF Haplotypes'!$A$10:$K$36,4,FALSE) -> 66.0624 | F11: =VLOOKUP(C11,'JR-CSF Haplotypes'!$A$10:$K$36,5,FALSE) -> 3 | H11: 0.9950481 | I11: 0 | J11: 0 | K11: 0 | L11: 0 | M11: 0
C12: CD50-m074 | D12: =VLOOKUP(C12,'JR-CSF Haplotypes'!$A$10:$K$36,4,FALSE) -> 63.3509 | F12: =VLOOKUP(C12,'JR-CSF Haplotypes'!$A$10:$K$36,5,FALSE) -> 3 | H12: 0.86808466 | I12: 0 | J12: 0.12426655 | K12: 0 | L12: 0 | M12: 0
B13: =VLOOKUP(C13,'JR-CSF Haplotypes'!$A$11:$C$36,3,FALSE) -> B: D279H | C13: CD21-m007 | D13: =VLOOKUP(C13,'JR-CSF Haplotypes'!$A$10:$K$36,4,FALSE) -> 149.745 | F13: =VLOOKUP(C13,'JR-CSF Haplotypes'!$A$10:$K$36,5,FALSE) -> 2 | H13: 0 | I13: 0 | J13: 0.98687215 | K13: 0 | L13: 0 | M13: 0
C14: CD50-m068 | D14: =VLOOKUP(C14,'JR-CSF Haplotypes'!$A$10:$K$36,4,FALSE) -> 39.0022 | F14: =VLOOKUP(C14,'JR-CSF Haplotypes'!$A$10:$K$36,5,FALSE) -> 2 | H14: 0 | I14: 0 | J14: 1 | K14: 0 | L14: 0 | M14: 0
B15: =VLOOKUP(C15,'JR-CSF Haplotypes'!$A$11:$C$36,3,FALSE) -> C: D279N + Other | C15: CD50-m071 | D15: =VLOOKUP(C15,'JR-CSF Haplotypes'!$A$10:$K$36,4,FALSE) -> 48.8981 | F15: =VLOOKUP(C15,'JR-CSF Haplotypes'!$A$10:$K$36,5,FALSE) -> 2 | H15: 0 | I15: 0 | J15: 0 | K15: 0 | L15: 0.825 | M15: 0
B16: =VLOOKUP(C16,'JR-CSF Haplotypes'!$A$11:$C$36,3,FALSE) -> D: D279E + Other | C16: CD50-m073 | D16: =VLOOKUP(C16,'JR-CSF Haplotypes'!$A$10:$K$36,4,FALSE) -> 76.1636 | F16: =VLOOKUP(C16,'JR-CSF Haplotypes'!$A$10:$K$36,5,FALSE) -> 3 | H16: 0 | I16: 0.98470995 | J16: 0 | K16: 0 | L16: 0 | M16: 0
B17: D279Y | C17: CD50-m066 | D17: =VLOOKUP(C17,'JR-CSF Haplotypes'!$A$10:$K$36,4,FALSE) -> 54.8498 | E17: =D17 -> 54.8498 | F17: =VLOOKUP(C17,'JR-CSF Haplotypes'!$A$10:$K$36,5,FALSE) -> 3 | H17: 0 | I17: 0 | J17: 0 | K17: 0 | L17: 0 | M17: 0.99717207

Sheet JR-CSF Haplotypes - NO CD50
D7: Geometric Mean Expression (ug/ml) | F7: Time to Escape (Weeks) | G7: REJO.c Pos | H7: 277
B8: Escape Path | C8: Sample ID | G8: HXB2 Pos | H8: 279
G9: WT AA | H9: D
G10: Mut AA | H10: A | I10: E | J10: H | K10: K | L10: N | M10: Y | O10: Mean Expression
B11: =VLOOKUP(C11,'JR-CSF Haplotypes'!$A$11:$C$36,3,FALSE) -> A: D279A | C11: CD21-m998 | D11: =VLOOKUP(C11,'JR-CSF Haplotypes'!$A$10:$K$36,4,FALSE) -> 182.155 | E11: =GEOMEAN(D11:D14) -> 111.67743 | F11: =VLOOKUP(C11,'JR-CSF Haplotypes'!$A$10:$K$36,5,FALSE) -> 2 | H11: 0.46604361 | I11: 0 | J11: 0 | K11: 0.10342679 | L11: 0.42554517 | M11: 0 | O11: =GEOMEAN(D11:D14) -> 111.67743 | Q11: =GEOMEAN(D11:D25) -> 107.06368
C12: CD21-m999 | D12: =VLOOKUP(C12,'JR-CSF Haplotypes'!$A$10:$K$36,4,FALSE) -> 204.0391 | F12: =VLOOKUP(C12,'JR-CSF Haplotypes'!$A$10:$K$36,5,FALSE) -> 2 | H12: 0.26298045 | I12: 0.25758597 | J12: 0 | K12: 0.13081591 | L12: 0.34052596 | M12: 0
C13: CD50-m069 | D13: =VLOOKUP(C13,'JR-CSF Haplotypes'!$A$10:$K$36,4,FALSE) -> 66.0624 | F13: =VLOOKUP(C13,'JR-CSF Haplotypes'!$A$10:$K$36,5,FALSE) -> 3 | H13: 0.9950481 | I13: 0 | J13: 0 | K13: 0 | L13: 0 | M13: 0
C14: CD50-m074 | D14: =VLOOKUP(C14,'JR-CSF Haplotypes'!$A$10:$K$36,4,FALSE) -> 63.3509 | F14: =VLOOKUP(C14,'JR-CSF Haplotypes'!$A$10:$K$36,5,FALSE) -> 3 | H14: 0.86808466 | I14: 0 | J14: 0.12426655 | K14: 0 | L14: 0 | M14: 0
B15: =VLOOKUP(C15,'JR-CSF Haplotypes'!$A$11:$C$36,3,FALSE) -> B: D279H | C15: CD21-m004 | D15: =VLOOKUP(C15,'JR-CSF Haplotypes'!$A$10:$K$36,4,FALSE) -> 106.9328 | E15: =GEOMEAN(D15:D18) -> 104.81097 | F15: =VLOOKUP(C15,'JR-CSF Haplotypes'!$A$10:$K$36,5,FALSE) -> 2 | H15: 0 | I15: 0 | J15: 0.54836163 | K15: 0.10209238 | L15: 0.34891433 | M15: 0 | O15: =GEOMEAN(D15:D18) -> 104.81097
C16: CD21-m006 | D16: =VLOOKUP(C16,'JR-CSF Haplotypes'!$A$10:$K$36,4,FALSE) -> 193.23 | F16: =VLOOKUP(C16,'JR-CSF Haplotypes'!$A$10:$K$36,5,FALSE) -> 2 | H16: 0 | I16: 0 | J16: 0.99202552 | K16: 0 | L16: 0 | M16: 0
C17: CD21-m007 | D17: =VLOOKUP(C17,'JR-CSF Haplotypes'!$A$10:$K$36,4,FALSE) -> 149.745 | F17: =VLOOKUP(C17,'JR-CSF Haplotypes'!$A$10:$K$36,5,FALSE) -> 2 | H17: 0 | I17: 0 | J17: 0.98687215 | K17: 0 | L17: 0 | M17: 0
C18: CD50-m068 | D18: =VLOOKUP(C18,'JR-CSF Haplotypes'!$A$10:$K$36,4,FALSE) -> 39.0022 | F18: =VLOOKUP(C18,'JR-CSF Haplotypes'!$A$10:$K$36,5,FALSE) -> 2 | H18: 0 | I18: 0 | J18: 1 | K18: 0 | L18: 0 | M18: 0
B19: =VLOOKUP(C19,'JR-CSF Haplotypes'!$A$11:$C$36,3,FALSE) -> C: D279N + Other | C19: CD21-m003 | D19: =VLOOKUP(C19,'JR-CSF Haplotypes'!$A$10:$K$36,4,FALSE) -> 159.5775 | E19: =GEOMEAN(D19:D21) -> 113.87425 | F19: =VLOOKUP(C19,'JR-CSF Haplotypes'!$A$10:$K$36,5,FALSE) -> 2 | H19: 0 | I19: 0 | J19: 0 | K19: 0 | L19: 0.9939985 | M19: 0
C20: CD21-m009 | D20: =VLOOKUP(C20,'JR-CSF Haplotypes'!$A$10:$K$36,4,FALSE) -> 189.24 | F20: =VLOOKUP(C20,'JR-CSF Haplotypes'!$A$10:$K$36,5,FALSE) -> 2 | H20: 0 | I20: 0 | J20: 0 | K20: 0 | L20: 0.99109063 | M20: 0
C21: CD50-m071 | D21: =VLOOKUP(C21,'JR-CSF Haplotypes'!$A$10:$K$36,4,FALSE) -> 48.8981 | F21: =VLOOKUP(C21,'JR-CSF Haplotypes'!$A$10:$K$36,5,FALSE) -> 2 | H21: 0 | I21: 0 | J21: 0 | K21: 0 | L21: 0.825 | M21: 0
B22: =VLOOKUP(C22,'JR-CSF Haplotypes'!$A$11:$C$36,3,FALSE) -> D: D279E + Other | C22: CD21-m002 | D22: =VLOOKUP(C22,'JR-CSF Haplotypes'!$A$10:$K$36,4,FALSE) -> 152.67 | E22: =GEOMEAN(D22:D24) -> 122.33875 | F22: =VLOOKUP(C22,'JR-CSF Haplotypes'!$A$10:$K$36,5,FALSE) -> 2 | H22: 0 | I22: 0.5207088 | J22: 0 | K22: 0.2882152 | L22: 0.16076003 | M22: 0
C23: CD21-m008 | D23: =VLOOKUP(C23,'JR-CSF Haplotypes'!$A$10:$K$36,4,FALSE) -> 157.4675 | F23: =VLOOKUP(C23,'JR-CSF Haplotypes'!$A$10:$K$36,5,FALSE) -> 2 | H23: 0 | I23: 0.49300323 | J23: 0 | K23: 0 | L23: 0 | M23: 0
C24: CD50-m073 | D24: =VLOOKUP(C24,'JR-CSF Haplotypes'!$A$10:$K$36,4,FALSE) -> 76.1636 | F24: =VLOOKUP(C24,'JR-CSF Haplotypes'!$A$10:$K$36,5,FALSE) -> 3 | H24: 0 | I24: 0.98470995 | J24: 0 | K24: 0 | L24: 0 | M24: 0
B25: D279Y | C25: CD50-m066 | D25: =VLOOKUP(C25,'JR-CSF Haplotypes'!$A$10:$K$36,4,FALSE) -> 54.8498 | E25: =D25 -> 54.8498 | F25: =VLOOKUP(C25,'JR-CSF Haplotypes'!$A$10:$K$36,5,FALSE) -> 3 | H25: 0 | I25: 0 | J25: 0 | K25: 0 | L25: 0 | M25: 0.99717207

Sheet JR-CSF Haplotypes Edited
D7: Geometric Mean Expression (ug/ml) | F7: Time to Escape (Weeks) | G7: REJO.c Pos | H7: 277
B8: Escape Path | C8: Sample ID | G8: HXB2 Pos | H8: 279
G9: WT AA | H9: D
G10: Mut AA | H10: A | I10: E | J10: H | K10: K | L10: N | M10: Y | O10: Mean Expression
B11: =VLOOKUP(C11,'JR-CSF Haplotypes'!$A$11:$C$36,3,FALSE) -> A: D279A | C11: CD21-m998 | D11: =VLOOKUP(C11,'JR-CSF Haplotypes'!$A$10:$K$36,4,FALSE) -> 182.155 | E11: =GEOMEAN(D11:D19) -> 196.07422 | F11: =VLOOKUP(C11,'JR-CSF Haplotypes'!$A$10:$K$36,5,FALSE) -> 2 | H11: 0.46604361 | I11: 0 | J11: 0 | K11: 0.10342679 | L11: 0.42554517 | M11: 0 | O11: =GEOMEAN(D11:D19) -> 196.07422 | Q11: =GEOMEAN(D11:D36) -> 172.06076
C12: CD21-m999 | D12: =VLOOKUP(C12,'JR-CSF Haplotypes'!$A$10:$K$36,4,FALSE) -> 204.0391 | F12: =VLOOKUP(C12,'JR-CSF Haplotypes'!$A$10:$K$36,5,FALSE) -> 2 | H12: 0.26298045 | I12: 0.25758597 | J12: 0 | K12: 0.13081591 | L12: 0.34052596 | M12: 0
C13: CD30-m193 | D13: =VLOOKUP(C13,'JR-CSF Haplotypes'!$A$10:$K$36,4,FALSE) -> 181.9843 | F13: =VLOOKUP(C13,'JR-CSF Haplotypes'!$A$10:$K$36,5,FALSE) -> 2 | H13: 0.99515613 | I13: 0 | J13: 0 | K13: 0 | L13: 0 | M13: 0
C14: CD30-m203 | D14: =VLOOKUP(C14,'JR-CSF Haplotypes'!$A$10:$K$36,4,FALSE) -> 253.7751 | F14: =VLOOKUP(C14,'JR-CSF Haplotypes'!$A$10:$K$36,5,FALSE) -> 4 | H14: 0.99348837 | I14: 0 | J14: 0 | K14: 0 | L14: 0 | M14: 0
C15: CD30-m204 | D15: =VLOOKUP(C15,'JR-CSF Haplotypes'!$A$10:$K$36,4,FALSE) -> 488.8859 | F15: =VLOOKUP(C15,'JR-CSF Haplotypes'!$A$10:$K$36,5,FALSE) -> 2 | H15: 0.74143986 | I15: 0.2542252 | J15: 0 | K15: 0 | L15: 0 | M15: 0
C16: CD30-m230 | D16: =VLOOKUP(C16,'JR-CSF Haplotypes'!$A$10:$K$36,4,FALSE) -> 307.7465 | F16: =VLOOKUP(C16,'JR-CSF Haplotypes'!$A$10:$K$36,5,FALSE) -> 2 | H16: 0.99336336 | I16: 0 | J16: 0 | K16: 0 | L16: 0 | M16: 0
C17: CD30-m231 | D17: =VLOOKUP(C17,'JR-CSF Haplotypes'!$A$10:$K$36,4,FALSE) -> 396.3138 | F17: =VLOOKUP(C17,'JR-CSF Haplotypes'!$A$10:$K$36,5,FALSE) -> 3 | H17: 0.99438269 | I17: 0 | J17: 0 | K17: 0 | L17: 0 | M17: 0
C18: CD50-m069 | D18: =VLOOKUP(C18,'JR-CSF Haplotypes'!$A$10:$K$36,4,FALSE) -> 66.0624 | F18: =VLOOKUP(C18,'JR-CSF Haplotypes'!$A$10:$K$36,5,FALSE) -> 3 | H18: 0.9950481 | I18: 0 | J18: 0 | K18: 0 | L18: 0 | M18: 0
C19: CD50-m074 | D19: =VLOOKUP(C19,'JR-CSF Haplotypes'!$A$10:$K$36,4,FALSE) -> 63.3509 | F19: =VLOOKUP(C19,'JR-CSF Haplotypes'!$A$10:$K$36,5,FALSE) -> 3 | H19: 0.86808466 | I19: 0 | J19: 0.12426655 | K19: 0 | L19: 0 | M19: 0
B20: =VLOOKUP(C20,'JR-CSF Haplotypes'!$A$11:$C$36,3,FALSE) -> B: D279H | C20: CD21-m004 | D20: =VLOOKUP(C20,'JR-CSF Haplotypes'!$A$10:$K$36,4,FALSE) -> 106.9328 | E20: =GEOMEAN(D20:D24) -> 133.21629 | F20: =VLOOKUP(C20,'JR-CSF Haplotypes'!$A$10:$K$36,5,FALSE) -> 2 | H20: 0 | I20: 0 | J20: 0.54836163 | K20: 0.10209238 | L20: 0.34891433 | M20: 0 | O20: =GEOMEAN(D20:D24) -> 133.21629
C21: CD21-m006 | D21: =VLOOKUP(C21,'JR-CSF Haplotypes'!$A$10:$K$36,4,FALSE) -> 193.23 | F21: =VLOOKUP(C21,'JR-CSF Haplotypes'!$A$10:$K$36,5,FALSE) -> 2 | H21: 0 | I21: 0 | J21: 0.99202552 | K21: 0 | L21: 0 | M21: 0
C22: CD21-m007 | D22: =VLOOKUP(C22,'JR-CSF Haplotypes'!$A$10:$K$36,4,FALSE) -> 149.745 | F22: =VLOOKUP(C22,'JR-CSF Haplotypes'!$A$10:$K$36,5,FALSE) -> 2 | H22: 0 | I22: 0 | J22: 0.98687215 | K22: 0 | L22: 0 | M22: 0
C23: CD30-m196 | D23: =VLOOKUP(C23,'JR-CSF Haplotypes'!$A$10:$K$36,4,FALSE) -> 347.664 | F23: =VLOOKUP(C23,'JR-CSF Haplotypes'!$A$10:$K$36,5,FALSE) -> 3 | H23: 0 | I23: 0.5385403 | J23: 0.45275706 | K23: 0 | L23: 0 | M23: 0
C24: CD50-m068 | D24: =VLOOKUP(C24,'JR-CSF Haplotypes'!$A$10:$K$36,4,FALSE) -> 39.0022 | F24: =VLOOKUP(C24,'JR-CSF Haplotypes'!$A$10:$K$36,5,FALSE) -> 2 | H24: 0 | I24: 0 | J24: 1 | K24: 0 | L24: 0 | M24: 0
B25: =VLOOKUP(C25,'JR-CSF Haplotypes'!$A$11:$C$36,3,FALSE) -> C: D279N + Other | C25: CD21-m003 | D25: =VLOOKUP(C25,'JR-CSF Haplotypes'!$A$10:$K$36,4,FALSE) -> 159.5775 | E25: =GEOMEAN(D25:D28) -> 150.52026 | F25: =VLOOKUP(C25,'JR-CSF Haplotypes'!$A$10:$K$36,5,FALSE) -> 2 | H25: 0 | I25: 0 | J25: 0 | K25: 0 | L25: 0.9939985 | M25: 0
C26: CD21-m009 | D26: =VLOOKUP(C26,'JR-CSF Haplotypes'!$A$10:$K$36,4,FALSE) -> 189.24 | F26: =VLOOKUP(C26,'JR-CSF Haplotypes'!$A$10:$K$36,5,FALSE) -> 2 | H26: 0 | I26: 0 | J26: 0 | K26: 0 | L26: 0.99109063 | M26: 0
C27: CD30-m197 | D27: =VLOOKUP(C27,'JR-CSF Haplotypes'!$A$10:$K$36,4,FALSE) -> 347.6188 | F27: =VLOOKUP(C27,'JR-CSF Haplotypes'!$A$10:$K$36,5,FALSE) -> 3 | H27: 0 | I27: 0 | J27: 0 | K27: 0 | L27: 0.98931516 | M27: 0
C28: CD50-m071 | D28: =VLOOKUP(C28,'JR-CSF Haplotypes'!$A$10:$K$36,4,FALSE) -> 48.8981 | F28: =VLOOKUP(C28,'JR-CSF Haplotypes'!$A$10:$K$36,5,FALSE) -> 2 | H28: 0 | I28: 0 | J28: 0 | K28: 0 | L28: 0.825 | M28: 0
B29: =VLOOKUP(C29,'JR-CSF Haplotypes'!$A$11:$C$36,3,FALSE) -> D: D279E + Other | C29: CD21-m002 | D29: =VLOOKUP(C29,'JR-CSF Haplotypes'!$A$10:$K$36,4,FALSE) -> 152.67 | E29: =GEOMEAN(D29:D31) -> 122.33875 | F29: =VLOOKUP(C29,'JR-CSF Haplotypes'!$A$10:$K$36,5,FALSE) -> 2 | H29: 0 | I29: 0.5207088 | J29: 0 | K29: 0.2882152 | L29: 0.16076003 | M29: 0
C30: CD21-m008 | D30: =VLOOKUP(C30,'JR-CSF Haplotypes'!$A$10:$K$36,4,FALSE) -> 157.4675 | F30: =VLOOKUP(C30,'JR-CSF Haplotypes'!$A$10:$K$36,5,FALSE) -> 2 | H30: 0 | I30: 0.49300323 | J30: 0 | K30: 0 | L30: 0 | M30: 0
C31: CD50-m073 | D31: =VLOOKUP(C31,'JR-CSF Haplotypes'!$A$10:$K$36,4,FALSE) -> 76.1636 | F31: =VLOOKUP(C31,'JR-CSF Haplotypes'!$A$10:$K$36,5,FALSE) -> 3 | H31: 0 | I31: 0.98470995 | J31: 0 | K31: 0 | L31: 0 | M31: 0
B32: =VLOOKUP(C32,'JR-CSF Haplotypes'!$A$11:$C$36,3,FALSE) -> E: D279K | C32: CD30-m207 | D32: =VLOOKUP(C32,'JR-CSF Haplotypes'!$A$10:$K$36,4,FALSE) -> 520.0582 | E32: =D32 -> 520.0582 | F32: =VLOOKUP(C32,'JR-CSF Haplotypes'!$A$10:$K$36,5,FALSE) -> 3 | H32: 0 | I32: 0 | J32: 0 | K32: 0.99758363 | L32: 0 | M32: 0
B33: =VLOOKUP(C33,'JR-CSF Haplotypes'!$A$11:$C$36,3,FALSE) -> F: D279Y | C33: CD30-m195 | D33: =VLOOKUP(C33,'JR-CSF Haplotypes'!$A$10:$K$36,4,FALSE) -> 235.2142 | E33: =GEOMEAN(D33:D35) -> 172.50025 | F33: =VLOOKUP(C33,'JR-CSF Haplotypes'!$A$10:$K$36,5,FALSE) -> 2 | H33: 0 | I33: 0 | J33: 0 | K33: 0 | L33: 0 | M33: 0.99007092
C34: CD30-m229 | D34: =VLOOKUP(C34,'JR-CSF Haplotypes'!$A$10:$K$36,4,FALSE) -> 397.8603 | F34: =VLOOKUP(C34,'JR-CSF Haplotypes'!$A$10:$K$36,5,FALSE) -> 3 | H34: 0 | I34: 0 | J34: 0 | K34: 0 | L34: 0 | M34: 0.9354905
C35: CD50-m066 | D35: =VLOOKUP(C35,'JR-CSF Haplotypes'!$A$10:$K$36,4,FALSE) -> 54.8498 | F35: =VLOOKUP(C35,'JR-CSF Haplotypes'!$A$10:$K$36,5,FALSE) -> 3 | H35: 0 | I35: 0 | J35: 0 | K35: 0 | L35: 0 | M35: 0.99717207
B36: =VLOOKUP(C36,'JR-CSF Haplotypes'!$A$11:$C$36,3,FALSE) -> Other | C36: CD30-m205 | D36: =VLOOKUP(C36,'JR-CSF Haplotypes'!$A$10:$K$36,4,FALSE) -> 297.6211 | E36: =D36 -> 297.6211 | F36: =VLOOKUP(C36,'JR-CSF Haplotypes'!$A$10:$K$36,5,FALSE) -> 3 | H36: 0 | I36: 0 | J36: 0 | K36: 0 | L36: 0 | M36: 0

Sheet JR-CSF Haplotypes
K7: aa_pos | L7: 2 | M7: 15 | N7: 16 | O7: 23 | P7: 30 | Q7: 31 | R7: 37 | S7: 41 | T7: 91 | U7: 94 | V7: 104 | W7: 109 | X7: 112 | Y7: 127 | Z7: 129 | AA7: 144 | AB7: 157 | AC7: 158 | AD7: 159 | AE7: 160 | AF7: 160 | AG7: 161 | AH7: 162 | AI7: 162 | AJ7: 163 | AK7: 164 | AL7: 164 | AM7: 169 | AN7: 174 | AO7: 174 | AP7: 176 | AQ7: 176 | AR7: 178 | AS7: 184 | AT7: 188 | AU7: 188 | AV7: 190 | AW7: 199 | AX7: 201 | AY7: 206 | AZ7: 228 | BA7: 253 | BB7: 264 | BC7: 273 | BD7: 274 | BE7: 276 | BF7: 277 | BG7: 277 | BH7: 277 | BI7: 277 | BJ7: 277 | BK7: 277 | BL7: 278 | BM7: 279 | BN7: 295 | BO7: 298 | BP7: 303 | BQ7: 304 | BR7: 307 | BS7: 307 | BT7: 313 | BU7: 313 | BV7: 315 | BW7: 315 | BX7: 332 | BY7: 336 | BZ7: 336 | CA7: 336 | CB7: 336 | CC7: 336 | CD7: 338 | CE7: 341 | CF7: 342 | CG7: 351 | CH7: 361 | CI7: 367 | CJ7: 382 | CK7: 384 | CL7: 388 | CM7: 390 | CN7: 395 | CO7: 399 | CP7: 399 | CQ7: 402 | CR7: 403 | CS7: 403 | CT7: 405 | CU7: 420 | CV7: 421 | CW7: 421 | CX7: 426 | CY7: 428 | CZ7: 450 | DA7: 451 | DB7: 453 | DC7: 455 | DD7: 455 | DE7: 466 | DF7: 486 | DG7: 526 | DH7: 531 | DI7: 540 | DJ7: 547 | DK7: 575 | DL7: 585 | DM7: 604 | DN7: 660 | DO7: 675 | DP7: 679 | DQ7: 688 | DR7: 691 | DS7: 693 | DT7: 715 | DU7: 718 | DV7: 728 | DW7: 738 | DX7: 750 | DY7: 762 | DZ7: 771 | EA7: 779 | EB7: 779 | EC7: 780 | ED7: 783 | EE7: 783 | EF7: 783 | EG7: 784 | EH7: 784 | EI7: 788 | EJ7: 793 | EK7: 809 | EL7: 814 | EM7: 824
K8: HXB2_pos | L8: 2 | M8: 12 | N8: 17 | O8: 24 | P8: 31 | Q8: 32 | R8: 38 | S8: 42 | T8: 92 | U8: 95 | V8: 105 | W8: 110 | X8: 113 | Y8: 128 | Z8: 130 | AA8: 146 | AB8: 160 | AC8: 161 | AD8: 162 | AE8: 163 | AF8: 163 | AG8: 164 | AH8: 165 | AI8: 165 | AJ8: 166 | AK8: 167 | AL8: 167 | AM8: 172 | AN8: 177 | AO8: 177 | AP8: 179 | AQ8: 179 | AR8: 181 | AS8: 187 | AT8: 190 | AU8: 190 | AV8: 192 | AW8: 201 | AX8: 203 | AY8: 208 | AZ8: 230 | BA8: 255 | BB8: 266 | BC8: 275 | BD8: 276 | BE8: 278 | BF8: 279 | BG8: 279 | BH8: 279 | BI8: 279 | BJ8: 279 | BK8: 279 | BL8: 280 | BM8: 281 | BN8: 297 | BO8: 300 | BP8: 305 | BQ8: 306 | BR8: 309 | BS8: 309 | BT8: 317 | BU8: 317 | BV8: 319 | BW8: 319 | BX8: 335 | BY8: 339 | BZ8: 339 | CA8: 339 | CB8: 339 | CC8: 339 | CD8: 341 | CE8: 344 | CF8: 345 | CG8: 355 | CH8: 365 | CI8: 371 | CJ8: 386 | CK8: 388 | CL8: 392 | CM8: 394 | CN8: 403 | CO8: 407 | CP8: 407 | CQ8: 410 | CR8: 411 | CS8: 411 | CT8: 413 | CU8: 428 | CV8: 429 | CW8: 429 | CX8: 434 | CY8: 436 | CZ8: 458 | DA8: 459 | DB8: 461 | DC8: 463 | DD8: 463 | DE8: 474 | DF8: 494 | DG8: 534 | DH8: 539 | DI8: 548 | DJ8: 555 | DK8: 583 | DL8: 593 | DM8: 612 | DN8: 668 | DO8: 683 | DP8: 687 | DQ8: 696 | DR8: 699 | DS8: 701 | DT8: 723 | DU8: 726 | DV8: 736 | DW8: 746 | DX8: 758 | DY8: 770 | DZ8: 779 | EA8: 787 | EB8: 787 | EC8: 788 | ED8: 791 | EE8: 791 | EF8: 791 | EG8: 792 | EH8: 792 | EI8: 796 | EJ8: 801 | EK8: 817 | EL8: 822 | EM8: 832
K9: JRCSF_aa | L9: R | M9: K | N9: G | O9: T | P9: V | Q9: E | R9: V | S9: V | T9: D | U9: M | V9: Q | W9: N | X9: D | Y9: T | Z9: N | AA9: G | AB9: N | AC9: I | AD9: T | AE9: K | AF9: K | AG9: S | AH9: I | AI9: I | AJ9: R | AK9: D | AL9: D | AM9: E | AN9: Y | AO9: Y | AP9: L | AQ9: L | AR9: V | AS9: K | AT9: K | AU9: K | AV9: R | AW9: I | AX9: Q | AY9: V | AZ9: N | BA9: V | BB9: A | BC9: D | BD9: N | BE9: T | BF9: D | BG9: D | BH9: D | BI9: D | BJ9: D | BK9: D | BL9: N | BM9: A | BN9: T | BO9: S | BP9: K | BQ9: S | BR9: I | BS9: I | BT9: F | BU9: F | BV9: T | BW9: T | BX9: R | BY9: N | BZ9: N | CA9: N | CB9: N | CC9: N | CD9: T | CE9: Q | CF9: I | CG9: N | CH9: S | CI9: I | CJ9: N | CK9: T | CL9: N | CM9: T | CN9: E | CO9: G | CP9: G | CQ9: G | CR9: N | CS9: N | CT9: T | CU9: Q | CV9: E | CW9: E | CX9: M | CY9: A | CZ9: G | DA9: G | DB9: N | DC9: S | DD9: S | DE9: D | DF9: L | DG9: S | DH9: V | DI9: I | DJ9: L | DK9: V | DL9: M | DM9: T | DN9: S | DO9: K | DP9: M | DQ9: R | DR9: F | DS9: V | DT9: A | DU9: G | DV9: E | DW9: G | DX9: V | DY9: R | DZ9: T | EA9: R | EB9: R | EC9: R | ED9: E | EE9: E | EF9: E | EG9: I | EH9: I | EI9: W | EJ9: Q | EK9: A | EL9: V | EM9: V
A10: Samples | B10: Escape Path ID | C10: Escape Path | D10: Geometric Mean Expression (mg/ml) | E10: Time to Escape (Weeks) | F10: Time of Sequencing | G10: Time After Escape | H10: Number of Mutations (>.1) | I10: Number of Mutations (>.5) | J10: Number of Mutations (>.9) | K10: aa_alt | L10: K | M10: T | N10: R | O10: I | P10: I | Q10: D | R10: I | S10: I | T10: N | U10: I | V10: H | W10: S | X10: N | Y10: A | Z10: D | AA10: E | AB10: DEL | AC10: DEL | AD10: DEL | AE10: N | AF10: DEL | AG10: DEL | AH10: R | AI10: T | AJ10: K | AK10: S | AL10: N | AM10: K | AN10: H | AO10: D | AP10: M | AQ10: R | AR10: I | AS10: E | AT10: N | AU10: E | AV10: K | AW10: V | AX10: H | AY10: I | AZ10: D | BA10: I | BB10: T | BC10: N | BD10: D | BE10: M | BF10: A | BG10: E | BH10: H | BI10: K | BJ10: N | BK10: Y | BL10: D | BM10: T | BN10: I | BO10: N | BP10: R | BQ10: G | BR10: L | BS10: M | BT10: L | BU10: I | BV10: DEL | BW10: P | BX10: K | BY10: T | BZ10: D | CA10: H | CB10: K | CC10: S | CD10: A | CE10: K | CF10: T | CG10: D | CH10: P | CI10: V | CJ10: D | CK10: A | CL10: S | CM10: A | CN10: K | CO10: S | CP10: D | CQ10: E | CR10: D | CS10: S | CT10: I | CU10: W | CV10: G | CW10: K | CX10: R | CY10: N | CZ10: D | DA10: D | DB10: D | DC10: N | DD10: R | DE10: N | DF10: I | DG10: A | DH10: A | DI10: V | DJ10: M | DK10: M | DL10: L | DM10: S | DN10: N | DO10: R | DP10: I | DQ10: K | DR10: L | DS10: I | DT10: T | DU10: E | DV10: G | DW10: R | DX10: I | DY10: H | DZ10: K | EA10: H | EB10: S | EC10: W | ED10: D | EE10: G | EF10: R | EG10: S | EH10: V | EI10: G | EJ10: R | EK10: T | EL10: I | EM10: I
A11: CD21-m998 | B11: A | C11: A: D279A | D11: =VLOOKUP(A11,Expression!$C$1:$D$462,2,FALSE) -> 182.155 | E11: =VLOOKUP(A11,'JRCSF Survival Analysis'!$A$1:$B$50,2,FALSE) -> 2 | F11: =VLOOKUP(A11,'sequencing metadata'!$A$1:$B$100,2,FALSE) -> 24 | G11: =F11-E11 -> 22 | H11: =COUNTIF(L11:EM11,">0.1") -> 20 | I11: =COUNTIF(L11:EM11,">0.5") -> 4 | J11: =COUNTIF(L11:EM11,">0.9") -> 1 | K11: CD21-m998 | L11: 0 | M11: 0 | N11: 0.16591928 | O11: 0 | P11: 0 | Q11: 0 | R11: 0 | S11: 0 | T11: 0 | U11: 0 | V11: 0 | W11: 0 | X11: 0 | Y11: 0 | Z11: 0 | AA11: 0 | AB11: 0.43267108 | AC11: 0.4541387 | AD11: 0.43721973 | AE11: 0 | AF11: 0 | AG11: 0 | AH11: 0 | AI11: 0 | AJ11: 0 | AK11: 0 | AL11: 0.50929368 | AM11: 0 | AN11: 0 | AO11: 0 | AP11: 0 | AQ11: 0.34347048 | AR11: 0 | AS11: 0 | AT11: 0 | AU11: 0 | AV11: 0 | AW11: 0 | AX11: 0.37943925 | AY11: 0 | AZ11: 0 | BA11: 0 | BB11: 0 | BC11: 0 | BD11: 0 | BE11: 0 | BF11: 0.46604361 | BG11: 0 | BH11: 0 | BI11: 0.10342679 | BJ11: 0.42554517 | BK11: 0 | BL11: 0 | BM11: 0 | BN11: 0 | BO11: 0 | BP11: 0 | BQ11: 0.1108631 | BR11: 0 | BS11: 0 | BT11: 0.12539185 | BU11: 0 | BV11: 0 | BW11: 0 | BX11: 0 | BY11: 0 | BZ11: 0 | CA11: 0 | CB11: 0 | CC11: 0.33381503 | CD11: 0 | CE11: 0 | CF11: 0 | CG11: 0 | CH11: 0 | CI11: 0 | CJ11: 0 | CK11: 0.46781116 | CL11: 0 | CM11: 0 | CN11: 0 | CO11: 0 | CP11: 0 | CQ11: 0 | CR11: 0.99651871 | CS11: 0 | CT11: 0 | CU11: 0 | CV11: 0 | CW11: 0 | CX11: 0.18217434 | CY11: 0 | CZ11: 0.16856781 | DA11: 0.62770013 | DB11: 0 | DC11: 0 | DD11: 0 | DE11: 0.19754768 | DF11: 0 | DG11: 0 | DH11: 0 | DI11: 0 | DJ11: 0 | DK11: 0 | DL11: 0.72977625 | DM11: 0 | DN11: 0 | DO11: 0 | DP11: 0 | DQ11: 0 | DR11: 0 | DS11: 0 | DT11: 0 | DU11: 0 | DV11: 0 | DW11: 0 | DX11: 0 | DY11: 0 | DZ11: 0 | EA11: 0 | EB11: 0 | EC11: 0 | ED11: 0 | EE11: 0 | EF11: 0 | EG11: 0 | EH11: 0 | EI11: 0 | EJ11: 0 | EK11: 0 | EL11: 0 | EM11: 0
A12: CD21-m999 | B12: A | C12: A: D279A | D12: =VLOOKUP(A12,Expression!$C$1:$D$462,2,FALSE) -> 204.0391 | E12: =VLOOKUP(A12,'JRCSF Survival Analysis'!$A$1:$B$50,2,FALSE) -> 2 | F12: =VLOOKUP(A12,'sequencing metadata'!$A$1:$B$100,2,FALSE) -> 24 | G12: =F12-E12 -> 22 | H12: =COUNTIF(L12:EM12,">0.1") -> 23 | I12: =COUNTIF(L12:EM12,">0.5") -> 1 | J12: =COUNTIF(L12:EM12,">0.9") -> 0 | K12: CD21-m999 | L12: 0.29861111 | M12: 0 | N12: 0 | O12: 0 | P12: 0 | Q12: 0 | R12: 0 | S12: 0 | T12: 0 | U12: 0 | V12: 0 | W12: 0 | X12: 0.21596244 | Y12: 0 | Z12: 0 | AA12: 0.42585034 | AB12: 0.26067747 | AC12: 0.26106195 | AD12: 0.25991189 | AE12: 0 | AF12: 0 | AG12: 0 | AH12: 0 | AI12: 0 | AJ12: 0 | AK12: 0 | AL12: 0 | AM12: 0 | AN12: 0 | AO12: 0 | AP12: 0 | AQ12: 0 | AR12: 0 | AS12: 0 | AT12: 0 | AU12: 0 | AV12: 0.34412955 | AW12: 0 | AX12: 0.27858439 | AY12: 0 | AZ12: 0 | BA12: 0 | BB12: 0 | BC12: 0 | BD12: 0 | BE12: 0 | BF12: 0.26298045 | BG12: 0.25758597 | BH12: 0 | BI12: 0.13081591 | BJ12: 0.34052596 | BK12: 0 | BL12: 0 | BM12: 0 | BN12: 0 | BO12: 0.24557522 | BP12: 0 | BQ12: 0 | BR12: 0 | BS12: 0 | BT12: 0.25688757 | BU12: 0 | BV12: 0 | BW12: 0 | BX12: 0.28733333 | BY12: 0 | BZ12: 0 | CA12: 0 | CB12: 0 | CC12: 0.25361367 | CD12: 0.38921283 | CE12: 0 | CF12: 0 | CG12: 0 | CH12: 0 | CI12: 0 | CJ12: 0 | CK12: 0 | CL12: 0 | CM12: 0 | CN12: 0 | CO12: 0 | CP12: 0.12604404 | CQ12: 0.42626011 | CR12: 0 | CS12: 0.10318949 | CT12: 0 | CU12: 0 | CV12: 0 | CW12: 0 | CX12: 0 | CY12: 0 | CZ12: 0 | DA12: 0.86363636 | DB12: 0 | DC12: 0.10237203 | DD12: 0.19975031 | DE12: 0 | DF12: 0 | DG12: 0 | DH12: 0 | DI12: 0 | DJ12: 0 | DK12: 0 | DL12: 0 | DM12: 0 | DN12: 0 | DO12: 0 | DP12: 0 | DQ12: 0 | DR12: 0 | DS12: 0 | DT12: 0 | DU12: 0 | DV12: 0 | DW12: 0 | DX12: 0 | DY12: 0 | DZ12: 0 | EA12: 0 | EB12: 0 | EC12: 0 | ED12: 0 | EE12: 0 | EF12: 0 | EG12: 0 | EH12: 0 | EI12: 0 | EJ12: 0 | EK12: 0 | EL12: 0 | EM12: 0
A13: CD30-m193 | B13: A | C13: A: D279A | D13: =VLOOKUP(A13,Expression!$C$1:$D$462,2,FALSE) -> 181.9843 | E13: =VLOOKUP(A13,'JRCSF Survival Analysis'!$A$1:$B$50,2,FALSE) -> 2 | F13: =VLOOKUP(A13,'sequencing metadata'!$A$1:$B$100,2,FALSE) -> 20 | G13: =F13-E13 -> 18 | H13: =COUNTIF(L13:EM13,">0.1") -> 16 | I13: =COUNTIF(L13:EM13,">0.5") -> 5 | J13: =COUNTIF(L13:EM13,">0.9") -> 1 | K13: CD30-m193 | L13: 0 | M13: 0 | N13: 0 | O13: 0 | P13: 0 | Q13: 0 | R13: 0 | S13: 0 | T13: 0 | U13: 0 | V13: 0.27305695 | W13: 0.70399786 | X13: 0 | Y13: 0 | Z13: 0 | AA13: 0.27309516 | AB13: 0 | AC13: 0 | AD13: 0 | AE13: 0 | AF13: 0 | AG13: 0 | AH13: 0 | AI13: 0 | AJ13: 0.27307692 | AK13: 0 | AL13: 0 | AM13: 0 | AN13: 0 | AO13: 0 | AP13: 0 | AQ13: 0 | AR13: 0 | AS13: 0 | AT13: 0 | AU13: 0 | AV13: 0 | AW13: 0 | AX13: 0 | AY13: 0 | AZ13: 0 | BA13: 0 | BB13: 0 | BC13: 0 | BD13: 0 | BE13: 0.36456632 | BF13: 0.99515613 | BG13: 0 | BH13: 0 | BI13: 0 | BJ13: 0 | BK13: 0 | BL13: 0 | BM13: 0 | BN13: 0 | BO13: 0 | BP13: 0.37866467 | BQ13: 0 | BR13: 0 | BS13: 0 | BT13: 0 | BU13: 0 | BV13: 0 | BW13: 0 | BX13: 0 | BY13: 0 | BZ13: 0.34625191 | CA13: 0 | CB13: 0 | CC13: 0 | CD13: 0.75730714 | CE13: 0 | CF13: 0.39909752 | CG13: 0 | CH13: 0 | CI13: 0 | CJ13: 0.34294252 | CK13: 0 | CL13: 0 | CM13: 0 | CN13: 0 | CO13: 0 | CP13: 0 | CQ13: 0 | CR13: 0.64864444 | CS13: 0 | CT13: 0 | CU13: 0 | CV13: 0 | CW13: 0 | CX13: 0 | CY13: 0 | CZ13: 0 | DA13: 0 | DB13: 0 | DC13: 0 | DD13: 0 | DE13: 0 | DF13: 0 | DG13: 0 | DH13: 0.34576023 | DI13: 0 | DJ13: 0 | DK13: 0 | DL13: 0 | DM13: 0 | DN13: 0.29429089 | DO13: 0 | DP13: 0 | DQ13: 0 | DR13: 0 | DS13: 0 | DT13: 0 | DU13: 0 | DV13: 0 | DW13: 0 | DX13: 0 | DY13: 0 | DZ13: 0 | EA13: 0.69622751 | EB13: 0 | EC13: 0 | ED13: 0 | EE13: 0.29468372 | EF13: 0 | EG13: 0 | EH13: 0 | EI13: 0 | EJ13: 0 | EK13: 0 | EL13: 0 | EM13: 0
A14: CD30-m203 | B14: A | C14: A: D279A | D14: =VLOOKUP(A14,Expression!$C$1:$D$462,2,FALSE) -> 253.7751 | E14: =VLOOKUP(A14,'JRCSF Survival Analysis'!$A$1:$B$50,2,FALSE) -> 4 | F14: =VLOOKUP(A14,'sequencing metadata'!$A$1:$B$100,2,FALSE) -> 20 | G14: =F14-E14 -> 16 | H14: =COUNTIF(L14:EM14,">0.1") -> 13 | I14: =COUNTIF(L14:EM14,">0.5") -> 6 | J14: =COUNTIF(L14:EM14,">0.9") -> 4 | K14: CD30-m203 | L14: 0 | M14: 0 | N14: 0 | O14: 0 | P14: 0.311229 | Q14: 0 | R14: 0.99593165 | S14: 0 | T14: 0 | U14: 0 | V14: 0 | W14: 0 | X14: 0 | Y14: 0 | Z14: 0 | AA14: 0 | AB14: 0 | AC14: 0 | AD14: 0 | AE14: 0 | AF14: 0 | AG14: 0 | AH14: 0 | AI14: 0 | AJ14: 0 | AK14: 0 | AL14: 0.98721228 | AM14: 0 | AN14: 0 | AO14: 0 | AP14: 0 | AQ14: 0 | AR14: 0 | AS14: 0 | AT14: 0 | AU14: 0 | AV14: 0 | AW14: 0 | AX14: 0 | AY14: 0 | AZ14: 0 | BA14: 0 | BB14: 0 | BC14: 0.4435411 | BD14: 0 | BE14: 0 | BF14: 0.99348837 | BG14: 0 | BH14: 0 | BI14: 0 | BJ14: 0 | BK14: 0 | BL14: 0 | BM14: 0 | BN14: 0 | BO14: 0 | BP14: 0 | BQ14: 0 | BR14: 0 | BS14: 0 | BT14: 0.4241206 | BU14: 0 | BV14: 0 | BW14: 0 | BX14: 0 | BY14: 0.41046832 | BZ14: 0 | CA14: 0 | CB14: 0 | CC14: 0 | CD14: 0 | CE14: 0 | CF14: 0 | CG14: 0 | CH14: 0 | CI14: 0 | CJ14: 0.53558052 | CK14: 0 | CL14: 0 | CM14: 0 | CN14: 0 | CO14: 0 | CP14: 0 | CQ14: 0 | CR14: 0.99270073 | CS14: 0 | CT14: 0 | CU14: 0 | CV14: 0 | CW14: 0 | CX14: 0 | CY14: 0 | CZ14: 0 | DA14: 0 | DB14: 0 | DC14: 0 | DD14: 0 | DE14: 0 | DF14: 0 | DG14: 0.39457014 | DH14: 0 | DI14: 0 | DJ14: 0 | DK14: 0 | DL14: 0 | DM14: 0 | DN14: 0 | DO14: 0.43195541 | DP14: 0 | DQ14: 0 | DR14: 0 | DS14: 0 | DT14: 0.68370987 | DU14: 0 | DV14: 0 | DW14: 0 | DX14: 0 | DY14: 0 | DZ14: 0 | EA14: 0 | EB14: 0 | EC14: 0 | ED14: 0 | EE14: 0 | EF14: 0 | EG14: 0 | EH14: 0 | EI14: 0 | EJ14: 0.33420708 | EK14: 0 | EL14: 0 | EM14: 0
A15: CD30-m204 | B15: A | C15: A: D279A | D15: =VLOOKUP(A15,Expression!$C$1:$D$462,2,FALSE) -> 488.8859 | E15: =VLOOKUP(A15,'JRCSF Survival Analysis'!$A$1:$B$50,2,FALSE) -> 2 | F15: =VLOOKUP(A15,'sequencing metadata'!$A$1:$B$100,2,FALSE) -> 20 | G15: =F15-E15 -> 18 | H15: =COUNTIF(L15:EM15,">0.1") -> 13 | I15: =COUNTIF(L15:EM15,">0.5") -> 9 | J15: =COUNTIF(L15:EM15,">0.9") -> 5 | K15: CD30-m204 | L15: 0 | M15: 0 | N15: 0 | O15: 0 | P15: 0 | Q15: 0 | R15: 0 | S15: 0 | T15: 0 | U15: 0 | V15: 0 | W15: 0 | X15: 0 | Y15: 0 | Z15: 0 | AA15: 0 | AB15: 0 | AC15: 0 | AD15: 0 | AE15: 0 | AF15: 0 | AG15: 0 | AH15: 0 | AI15: 0 | AJ15: 0 | AK15: 0 | AL15: 0.99236512 | AM15: 0 | AN15: 0 | AO15: 0 | AP15: 0 | AQ15: 0 | AR15: 0 | AS15: 0 | AT15: 0 | AU15: 0 | AV15: 0 | AW15: 0 | AX15: 0 | AY15: 0 | AZ15: 0 | BA15: 0 | BB15: 0 | BC15: 0 | BD15: 0.24838001 | BE15: 0 | BF15: 0.74143986 | BG15: 0.2542252 | BH15: 0 | BI15: 0 | BJ15: 0 | BK15: 0 | BL15: 0 | BM15: 0 | BN15: 0 | BO15: 0 | BP15: 0 | BQ15: 0 | BR15: 0 | BS15: 0 | BT15: 0 | BU15: 0 | BV15: 0 | BW15: 0 | BX15: 0 | BY15: 0 | BZ15: 0 | CA15: 0 | CB15: 0 | CC15: 0.92842942 | CD15: 0 | CE15: 0 | CF15: 0 | CG15: 0 | CH15: 0 | CI15: 0 | CJ15: 0.20362938 | CK15: 0 | CL15: 0 | CM15: 0 | CN15: 0 | CO15: 0 | CP15: 0 | CQ15: 0 | CR15: 0.83362438 | CS15: 0 | CT15: 0 | CU15: 0 | CV15: 0 | CW15: 0 | CX15: 0 | CY15: 0 | CZ15: 0 | DA15: 0 | DB15: 0 | DC15: 0 | DD15: 0 | DE15: 0 | DF15: 0 | DG15: 0 | DH15: 0 | DI15: 0 | DJ15: 0 | DK15: 0 | DL15: 0.12110175 | DM15: 0.81134554 | DN15: 0 | DO15: 0 | DP15: 0 | DQ15: 0 | DR15: 0.89278957 | DS15: 0.90131781 | DT15: 0 | DU15: 0 | DV15: 0 | DW15: 0 | DX15: 0 | DY15: 0 | DZ15: 0 | EA15: 0 | EB15: 0.90395007 | EC15: 0 | ED15: 0 | EE15: 0 | EF15: 0 | EG15: 0 | EH15: 0 | EI15: 0 | EJ15: 0 | EK15: 0 | EL15: 0.90238704 | EM15: 0
A16: CD30-m230 | B16: A | C16: A: D279A | D16: =VLOOKUP(A16,Expression!$C$1:$D$462,2,FALSE) -> 307.7465 | E16: =VLOOKUP(A16,'JRCSF Survival Analysis'!$A$1:$B$50,2,FALSE) -> 2 | F16: =VLOOKUP(A16,'sequencing metadata'!$A$1:$B$100,2,FALSE) -> 16 | G16: =F16-E16 -> 14 | H16: =COUNTIF(L16:EM16,">0.1") -> 7 | I16: =COUNTIF(L16:EM16,">0.5") -> 6 | J16: =COUNTIF(L16:EM16,">0.9") -> 2 | K16: CD30-m230 | L16: 0 | M16: 0 | N16: 0 | O16: 0 | P16: 0 | Q16: 0 | R16: 0 | S16: 0 | T16: 0 | U16: 0 | V16: 0 | W16: 0 | X16: 0 | Y16: 0 | Z16: 0 | AA16: 0 | AB16: 0 | AC16: 0 | AD16: 0 | AE16: 0 | AF16: 0 | AG16: 0 | AH16: 0 | AI16: 0 | AJ16: 0 | AK16: 0 | AL16: 0.80623159 | AM16: 0 | AN16: 0 | AO16: 0 | AP16: 0 | AQ16: 0 | AR16: 0 | AS16: 0 | AT16: 0 | AU16: 0 | AV16: 0 | AW16: 0 | AX16: 0 | AY16: 0 | AZ16: 0 | BA16: 0 | BB16: 0 | BC16: 0 | BD16: 0 | BE16: 0 | BF16: 0.99336336 | BG16: 0 | BH16: 0 | BI16: 0 | BJ16: 0 | BK16: 0 | BL16: 0 | BM16: 0 | BN16: 0.15973003 | BO16: 0 | BP16: 0 | BQ16: 0 | BR16: 0 | BS16: 0 | BT16: 0 | BU16: 0 | BV16: 0 | BW16: 0 | BX16: 0 | BY16: 0 | BZ16: 0.99210143 | CA16: 0 | CB16: 0 | CC16: 0 | CD16: 0 | CE16: 0 | CF16: 0 | CG16: 0 | CH16: 0 | CI16: 0 | CJ16: 0.84185865 | CK16: 0 | CL16: 0 | CM16: 0 | CN16: 0 | CO16: 0 | CP16: 0 | CQ16: 0 | CR16: 0 | CS16: 0 | CT16: 0 | CU16: 0 | CV16: 0 | CW16: 0 | CX16: 0 | CY16: 0 | CZ16: 0 | DA16: 0 | DB16: 0 | DC16: 0 | DD16: 0 | DE16: 0 | DF16: 0 | DG16: 0 | DH16: 0 | DI16: 0 | DJ16: 0 | DK16: 0 | DL16: 0 | DM16: 0 | DN16: 0 | DO16: 0 | DP16: 0 | DQ16: 0 | DR16: 0 | DS16: 0 | DT16: 0 | DU16: 0 | DV16: 0 | DW16: 0 | DX16: 0 | DY16: 0 | DZ16: 0.81366191 | EA16: 0.83684146 | EB16: 0 | EC16: 0 | ED16: 0 | EE16: 0 | EF16: 0 | EG16: 0 | EH16: 0 | EI16: 0 | EJ16: 0 | EK16: 0 | EL16: 0 | EM16: 0
A17: CD30-m231 | B17: A | C17: A: D279A | D17: =VLOOKUP(A17,Expression!$C$1:$D$462,2,FALSE) -> 396.3138 | E17: =VLOOKUP(A17,'JRCSF Survival Analysis'!$A$1:$B$50,2,FALSE) -> 3 | F17: =VLOOKUP(A17,'sequencing metadata'!$A$1:$B$100,2,FALSE) -> 20 | G17: =F17-E17 -> 17 | H17: =COUNTIF(L17:EM17,">0.1") -> 11 | I17: =COUNTIF(L17:EM17,">0.5") -> 7 | J17: =COUNTIF(L17:EM17,">0.9") -> 3 | K17: CD30-m231 | L17: 0 | M17: 0 | N17: 0 | O17: 0 | P17: 0 | Q17: 0.93326425 | R17: 0 | S17: 0 | T17: 0 | U17: 0 | V17: 0 | W17: 0 | X17: 0 | Y17: 0 | Z17: 0 | AA17: 0 | AB17: 0 | AC17: 0 | AD17: 0 | AE17: 0 | AF17: 0 | AG17: 0 | AH17: 0 | AI17: 0 | AJ17: 0 | AK17: 0.51189128 | AL17: 0 | AM17: 0 | AN17: 0.21268479 | AO17: 0 | AP17: 0 | AQ17: 0 | AR17: 0 | AS17: 0 | AT17: 0 | AU17: 0.15503636 | AV17: 0 | AW17: 0 | AX17: 0 | AY17: 0 | AZ17: 0 | BA17: 0 | BB17: 0 | BC17: 0 | BD17: 0 | BE17: 0 | BF17: 0.99438269 | BG17: 0 | BH17: 0 | BI17: 0 | BJ17: 0 | BK17: 0 | BL17: 0 | BM17: 0 | BN17: 0 | BO17: 0 | BP17: 0 | BQ17: 0 | BR17: 0 | BS17: 0 | BT17: 0 | BU17: 0 | BV17: 0 | BW17: 0 | BX17: 0 | BY17: 0 | BZ17: 0.99522787 | CA17: 0 | CB17: 0 | CC17: 0 | CD17: 0 | CE17: 0 | CF17: 0 | CG17: 0 | CH17: 0 | CI17: 0 | CJ17: 0 | CK17: 0 | CL17: 0 | CM17: 0 | CN17: 0 | CO17: 0 | CP17: 0.17650741 | CQ17: 0 | CR17: 0 | CS17: 0.52281544 | CT17: 0 | CU17: 0 | CV17: 0 | CW17: 0.11607525 | CX17: 0 | CY17: 0 | CZ17: 0 | DA17: 0 | DB17: 0 | DC17: 0 | DD17: 0 | DE17: 0 | DF17: 0 | DG17: 0 | DH17: 0 | DI17: 0 | DJ17: 0 | DK17: 0 | DL17: 0 | DM17: 0 | DN17: 0 | DO17: 0 | DP17: 0 | DQ17: 0 | DR17: 0 | DS17: 0 | DT17: 0.8192877 | DU17: 0 | DV17: 0 | DW17: 0 | DX17: 0 | DY17: 0.54874618 | DZ17: 0 | EA17: 0 | EB17: 0 | EC17: 0 | ED17: 0 | EE17: 0 | EF17: 0 | EG17: 0 | EH17: 0 | EI17: 0 | EJ17: 0 | EK17: 0 | EL17: 0 | EM17: 0
A18: CD50-m069 | B18: A | C18: A: D279A | D18: =VLOOKUP(A18,Expression!$C$1:$D$462,2,FALSE) -> 66.0624 | E18: =VLOOKUP(A18,'JRCSF Survival Analysis'!$A$1:$B$50,2,FALSE) -> 3 | F18: =VLOOKUP(A18,'sequencing metadata'!$A$1:$B$100,2,FALSE) -> 24 | G18: =F18-E18 -> 21 | H18: =COUNTIF(L18:EM18,">0.1") -> 11 | I18: =COUNTIF(L18:EM18,">0.5") -> 9 | J18: =COUNTIF(L18:EM18,">0.9") -> 5 | K18: CD50-m069 | L18: 0 | M18: 0 | N18: 0 | O18: 0 | P18: 0 | Q18: 0 | R18: 0 | S18: 0 | T18: 0 | U18: 0 | V18: 0 | W18: 0 | X18: 0 | Y18: 0 | Z18: 0 | AA18: 0 | AB18: 0 | AC18: 0 | AD18: 0 | AE18: 0 | AF18: 0 | AG18: 0 | AH18: 0 | AI18: 0 | AJ18: 0 | AK18: 0 | AL18: 0.99690667 | AM18: 0 | AN18: 0 | AO18: 0 | AP18: 0 | AQ18: 0 | AR18: 0.67806797 | AS18: 0 | AT18: 0 | AU18: 0 | AV18: 0 | AW18: 0 | AX18: 0 | AY18: 0.41988993 | AZ18: 0 | BA18: 0 | BB18: 0 | BC18: 0 | BD18: 0.99812999 | BE18: 0 | BF18: 0.9950481 | BG18: 0 | BH18: 0 | BI18: 0 | BJ18: 0 | BK18: 0 | BL18: 0 | BM18: 0 | BN18: 0 | BO18: 0 | BP18: 0 | BQ18: 0 | BR18: 0 | BS18: 0 | BT18: 0 | BU18: 0 | BV18: 0 | BW18: 0 | BX18: 0 | BY18: 0 | BZ18: 0.99677878 | CA18: 0 | CB18: 0 | CC18: 0 | CD18: 0 | CE18: 0 | CF18: 0 | CG18: 0 | CH18: 0 | CI18: 0 | CJ18: 0 | CK18: 0 | CL18: 0 | CM18: 0 | CN18: 0 | CO18: 0 | CP18: 0 | CQ18: 0.57692308 | CR18: 0 | CS18: 0 | CT18: 0 | CU18: 0 | CV18: 0.9964863 | CW18: 0 | CX18: 0 | CY18: 0 | CZ18: 0 | DA18: 0 | DB18: 0 | DC18: 0 | DD18: 0 | DE18: 0 | DF18: 0 | DG18: 0 | DH18: 0 | DI18: 0 | DJ18: 0 | DK18: 0.58675949 | DL18: 0 | DM18: 0 | DN18: 0 | DO18: 0 | DP18: 0 | DQ18: 0 | DR18: 0 | DS18: 0 | DT18: 0 | DU18: 0 | DV18: 0 | DW18: 0 | DX18: 0 | DY18: 0 | DZ18: 0 | EA18: 0.58497044 | EB18: 0 | EC18: 0 | ED18: 0 | EE18: 0.41912725 | EF18: 0 | EG18: 0 | EH18: 0 | EI18: 0 | EJ18: 0 | EK18: 0 | EL18: 0 | EM18: 0
A19: CD50-m074 | B19: A | C19: A: D279A | D19: =VLOOKUP(A19,Expression!$C$1:$D$462,2,FALSE) -> 63.3509 | E19: =VLOOKUP(A19,'JRCSF Survival Analysis'!$A$1:$B$50,2,FALSE) -> 3 | F19: =VLOOKUP(A19,'sequencing metadata'!$A$1:$B$100,2,FALSE) -> 24 | G19: =F19-E19 -> 21 | H19: =COUNTIF(L19:EM19,">0.1") -> 16 | I19: =COUNTIF(L19:EM19,">0.5") -> 6 | J19: =COUNTIF(L19:EM19,">0.9") -> 2 | K19: CD50-m074 | L19: 0 | M19: 0 | N19: 0 | O19: 0 | P19: 0 | Q19: 0 | R19: 0 | S19: 0 | T19: 0 | U19: 0 | V19: 0 | W19: 0 | X19: 0 | Y19: 0 | Z19: 0 | AA19: 0 | AB19: 0 | AC19: 0 | AD19: 0 | AE19: 0 | AF19: 0 | AG19: 0 | AH19: 0 | AI19: 0 | AJ19: 0 | AK19: 0 | AL19: 0 | AM19: 0 | AN19: 0.41234462 | AO19: 0 | AP19: 0 | AQ19: 0 | AR19: 0 | AS19: 0.13110048 | AT19: 0 | AU19: 0 | AV19: 0 | AW19: 0 | AX19: 0.38742673 | AY19: 0.62845567 | AZ19: 0 | BA19: 0 | BB19: 0 | BC19: 0 | BD19: 0.37979207 | BE19: 0.12524686 | BF19: 0.86808466 | BG19: 0 | BH19: 0.12426655 | BI19: 0 | BJ19: 0 | BK19: 0 | BL19: 0 | BM19: 0 | BN19: 0 | BO19: 0 | BP19: 0 | BQ19: 0 | BR19: 0 | BS19: 0 | BT19: 0 | BU19: 0 | BV19: 0 | BW19: 0 | BX19: 0 | BY19: 0 | BZ19: 0 | CA19: 0.99640758 | CB19: 0 | CC19: 0 | CD19: 0 | CE19: 0 | CF19: 0 | CG19: 0 | CH19: 0 | CI19: 0 | CJ19: 0.69819472 | CK19: 0 | CL19: 0 | CM19: 0 | CN19: 0 | CO19: 0 | CP19: 0 | CQ19: 0 | CR19: 0 | CS19: 0 | CT19: 0 | CU19: 0.99469165 | CV19: 0 | CW19: 0 | CX19: 0 | CY19: 0 | CZ19: 0 | DA19: 0 | DB19: 0.24793269 | DC19: 0 | DD19: 0 | DE19: 0 | DF19: 0 | DG19: 0 | DH19: 0 | DI19: 0 | DJ19: 0 | DK19: 0 | DL19: 0 | DM19: 0 | DN19: 0 | DO19: 0 | DP19: 0 | DQ19: 0 | DR19: 0 | DS19: 0 | DT19: 0 | DU19: 0 | DV19: 0 | DW19: 0.1143049 | DX19: 0 | DY19: 0 | DZ19: 0 | EA19: 0 | EB19: 0.13720317 | EC19: 0 | ED19: 0 | EE19: 0 | EF19: 0.69329722 | EG19: 0 | EH19: 0.10611335 | EI19: 0 | EJ19: 0 | EK19: 0 | EL19: 0 | EM19: 0
A20: CD21-m004 | B20: B | C20: B: D279H | D20: =VLOOKUP(A20,Expression!$C$1:$D$462,2,FALSE) -> 106.9328 | E20: =VLOOKUP(A20,'JRCSF Survival Analysis'!$A$1:$B$50,2,FALSE) -> 2 | F20: =VLOOKUP(A20,'sequencing metadata'!$A$1:$B$100,2,FALSE) -> 12 | G20: =F20-E20 -> 10 | H20: =COUNTIF(L20:EM20,">0.1") -> 16 | I20: =COUNTIF(L20:EM20,">0.5") -> 6 | J20: =COUNTIF(L20:EM20,">0.9") -> 3 | K20: CD21-m004 | L20: 0 | M20: 0 | N20: 0 | O20: 0 | P20: 0 | Q20: 0 | R20: 0 | S20: 0 | T20: 0 | U20: 0 | V20: 0 | W20: 0 | X20: 0 | Y20: 0 | Z20: 0 | AA20: 0 | AB20: 0.94605039 | AC20: 0.94972847 | AD20: 0.93549373 | AE20: 0 | AF20: 0 | AG20: 0 | AH20: 0 | AI20: 0 | AJ20: 0 | AK20: 0 | AL20: 0 | AM20: 0 | AN20: 0.11025505 | AO20: 0.14147184 | AP20: 0.31455142 | AQ20: 0 | AR20: 0 | AS20: 0 | AT20: 0 | AU20: 0 | AV20: 0 | AW20: 0 | AX20: 0 | AY20: 0 | AZ20: 0 | BA20: 0 | BB20: 0 | BC20: 0 | BD20: 0 | BE20: 0 | BF20: 0 | BG20: 0 | BH20: 0.54836163 | BI20: 0.10209238 | BJ20: 0.34891433 | BK20: 0 | BL20: 0 | BM20: 0 | BN20: 0 | BO20: 0 | BP20: 0 | BQ20: 0.15484805 | BR20: 0 | BS20: 0 | BT20: 0 | BU20: 0 | BV20: 0 | BW20: 0 | BX20: 0 | BY20: 0 | BZ20: 0.26282895 | CA20: 0.52796053 | CB20: 0 | CC20: 0.11567982 | CD20: 0 | CE20: 0 | CF20: 0 | CG20: 0 | CH20: 0 | CI20: 0 | CJ20: 0 | CK20: 0 | CL20: 0 | CM20: 0 | CN20: 0 | CO20: 0 | CP20: 0 | CQ20: 0 | CR20: 0 | CS20: 0 | CT20: 0.2115847 | CU20: 0 | CV20: 0 | CW20: 0 | CX20: 0.16652946 | CY20: 0 | CZ20: 0 | DA20: 0.61930905 | DB20: 0 | DC20: 0 | DD20: 0 | DE20: 0 | DF20: 0 | DG20: 0 | DH20: 0 | DI20: 0 | DJ20: 0 | DK20: 0 | DL20: 0 | DM20: 0 | DN20: 0 | DO20: 0 | DP20: 0 | DQ20: 0 | DR20: 0 | DS20: 0 | DT20: 0 | DU20: 0 | DV20: 0 | DW20: 0 | DX20: 0 | DY20: 0 | DZ20: 0 | EA20: 0 | EB20: 0 | EC20: 0 | ED20: 0 | EE20: 0 | EF20: 0 | EG20: 0 | EH20: 0 | EI20: 0 | EJ20: 0 | EK20: 0 | EL20: 0 | EM20: 0
A21: CD21-m006 | B21: B | C21: B: D279H | D21: =VLOOKUP(A21,Expression!$C$1:$D$462,2,FALSE) -> 193.23 | E21: =VLOOKUP(A21,'JRCSF Survival Analysis'!$A$1:$B$50,2,FALSE) -> 2 | F21: =VLOOKUP(A21,'sequencing metadata'!$A$1:$B$100,2,FALSE) -> 24 | G21: =F21-E21 -> 22 | H21: =COUNTIF(L21:EM21,">0.1") -> 9 | I21: =COUNTIF(L21:EM21,">0.5") -> 4 | J21: =COUNTIF(L21:EM21,">0.9") -> 2 | K21: CD21-m006 | L21: 0 | M21: 0 | N21: 0 | O21: 0 | P21: 0 | Q21: 0 | R21: 0 | S21: 0 | T21: 0 | U21: 0 | V21: 0 | W21: 0 | X21: 0 | Y21: 0 | Z21: 0 | AA21: 0 | AB21: 0 | AC21: 0 | AD21: 0 | AE21: 0 | AF21: 0 | AG21: 0 | AH21: 0.98312236 | AI21: 0 | AJ21: 0 | AK21: 0 | AL21: 0 | AM21: 0 | AN21: 0 | AO21: 0 | AP21: 0 | AQ21: 0 | AR21: 0 | AS21: 0 | AT21: 0 | AU21: 0 | AV21: 0 | AW21: 0 | AX21: 0 | AY21: 0 | AZ21: 0 | BA21: 0 | BB21: 0 | BC21: 0 | BD21: 0.87842466 | BE21: 0 | BF21: 0 | BG21: 0 | BH21: 0.99202552 | BI21: 0 | BJ21: 0 | BK21: 0 | BL21: 0 | BM21: 0 | BN21: 0 | BO21: 0 | BP21: 0 | BQ21: 0 | BR21: 0 | BS21: 0 | BT21: 0 | BU21: 0 | BV21: 0 | BW21: 0 | BX21: 0 | BY21: 0 | BZ21: 0.83301708 | CA21: 0 | CB21: 0 | CC21: 0.16318786 | CD21: 0 | CE21: 0 | CF21: 0 | CG21: 0 | CH21: 0 | CI21: 0 | CJ21: 0 | CK21: 0 | CL21: 0 | CM21: 0 | CN21: 0 | CO21: 0 | CP21: 0 | CQ21: 0 | CR21: 0 | CS21: 0 | CT21: 0 | CU21: 0 | CV21: 0 | CW21: 0 | CX21: 0 | CY21: 0 | CZ21: 0 | DA21: 0 | DB21: 0 | DC21: 0 | DD21: 0 | DE21: 0 | DF21: 0 | DG21: 0 | DH21: 0 | DI21: 0 | DJ21: 0.33992095 | DK21: 0 | DL21: 0.12108559 | DM21: 0 | DN21: 0 | DO21: 0 | DP21: 0 | DQ21: 0 | DR21: 0 | DS21: 0 | DT21: 0 | DU21: 0 | DV21: 0 | DW21: 0 | DX21: 0.40734266 | DY21: 0 | DZ21: 0 | EA21: 0 | EB21: 0 | EC21: 0 | ED21: 0 | EE21: 0 | EF21: 0 | EG21: 0 | EH21: 0 | EI21: 0 | EJ21: 0 | EK21: 0.47672253 | EL21: 0 | EM21: 0
A22: CD21-m007 | B22: B | C22: B: D279H | D22: =VLOOKUP(A22,Expression!$C$1:$D$462,2,FALSE) -> 149.745 | E22: =VLOOKUP(A22,'JRCSF Survival Analysis'!$A$1:$B$50,2,FALSE) -> 2 | F22: =VLOOKUP(A22,'sequencing metadata'!$A$1:$B$100,2,FALSE) -> 21 | G22: =F22-E22 -> 19 | H22: =COUNTIF(L22:EM22,">0.1") -> 17 | I22: =COUNTIF(L22:EM22,">0.5") -> 5 | J22: =COUNTIF(L22:EM22,">0.9") -> 1 | K22: CD21-m007 | L22: 0 | M22: 0 | N22: 0 | O22: 0 | P22: 0 | Q22: 0 | R22: 0 | S22: 0 | T22: 0 | U22: 0 | V22: 0 | W22: 0 | X22: 0 | Y22: 0.36371761 | Z22: 0 | AA22: 0 | AB22: 0 | AC22: 0.25151149 | AD22: 0.2527339 | AE22: 0 | AF22: 0.16748768 | AG22: 0.17391304 | AH22: 0 | AI22: 0 | AJ22: 0 | AK22: 0 | AL22: 0 | AM22: 0 | AN22: 0 | AO22: 0 | AP22: 0 | AQ22: 0 | AR22: 0.26934985 | AS22: 0 | AT22: 0 | AU22: 0 | AV22: 0 | AW22: 0 | AX22: 0.5477707 | AY22: 0 | AZ22: 0 | BA22: 0 | BB22: 0 | BC22: 0 | BD22: 0.18969298 | BE22: 0 | BF22: 0 | BG22: 0 | BH22: 0.98687215 | BI22: 0 | BJ22: 0 | BK22: 0 | BL22: 0 | BM22: 0 | BN22: 0 | BO22: 0 | BP22: 0 | BQ22: 0 | BR22: 0 | BS22: 0 | BT22: 0 | BU22: 0 | BV22: 0 | BW22: 0 | BX22: 0 | BY22: 0 | BZ22: 0 | CA22: 0.12388775 | CB22: 0 | CC22: 0.85900068 | CD22: 0 | CE22: 0 | CF22: 0 | CG22: 0 | CH22: 0 | CI22: 0.37725381 | CJ22: 0 | CK22: 0 | CL22: 0 | CM22: 0 | CN22: 0 | CO22: 0 | CP22: 0.35164051 | CQ22: 0.44231956 | CR22: 0 | CS22: 0 | CT22: 0 | CU22: 0 | CV22: 0 | CW22: 0 | CX22: 0 | CY22: 0 | CZ22: 0 | DA22: 0 | DB22: 0.26331583 | DC22: 0 | DD22: 0 | DE22: 0.56481481 | DF22: 0 | DG22: 0 | DH22: 0 | DI22: 0 | DJ22: 0 | DK22: 0 | DL22: 0.76433915 | DM22: 0 | DN22: 0 | DO22: 0 | DP22: 0 | DQ22: 0 | DR22: 0 | DS22: 0 | DT22: 0 | DU22: 0 | DV22: 0 | DW22: 0 | DX22: 0 | DY22: 0 | DZ22: 0 | EA22: 0 | EB22: 0 | EC22: 0 | ED22: 0 | EE22: 0 | EF22: 0 | EG22: 0 | EH22: 0 | EI22: 0 | EJ22: 0 | EK22: 0 | EL22: 0 | EM22: 0
... A36: CD30-m205 | B36: Other | C36: Other | D36: =VLOOKUP(A36,Expression!$C$1:$D$462,2,FALSE) -> 297.6211 | E36: =VLOOKUP(A36,'JRCSF Survival Analysis'!$A$1:$B$50,2,FALSE) -> 3 | F36: =VLOOKUP(A36,'sequencing metadata'!$A$1:$B$100,2,FALSE) -> 20 | G36: =F36-E36 -> 17 | H36: =COUNTIF(L36:EM36,">0.1") -> 9 | I36: =COUNTIF(L36:EM36,">0.5") -> 9 | J36: =COUNTIF(L36:EM36,">0.9") -> 9 | K36: CD30-m205 | L36: 0.9885823 | M36: 0 | N36: 0 | O36: 0 | P36: 0 | Q36: 0 | R36: 0 | S36: 0 | T36: 0 | U36: 0 | V36: 0 | W36: 0.9909688 | X36: 0 | Y36: 0 | Z36: 0 | AA36: 0 | AB36: 0 | AC36: 0 | AD36: 0 | AE36: 0 | AF36: 0 | AG36: 0 | AH36: 0.99318151 | AI36: 0 | AJ36: 0 | AK36: 0 | AL36: 0 | AM36: 0 | AN36: 0 | AO36: 0 | AP36: 0 | AQ36: 0 | AR36: 0 | AS36: 0 | AT36: 0 | AU36: 0 | AV36: 0 | AW36: 0 | AX36: 0 | AY36: 0 | AZ36: 0 | BA36: 0 | BB36: 0 | BC36: 0 | BD36: 0 | BE36: 0 | BF36: 0 | BG36: 0 | BH36: 0 | BI36: 0 | BJ36: 0 | BK36: 0 | BL36: 0.99284708 | BM36: 0.99323181 | BN36: 0 | BO36: 0 | BP36: 0 | BQ36: 0 | BR36: 0 | BS36: 0 | BT36: 0 | BU36: 0 | BV36: 0 | BW36: 0 | BX36: 0 | BY36: 0 | BZ36: 0.9918713 | CA36: 0 | CB36: 0 | CC36: 0 | CD36: 0 | CE36: 0 | CF36: 0 | CG36: 0 | CH36: 0 | CI36: 0 | CJ36: 0 | CK36: 0 | CL36: 0 | CM36: 0 | CN36: 0 | CO36: 0 | CP36: 0 | CQ36: 0 | CR36: 0 | CS36: 0 | CT36: 0 | CU36: 0 | CV36: 0 | CW36: 0 | CX36: 0 | CY36: 0 | CZ36: 0 | DA36: 0 | DB36: 0 | DC36: 0 | DD36: 0 | DE36: 0 | DF36: 0 | DG36: 0.98607759 | DH36: 0 | DI36: 0 | DJ36: 0 | DK36: 0 | DL36: 0 | DM36: 0 | DN36: 0 | DO36: 0 | DP36: 0 | DQ36: 0 | DR36: 0 | DS36: 0 | DT36: 0 | DU36: 0 | DV36: 0 | DW36: 0 | DX36: 0 | DY36: 0 | DZ36: 0 | EA36: 0 | EB36: 0 | EC36: 0 | ED36: 0 | EE36: 0 | EF36: 0 | EG36: 0.98607242 | EH36: 0 | EI36: 0.98743161 | EJ36: 0 | EK36: 0 | EL36: 0 | EM36: 0
BF37: =SUM(BF11:BF36) -> 7.3099872 | BG37: =SUM(BG11:BG36) -> 3.0487734 | BH37: =SUM(BH11:BH36) -> 4.1042829 | BI37: =SUM(BI11:BI36) -> 1.6221339 | BJ37: =SUM(BJ11:BJ36) -> 5.0751498 | BK37: =SUM(BK11:BK36) -> 2.9227335
BF38: =BF37/SUM($BF$37:$BK$37) -> 0.30353232 | BG38: =BG37/SUM($BF$37:$BK$37) -> 0.1265941 | BH38: =BH37/SUM($BF$37:$BK$37) -> 0.17042198 | BI38: =BI37/SUM($BF$37:$BK$37) -> 0.067355804 | BJ38: =BJ37/SUM($BF$37:$BK$37) -> 0.21073525 | BK38: =BK37/SUM($BF$37:$BK$37) -> 0.12136055

Sheet JRCSF Haplotype Counts
A3: Row Labels | B3: Count of Escape Path | C3: Count of Escape Path2
A4: A: D279A | B4: 9 | C4: 0.34615385 | E4: =B4/SUM(B4:B5) -> 0.64285714 | F4: =SUM(C4:C5) -> 0.53846154
A5: B: D279H | B5: 5 | C5: 0.19230769 | E5: =B5/SUM(B4:B5) -> 0.35714286
A6: C: D279N + Other | B6: 4 | C6: 0.15384615
A7: D: D279E + Other | B7: 3 | C7: 0.11538462 | D7: =SUM(C7:C9) -> 0.26923077
A8: E: D279K | B8: 1 | C8: 0.038461538
A9: F: D279Y | B9: 3 | C9: 0.11538462
A10: Other | B10: 1 | C10: 0.038461538
A11: Grand Total | B11: 26 | C11: 1

Sheet JRCSF Survival Analysis
A1: Sample | B1: Weeks Post-AAV | C1: VRC07
A2: CD50-m066 | B2: 3 | C2: 1
A3: CD50-m067 | B3: 2 | C3: 1
A4: CD50-m068 | B4: 2 | C4: 1
A5: CD50-m069 | B5: 3 | C5: 1
A6: CD50-m071 | B6: 2 | C6: 1
A7: CD50-m072 | B7: 3 | C7: 1
A8: CD50-m073 | B8: 3 | C8: 1
A9: CD50-m074 | B9: 3 | C9: 1
A10: CD21-m998 | B10: 2
A11: CD21-m999 | B11: 2
A12: CD21-m002 | B12: 2
A13: CD21-m003 | B13: 2
A14: CD21-m004 | B14: 2
A15: CD21-m006 | B15: 2
A16: CD21-m007 | B16: 2
A17: CD21-m008 | B17: 2
A18: CD21-m009 | B18: 2
A19: CD30-m193 | B19: 2
A20: CD30-m195 | B20: 2
A21: CD30-m196 | B21: 3
... A32: CD30-m232 | B32: 2

Sheet sequencing metadata
A1: sample | B1: week
A2: CD5-m260 | B2: 24
A3: CD5-m263 | B3: 15
A4: CD5-m264 | B4: 9
A5: CD5-m265 | B5: 25
A6: CD5-m269 | B6: 22
A7: CD5-m271 | B7: 26
A8: CD5-m272 | B8: 26
A9: CD5-m273 | B9: 18
A10: CD5-m281 | B10: 20
A11: CD5-m285 | B11: 26
A12: CD10-m880 | B12: 24
A13: CD20-m020 | B13: 18
... A28: CD46-m336 | B28: 24
A29: CD46-m337
A30: CD46-m339 | B30: 13
A31: CD46-m340 | B31: 22
A32: CD50-m131 | B32: 15
A33: CD50-m134 | B33: 12
A34: CD50-m136 | B34: 12
A35: CD21-m998 | B35: 24
A36: CD21-m999 | B36: 24
A37: CD21-m002 | B37: 18
A38: CD21-m003 | B38: 24
A39: CD21-m004 | B39: 12
A40: CD21-m006 | B40: 24
A41: CD21-m007 | B41: 21
... A50: CD30-m205 | B50: 20
A51: CD30-m206
A52: CD30-m207 | B52: 20
A53: CD30-m228
A54: CD30-m229 | B54: 20
A55: CD30-m230 | B55: 16
A56: CD30-m231 | B56: 20
A57: CD30-m232 | B57: 12
A58: CD50-m066 | B58: 24
A59: CD50-m067
A60: CD50-m068 | B60: 24
A61: CD50-m069 | B61: 24
A62: CD50-m071 | B62: 24
...

Sheet Expression
A1: Experiment | B1: Mouse | C1: ID | D1: Geomean
A2: CD5 | B2: 260 | C2: =_xlfn.CONCAT(A2,"-m",B2) -> CD5-m260 | D2: 20.088
A3: CD5 | B3: 261 | C3: =_xlfn.CONCAT(A3,"-m",B3) -> CD5-m261 | D3: 40.2419
A4: CD5 | B4: 263 | C4: =_xlfn.CONCAT(A4,"-m",B4) -> CD5-m263 | D4: 32.966
A5: CD5 | B5: 264 | C5: =_xlfn.CONCAT(A5,"-m",B5) -> CD5-m264 | D5: 18.2003
A6: CD5 | B6: 265 | C6: =_xlfn.CONCAT(A6,"-m",B6) -> CD5-m265 | D6: 37.9099
A7: CD5 | B7: 266 | C7: =_xlfn.CONCAT(A7,"-m",B7) -> CD5-m266 | D7: 49.7924
A8: CD5 | B8: 267 | C8: =_xlfn.CONCAT(A8,"-m",B8) -> CD5-m267 | D8: 41.9774
A9: CD5 | B9: 269 | C9: =_xlfn.CONCAT(A9,"-m",B9) -> CD5-m269 | D9: 33.6268
A10: CD5 | B10: 270 | C10: =_xlfn.CONCAT(A10,"-m",B10) -> CD5-m270 | D10: 50.4443
A11: CD5 | B11: 271 | C11: =_xlfn.CONCAT(A11,"-m",B11) -> CD5-m271 | D11: 15.9094
A12: CD5 | B12: 272 | C12: =_xlfn.CONCAT(A12,"-m",B12) -> CD5-m272 | D12: 32.7447
A13: CD5 | B13: 273 | C13: =_xlfn.CONCAT(A13,"-m",B13) -> CD5-m273 | D13: 70.4947
... A53: CD10 | B53: 900 | C53: =_xlfn.CONCAT(A53,"-m",B53) -> CD10-m900 | D53: 42.3516
A54: CD20 | B54: m004 | C54: =_xlfn.CONCAT(A54,"-",B54) -> CD20-m004 | D54: 15.3163
A55: CD20 | B55: m005 | C55: =_xlfn.CONCAT(A55,"-",B55) -> CD20-m005 | D55: 13.9864
A56: CD20 | B56: m006 | C56: =_xlfn.CONCAT(A56,"-",B56) -> CD20-m006 | D56: 15.93
A57: CD20 | B57: m007 | C57: =_xlfn.CONCAT(A57,"-",B57) -> CD20-m007 | D57: 11.8393
A58: CD20 | B58: m008 | C58: =_xlfn.CONCAT(A58,"-",B58) -> CD20-m008 | D58: 14.6341
A59: CD20 | B59: m009 | C59: =_xlfn.CONCAT(A59,"-",B59) -> CD20-m009 | D59: 2.3771
A60: CD20 | B60: m010 | C60: =_xlfn.CONCAT(A60,"-",B60) -> CD20-m010 | D60: 11.8213
A61: CD20 | B61: m011 | C61: =_xlfn.CONCAT(A61,"-",B61) -> CD20-m011 | D61: 17.4849
A62: CD20 | B62: m012 | C62: =_xlfn.CONCAT(A62,"-",B62) -> CD20-m012 | D62: 16.7985
A63: CD20 | B63: m013 | C63: =_xlfn.CONCAT(A63,"-",B63) -> CD20-m013 | D63: 14.5655
A64: CD20 | B64: m029 | C64: =_xlfn.CONCAT(A64,"-",B64) -> CD20-m029 | D64: 4.3733
A65: CD20 | B65: m030 | C65: =_xlfn.CONCAT(A65,"-",B65) -> CD20-m030 | D65: 17.6805
... A171: CD27 | B171: m803 | C171: =_xlfn.CONCAT(A171,"-",B171) -> CD27-m803 | D171: 0.5787
A172: CD30 | B172: 158 | C172: =_xlfn.CONCAT(A172,"-m",B172) -> CD30-m158 | D172: 586.3097
A173: CD30 | B173: 159 | C173: =_xlfn.CONCAT(A173,"-m",B173) -> CD30-m159 | D173: 315.0203
A174: CD30 | B174: 160 | C174: =_xlfn.CONCAT(A174,"-m",B174) -> CD30-m160 | D174: 347.1628
A175: CD30 | B175: 161 | C175: =_xlfn.CONCAT(A175,"-m",B175) -> CD30-m161 | D175: 274.6268
A176: CD30 | B176: 162 | C176: =_xlfn.CONCAT(A176,"-m",B176) -> CD30-m162 | D176: 794.0524
A177: CD30 | B177: 164 | C177: =_xlfn.CONCAT(A177,"-m",B177) -> CD30-m164 | D177: 244.8502
A178: CD30 | B178: 165 | C178: =_xlfn.CONCAT(A178,"-m",B178) -> CD30-m165 | D178: 337.2518
A179: CD30 | B179: 166 | C179: =_xlfn.CONCAT(A179,"-m",B179) -> CD30-m166 | D179: 490.1936
A180: CD30 | B180: 167 | C180: =_xlfn.CONCAT(A180,"-m",B180) -> CD30-m167 | D180: 338.1059
A181: CD30 | B181: 168 | C181: =_xlfn.CONCAT(A181,"-m",B181) -> CD30-m168 | D181: 550.2127
A182: CD30 | B182: 169 | C182: =_xlfn.CONCAT(A182,"-m",B182) -> CD30-m169 | D182: 262.5437
A183: CD30 | B183: 170 | C183: =_xlfn.CONCAT(A183,"-m",B183) -> CD30-m170 | D183: 341.9487
... A311: CD46 | B311: 402 | C311: =_xlfn.CONCAT(A311,"-m",B311) -> CD46-m402 | D311: 20.7454
...

Sheet survival
A1: Sample | B1: Weeks Post-AAV | C1: Luciferase | D1: VRC07 | E1: PGDM140 | F1: N6
A2: CD5-m260 | B2: 12 | D2: 1
A3: CD5-m263 | B3: 7 | D3: 1
A4: CD5-m264 | B4: 4 | D4: 1
A5: CD5-m265 | B5: 5 | D5: 1
A6: CD5-m269 | B6: 14 | D6: 1
A7: CD5-m271 | B7: 3 | D7: 1
A8: CD5-m272 | B8: 5 | D8: 1
A9: CD5-m273 | B9: 8 | D9: 1
A10: CD5-m281 | B10: 2 | D10: 1
A11: CD5-m285 | B11: 2 | D11: 1
A12: CD10-m880 | B12: 10 | D12: 1
A13: CD20-m020 | B13: 3 | D13: 1
... A57: CD21-m020 | B57: 20 | D57: 0
A58: CD5-m245 | B58: 2 | C58: 1
A59: CD5-m246 | B59: 2 | C59: 1
A60: CD5-m247 | B60: 2 | C60: 1
A61: CD5-m248 | B61: 2 | C61: 1
A62: CD5-m249 | B62: 2 | C62: 1
A63: CD5-m250 | B63: 2 | C63: 1
A64: CD5-m251 | B64: 2 | C64: 1
A65: CD5-m253 | B65: 2 | C65: 1
A66: CD5-m254 | B66: 2 | C66: 1
A67: CD5-m255 | B67: 2 | C67: 1
A68: CD5-m256 | B68: 2 | C68: 1
A69: CD5-m257 | B69: 2 | C69: 1
... A101: CD21-m013 | B101: 2 | C101: 1
A102: CD21-m021*
A103: CD21-m022 | B103: 2 | C103: 1
A104: CD21-m023 | B104: 2 | C104: 1
A105: CD21-m024 | B105: 2 | C105: 1
A106: CD21-m025 | B106: 2 | C106: 1
A107: CD21-m026 | B107: 2 | C107: 1
A108: CD46-m324 | B108: 2 | C108: 1
A109: CD46-m327*
A110: CD46-m328 | B110: 2 | C110: 1
A111: CD46-m330 | B111: 2 | C111: 1
A112: CD5-m283*
A113: CD10-m876*
A114: CD20-m025*
...

Sheet JR-CSF Raw 0.1
B1: aa_pos | C1: HXB2_pos | D1: JRCSF_aa | E1: HXB2_aa | F1: Syn | G1: aa_alt | H1: CD21-m002 | I1: CD21-m003 | J1: CD21-m004 | K1: CD21-m006 | L1: CD21-m007 | M1: CD21-m008 | N1: CD21-m009 | O1: CD21-m998 | P1: CD21-m999 | Q1: CD30-m193 | R1: CD30-m195 | S1: CD30-m196 | T1: CD30-m197 | U1: CD30-m203 | V1: CD30-m204 | W1: CD30-m205 | X1: CD30-m207 | Y1: CD30-m229 | Z1: CD30-m230 | AA1: CD30-m231 | AB1: CD50-m066 | AC1: CD50-m068 | AD1: CD50-m069 | AE1: CD50-m071 | AF1: CD50-m073 | AG1: CD50-m074 | AH1: Score
A2: 0 | B2: 1 | C2: 1 | D2: M | E2: M | F2: =D2=G2 -> FALSE | G2: 0 | H2: 0 | I2: 0 | J2: 0 | K2: 0 | L2: 0 | M2: 0 | N2: 0 | O2: 0 | P2: 0 | Q2: 0 | R2: 0 | S2: 0 | T2: 0 | U2: 0 | V2: 0 | W2: 0 | X2: 0 | Y2: 0 | Z2: 0 | AA2: 0 | AB2: 0 | AC2: 0 | AD2: 0 | AE2: 0 | AF2: 0 | AG2: 0 | AH2: =COUNTIF(H2:AG2,">0.25") -> 0
A3: 1 | B3: 2 | C3: 2 | D3: R | E3: R | F3: =D3=G3 -> FALSE | G3: K | H3: 0 | I3: 0 | J3: 0 | K3: 0 | L3: 0 | M3: 0 | N3: 0 | O3: 0 | P3: 0.29861111 | Q3: 0 | R3: 0 | S3: 0 | T3: 0 | U3: 0 | V3: 0 | W3: 0.9885823 | X3: 0 | Y3: 0 | Z3: 0 | AA3: 0 | AB3: 0 | AC3: 0 | AD3: 0 | AE3: 0 | AF3: 0 | AG3: 0 | AH3: =COUNTIF(H3:AG3,">0.25") -> 2
A4: 2 | B4: 3 | C4: 3 | D4: V | E4: V | F4: =D4=G4 -> FALSE | G4: 0 | H4: 0 | I4: 0 | J4: 0 | K4: 0 | L4: 0 | M4: 0 | N4: 0 | O4: 0 | P4: 0 | Q4: 0 | R4: 0 | S4: 0 | T4: 0 | U4: 0 | V4: 0 | W4: 0 | X4: 0 | Y4: 0 | Z4: 0 | AA4: 0 | AB4: 0 | AC4: 0 | AD4: 0 | AE4: 0 | AF4: 0 | AG4: 0 | AH4: =COUNTIF(H4:AG4,">0.25") -> 0
A5: 3 | B5: 4 | C5: 4 | D5: K | E5: K | F5: =D5=G5 -> TRUE | G5: K | H5: 0 | I5: 0 | J5: 0 | K5: 0 | L5: 0 | M5: 0 | N5: 0 | O5: 0 | P5: 0 | Q5: 0 | R5: 0 | S5: 0 | T5: 0 | U5: 0 | V5: 0 | W5: 0 | X5: 0 | Y5: 0 | Z5: 0 | AA5: 0 | AB5: 0.10099241 | AC5: 0 | AD5: 0 | AE5: 0 | AF5: 0 | AG5: 0 | AH5: =COUNTIF(H5:AG5,">0.25") -> 0
A6: 4 | B6: 4 | C6: 4 | D6: K | E6: K | F6: =D6=G6 -> FALSE | G6: R | H6: 0 | I6: 0 | J6: 0 | K6: 0 | L6: 0 | M6: 0.15833333 | N6: 0 | O6: 0 | P6: 0 | Q6: 0 | R6: 0 | S6: 0 | T6: 0 | U6: 0 | V6: 0 | W6: 0 | X6: 0 | Y6: 0 | Z6: 0 | AA6: 0 | AB6: 0 | AC6: 0 | AD6: 0 | AE6: 0 | AF6: 0 | AG6: 0 | AH6: =COUNTIF(H6:AG6,">0.25") -> 0
A7: 5 | B7: 5 | C7: 4a | D7: G | E7: - | F7: =D7=G7 -> FALSE | G7: 0 | H7: 0 | I7: 0 | J7: 0 | K7: 0 | L7: 0 | M7: 0 | N7: 0 | O7: 0 | P7: 0 | Q7: 0 | R7: 0 | S7: 0 | T7: 0 | U7: 0 | V7: 0 | W7: 0 | X7: 0 | Y7: 0 | Z7: 0 | AA7: 0 | AB7: 0 | AC7: 0 | AD7: 0 | AE7: 0 | AF7: 0 | AG7: 0 | AH7: =COUNTIF(H7:AG7,">0.25") -> 0
A8: 6 | B8: 6 | C8: 4b | D8: I | E8: - | F8: =D8=G8 -> FALSE | G8: 0 | H8: 0 | I8: 0 | J8: 0 | K8: 0 | L8: 0 | M8: 0 | N8: 0 | O8: 0 | P8: 0 | Q8: 0 | R8: 0 | S8: 0 | T8: 0 | U8: 0 | V8: 0 | W8: 0 | X8: 0 | Y8: 0 | Z8: 0 | AA8: 0 | AB8: 0 | AC8: 0 | AD8: 0 | AE8: 0 | AF8: 0 | AG8: 0 | AH8: =COUNTIF(H8:AG8,">0.25") -> 0
A9: 7 | B9: 7 | C9: 4c | D9: R | E9: - | F9: =D9=G9 -> FALSE | G9: M | H9: 0 | I9: 0 | J9: 0 | K9: 0 | L9: 0 | M9: 0 | N9: 0.19104478 | O9: 0 | P9: 0 | Q9: 0 | R9: 0 | S9: 0 | T9: 0 | U9: 0 | V9: 0 | W9: 0 | X9: 0 | Y9: 0 | Z9: 0 | AA9: 0 | AB9: 0 | AC9: 0 | AD9: 0 | AE9: 0 | AF9: 0 | AG9: 0 | AH9: =COUNTIF(H9:AG9,">0.25") -> 0
A10: 8 | B10: 8 | C10: 5 | D10: K | E10: E | F10: =D10=G10 -> FALSE | G10: 0 | H10: 0 | I10: 0 | J10: 0 | K10: 0 | L10: 0 | M10: 0 | N10: 0 | O10: 0 | P10: 0 | Q10: 0 | R10: 0 | S10: 0 | T10: 0 | U10: 0 | V10: 0 | W10: 0 | X10: 0 | Y10: 0 | Z10: 0 | AA10: 0 | AB10: 0 | AC10: 0 | AD10: 0 | AE10: 0 | AF10: 0 | AG10: 0 | AH10: =COUNTIF(H10:AG10,">0.25") -> 0
A11: 9 | B11: 9 | C11: 6 | D11: N | E11: K | F11: =D11=G11 -> FALSE | G11: 0 | H11: 0 | I11: 0 | J11: 0 | K11: 0 | L11: 0 | M11: 0 | N11: 0 | O11: 0 | P11: 0 | Q11: 0 | R11: 0 | S11: 0 | T11: 0 | U11: 0 | V11: 0 | W11: 0 | X11: 0 | Y11: 0 | Z11: 0 | AA11: 0 | AB11: 0 | AC11: 0 | AD11: 0 | AE11: 0 | AF11: 0 | AG11: 0 | AH11: =COUNTIF(H11:AG11,">0.25") -> 0
A12: 10 | B12: 10 | C12: 7 | D12: Y | E12: Y | F12: =D12=G12 -> FALSE | G12: 0 | H12: 0 | I12: 0 | J12: 0 | K12: 0 | L12: 0 | M12: 0 | N12: 0 | O12: 0 | P12: 0 | Q12: 0 | R12: 0 | S12: 0 | T12: 0 | U12: 0 | V12: 0 | W12: 0 | X12: 0 | Y12: 0 | Z12: 0 | AA12: 0 | AB12: 0 | AC12: 0 | AD12: 0 | AE12: 0 | AF12: 0 | AG12: 0 | AH12: =COUNTIF(H12:AG12,">0.25") -> 0
A13: 11 | B13: 11 | C13: 8 | D13: Q | E13: Q | F13: =D13=G13 -> FALSE | G13: 0 | H13: 0 | I13: 0 | J13: 0 | K13: 0 | L13: 0 | M13: 0 | N13: 0 | O13: 0 | P13: 0 | Q13: 0 | R13: 0 | S13: 0 | T13: 0 | U13: 0 | V13: 0 | W13: 0 | X13: 0 | Y13: 0 | Z13: 0 | AA13: 0 | AB13: 0 | AC13: 0 | AD13: 0 | AE13: 0 | AF13: 0 | AG13: 0 | AH13: =COUNTIF(H13:AG13,">0.25") -> 0
A14: 12 | B14: 12 | C14: 9 | D14: H | E14: H | F14: =D14=G14 -> FALSE | G14: 0 | H14: 0 | I14: 0 | J14: 0 | K14: 0 | L14: 0 | M14: 0 | N14: 0 | O14: 0 | P14: 0 | Q14: 0 | R14: 0 | S14: 0 | T14: 0 | U14: 0 | V14: 0 | W14: 0 | X14: 0 | Y14: 0 | Z14: 0 | AA14: 0 | AB14: 0 | AC14: 0 | AD14: 0 | AE14: 0 | AF14: 0 | AG14: 0 | AH14: =COUNTIF(H14:AG14,">0.25") -> 0
A15: 13 | B15: 13 | C15: 10 | D15: L | E15: L | F15: =D15=G15 -> FALSE | G15: 0 | H15: 0 | I15: 0 | J15: 0 | K15: 0 | L15: 0 | M15: 0 | N15: 0 | O15: 0 | P15: 0 | Q15: 0 | R15: 0 | S15: 0 | T15: 0 | U15: 0 | V15: 0 | W15: 0 | X15: 0 | Y15: 0 | Z15: 0 | AA15: 0 | AB15: 0 | AC15: 0 | AD15: 0 | AE15: 0 | AF15: 0 | AG15: 0 | AH15: =COUNTIF(H15:AG15,">0.25") -> 0
A16: 14 | B16: 14 | C16: 11 | D16: W | E16: W | F16: =D16=G16 -> FALSE | G16: 0 | H16: 0 | I16: 0 | J16: 0 | K16: 0 | L16: 0 | M16: 0 | N16: 0 | O16: 0 | P16: 0 | Q16: 0 | R16: 0 | S16: 0 | T16: 0 | U16: 0 | V16: 0 | W16: 0 | X16: 0 | Y16: 0 | Z16: 0 | AA16: 0 | AB16: 0 | AC16: 0 | AD16: 0 | AE16: 0 | AF16: 0 | AG16: 0 | AH16: =COUNTIF(H16:AG16,">0.25") -> 0
A17: 15 | B17: 15 | C17: 12 | D17: K | E17: R | F17: =D17=G17 -> FALSE | G17: E | H17: 0 | I17: 0 | J17: 0 | K17: 0 | L17: 0 | M17: 0.10456554 | N17: 0 | O17: 0 | P17: 0 | Q17: 0 | R17: 0 | S17: 0 | T17: 0 | U17: 0 | V17: 0 | W17: 0 | X17: 0 | Y17: 0 | Z17: 0 | AA17: 0 | AB17: 0 | AC17: 0 | AD17: 0 | AE17: 0 | AF17: 0 | AG17: 0 | AH17: =COUNTIF(H17:AG17,">0.25") -> 0
A18: 16 | B18: 15 | C18: 12 | D18: K | E18: R | F18: =D18=G18 -> FALSE | G18: T | H18: 0 | I18: 0 | J18: 0 | K18: 0 | L18: 0 | M18: 0.32400589 | N18: 0 | O18: 0 | P18: 0 | Q18: 0 | R18: 0 | S18: 0 | T18: 0 | U18: 0 | V18: 0 | W18: 0 | X18: 0 | Y18: 0 | Z18: 0 | AA18: 0 | AB18: 0 | AC18: 0 | AD18: 0 | AE18: 0 | AF18: 0 | AG18: 0 | AH18: =COUNTIF(H18:AG18,">0.25") -> 1
A19: 17 | B19: 15a | C19: 13 | D19: - | E19: W | F19: =D19=G19 -> FALSE | G19: 0 | H19: 0 | I19: 0 | J19: 0 | K19: 0 | L19: 0 | M19: 0 | N19: 0 | O19: 0 | P19: 0 | Q19: 0 | R19: 0 | S19: 0 | T19: 0 | U19: 0 | V19: 0 | W19: 0 | X19: 0 | Y19: 0 | Z19: 0 | AA19: 0 | AB19: 0 | AC19: 0 | AD19: 0 | AE19: 0 | AF19: 0 | AG19: 0 | AH19: =COUNTIF(H19:AG19,">0.25") -> 0
A20: 18 | B20: 15b | C20: 14 | D20: - | E20: G | F20: =D20=G20 -> FALSE | G20: 0 | H20: 0 | I20: 0 | J20: 0 | K20: 0 | L20: 0 | M20: 0 | N20: 0 | O20: 0 | P20: 0 | Q20: 0 | R20: 0 | S20: 0 | T20: 0 | U20: 0 | V20: 0 | W20: 0 | X20: 0 | Y20: 0 | Z20: 0 | AA20: 0 | AB20: 0 | AC20: 0 | AD20: 0 | AE20: 0 | AF20: 0 | AG20: 0 | AH20: =COUNTIF(H20:AG20,">0.25") -> 0
A21: 19 | B21: 15c | C21: 15 | D21: - | E21: W | F21: =D21=G21 -> FALSE | G21: 0 | H21: 0 | I21: 0 | J21: 0 | K21: 0 | L21: 0 | M21: 0 | N21: 0 | O21: 0 | P21: 0 | Q21: 0 | R21: 0 | S21: 0 | T21: 0 | U21: 0 | V21: 0 | W21: 0 | X21: 0 | Y21: 0 | Z21: 0 | AA21: 0 | AB21: 0 | AC21: 0 | AD21: 0 | AE21: 0 | AF21: 0 | AG21: 0 | AH21: =COUNTIF(H21:AG21,">0.25") -> 0
A22: 20 | B22: 15d | C22: 16 | D22: - | E22: R | F22: =D22=G22 -> FALSE | G22: 0 | H22: 0 | I22: 0 | J22: 0 | K22: 0 | L22: 0 | M22: 0 | N22: 0 | O22: 0 | P22: 0 | Q22: 0 | R22: 0 | S22: 0 | T22: 0 | U22: 0 | V22: 0 | W22: 0 | X22: 0 | Y22: 0 | Z22: 0 | AA22: 0 | AB22: 0 | AC22: 0 | AD22: 0 | AE22: 0 | AF22: 0 | AG22: 0 | AH22: =COUNTIF(H22:AG22,">0.25") -> 0
A23: 21 | B23: 16 | C23: 17 | D23: G | E23: W | F23: =D23=G23 -> FALSE | G23: R | H23: 0 | I23: 0 | J23: 0 | K23: 0 | L23: 0 | M23: 0.91027496 | N23: 0.23434992 | O23: 0.16591928 | P23: 0 | Q23: 0 | R23: 0 | S23: 0 | T23: 0 | U23: 0 | V23: 0 | W23: 0 | X23: 0 | Y23: 0 | Z23: 0 | AA23: 0 | AB23: 0 | AC23: 0 | AD23: 0 | AE23: 0 | AF23: 0 | AG23: 0 | AH23: =COUNTIF(H23:AG23,">0.25") -> 1
A24: 22 | B24: 17 | C24: 18 | D24: G | E24: G | F24: =D24=G24 -> TRUE | G24: G | H24: 0 | I24: 0 | J24: 0 | K24: 0 | L24: 0 | M24: 0 | N24: 0 | O24: 0 | P24: 0 | Q24: 0 | R24: 0 | S24: 0 | T24: 0 | U24: 0 | V24: 0 | W24: 0 | X24: 0 | Y24: 0.13252197 | Z24: 0 | AA24: 0 | AB24: 0 | AC24: 0 | AD24: 0 | AE24: 0 | AF24: 0 | AG24: 0 | AH24: =COUNTIF(H24:AG24,">0.25") -> 0
A25: 23 | B25: 18 | C25: 19 | D25: I | E25: T | F25: =D25=G25 -> FALSE | G25: T | H25: 0 | I25: 0 | J25: 0 | K25: 0 | L25: 0 | M25: 0 | N25: 0 | O25: 0.13934426 | P25: 0 | Q25: 0 | R25: 0 | S25: 0 | T25: 0 | U25: 0 | V25: 0 | W25: 0 | X25: 0 | Y25: 0 | Z25: 0 | AA25: 0 | AB25: 0 | AC25: 0 | AD25: 0 | AE25: 0 | AF25: 0 | AG25: 0 | AH25: =COUNTIF(H25:AG25,">0.25") -> 0
A26: 24 | B26: 18 | C26: 19 | D26: I | E26: T | F26: =D26=G26 -> TRUE | G26: I | H26: 0 | I26: 0 | J26: 0 | K26: 0 | L26: 0 | M26: 0 | N26: 0 | O26: 0 | P26: 0 | Q26: 0 | R26: 0 | S26: 0.35629032 | T26: 0 | U26: 0 | V26: 0 | W26: 0 | X26: 0 | Y26: 0 | Z26: 0 | AA26: 0 | AB26: 0 | AC26: 0 | AD26: 0 | AE26: 0 | AF26: 0 | AG26: 0 | AH26: =COUNTIF(H26:AG26,">0.25") -> 1
A27: 25 | B27: 19 | C27: 20 | D27: L | E27: M | F27: =D27=G27 -> TRUE | G27: L | H27: 0 | I27: 0 | J27: 0 | K27: 0 | L27: 0 | M27: 0 | N27: 0 | O27: 0 | P27: 0.41946309 | Q27: 0 | R27: 0 | S27: 0 | T27: 0 | U27: 0 | V27: 0 | W27: 0 | X27: 0 | Y27: 0 | Z27: 0 | AA27: 0 | AB27: 0 | AC27: 0 | AD27: 0 | AE27: 0 | AF27: 0 | AG27: 0 | AH27: =COUNTIF(H27:AG27,">0.25") -> 1
